Workbook

Sheet About
A1: EIaE BAU Imported Electricity | B1: North Dakota | C1: 46185 | K1: Alabama | L1: AL | M1: EIA
A2: EIaE BAU Exported Electricity | B2: =LOOKUP(B1,K1:L50,L1:L50) -> ND | K2: Alaska | L2: AK | M2: EIA
A3: EIaE Imported Electricity Price | K3: Arizona | L3: AZ | M3: EIA
A4: EIaE BAU Exported Electricity Price | K4: Arkansas | L4: AR | M4: EIA
K5: California | L5: CA | M5: EIA
A6: Source: | B6: Quantity of Imports and Exports | K6: Colorado | L6: CO | M6: EIA
B7: Energy Information Administration | E7: State Imports Weighted by Fuel Mix of External States | K7: Connecticut | L7: CT | M7: EIA
B8: 2024 | E8: From EPS Outputs from TCAMRB | K8: Delaware | L8: DE | M8: EIA
B9: Annual Energy Outlook 2021 and 2022 | E9: ReEDs generation by resource (Mid-case) | K9: Florida | L9: FL | M9: EIA
B10: https://www.eia.gov/outlooks/aeo/tables_side.php | K10: Georgia | L10: GA | M10: EIA
B11: Table 10 | K11: Hawaii | L11: HI | M11: EIA
K12: Idaho | L12: ID | M12: EIA
B13: Canadian Electricity Generation by Type | K13: Illinois | L13: IL | M13: EIA
B14: National Energy Board, Government of Canada | E14: Imports and Export EIA SEDS | K14: Indiana | L14: IN | M14: EIA
B15: 2024 | E15: Energy Information Administration | K15: Iowa | L15: IA | M15: EIA
B16: Canada's Energy Future 2021, Appendices | E16: 2024 | K16: Kansas | L16: KS | M16: EIA
B17: https://apps.neb-one.gc.ca/ftrppndc/dflt.aspx?GoCTemplateCulture=en-CA | E17: Example Link: https://www.eia.gov/electricity/state/virginia/state_tables.php | K17: Kentucky | L17: KY | M17: EIA
B18: Table "Electricity Generation," Reference Case, Canada | E18: Tab 10: Imports and Exports (lines 15,28) | K18: Louisiana | L18: LA | M18: EIA
K19: Maine | L19: ME | M19: EIA
B20: Imported and Exported Electricity Prices | K20: Maryland | L20: MD | M20: EIA
B21: Energy Information Administration | E21: Mexican Electricity Generation by Type | K21: Massachusetts | L21: MA | M21: EIA
B22: May 2026 | E22: Energy Information Agency | K22: Michigan | L22: MI | M22: EIA
B23: Short-Term Energy Outlook | E23: 2016 | K23: Minnesota | L23: MN | M23: EIA
B24: https://www.eia.gov/outlooks/steo/tables/pdf/7atab.pdf | E24: Mexico Analysis | K24: Mississippi | L24: MS | M24: EIA
B25: Table 7 | E25: https://www.eia.gov/international/analysis/country/MEX | K25: Missouri | L25: MO | M25: EIA
E26: Table 12, 14 | K26: Montana | L26: MT | M26: EIA
B27: Canada NG Generation by Turbine Type | K27: Nebraska | L27: NE | M27: EIA
B28: Statistics Canada | K28: Nevada | L28: NV | M28: EIA
B29: 2022 | K29: New Hampshire | L29: NH | M29: EIA
B30: Electric power generation, monthly generation by type of electricity | K30: New Jersey | L30: NJ | M30: EIA
B31: https://www150.statcan.gc.ca/t1/tbl1/en/tv.action?pid=2510001501&pickMembers%5B0%5D=1.1&pickMembers%5B1%5D=2.2&cubeTimeFrame.startMonth=01&cubeTimeFrame.startYear=2015&cubeTimeFrame.endMonth=12&cubeTimeFrame.endYear=2015&referencePeriods=20150101%2C20151201 | K31: New Mexico | L31: NM | M31: EIA
B32: Data after 2015 does not break out turbine types, so we use data from 2015. | K32: New York | L32: NY | M32: EIA
K33: North Carolina | L33: NC | M33: EIA
B34: NREL REEDS Scenario Viewer | K34: North Dakota | L34: ND | M34: EIA
B35: NREL | K35: Ohio | L35: OH | M35: EIA
B36: 2023 | K36: Oklahoma | L36: OK | M36: EIA
B37: Cambium 2022 Mid-Case | K37: Oregon | L37: OR | M37: EIA
B38: https://scenarioviewer.nrel.gov/?project=82460f06-548c-4954-b2d9-b84ba92d63e2&mode=download&layout=Default | K38: Pennsylvania | L38: PA | M38: EIA
K39: Rhode Island | L39: RI | M39: EIA
K40: South Carolina | L40: SC | M40: EIA
...

Sheet Table 7_Wholesale prices
A1: Wholesale Electricity Prices (dollars per megawatthour) | B1: 2025$ | F1: 2012$
B2: 2025 | C2: 2026 | D2: 2027 | F2: 2025 | G2: 2026 | H2: 2027
A3: ERCOT | B3: 37.33 | C3: 37.61 | D3: 39.44 | F3: =B3*About!$A$73 -> 26.971844 | G3: =C3*About!$A$73 -> 27.174151 | H3: =D3*About!$A$73 -> 28.496371
A4: CAISO | B4: 28.56 | C4: 23.01 | D4: 25.86 | F4: =B4*About!$A$73 -> 20.635303 | G4: =C4*About!$A$73 -> 16.625291 | H4: =D4*About!$A$73 -> 18.684487
A5: ISO-NE | B5: 75.58 | C5: 72.09 | D5: 55.03 | F5: =B5*About!$A$73 -> 54.608411 | G5: =C5*About!$A$73 -> 52.0868 | H5: =D5*About!$A$73 -> 39.76053
A6: NYISO | B6: 72.1 | C6: 74.28 | D6: 57.96 | F6: =B6*About!$A$73 -> 52.094025 | G6: =C6*About!$A$73 -> 53.669129 | H6: =D6*About!$A$73 -> 41.877527
A7: PJM | B7: 60.09 | C7: 73.16 | D7: 67.35 | F7: =B7*About!$A$73 -> 43.416504 | G7: =C7*About!$A$73 -> 52.859901 | H7: =D7*About!$A$73 -> 48.662033
A8: MISO | B8: 46.82 | C8: 46.21 | D8: 45.05 | F8: =B8*About!$A$73 -> 33.828603 | G8: =C8*About!$A$73 -> 33.387863 | H8: =D8*About!$A$73 -> 32.549734
A9: SPP | B9: 37.91 | C9: 34.42 | D9: 34.26 | F9: =B9*About!$A$73 -> 27.390908 | G9: =C9*About!$A$73 -> 24.869297 | H9: =D9*About!$A$73 -> 24.753693
A10: SERC | B10: 41.41 | C10: 44.42 | D10: 41.3 | F10: =B10*About!$A$73 -> 29.919744 | G10: =C10*About!$A$73 -> 32.094544 | H10: =D10*About!$A$73 -> 29.840267
A11: FRCC | B11: 44.6 | C11: 47.32 | D11: 42 | F11: =B11*About!$A$73 -> 32.224598 | G11: =C11*About!$A$73 -> 34.189865 | H11: =D11*About!$A$73 -> 30.346034
A12: Northwest | B12: 45.57 | C12: 28.63 | D12: 29.7 | F12: =B12*About!$A$73 -> 32.925447 | G12: =C12*About!$A$73 -> 20.68588 | H12: =D12*About!$A$73 -> 21.458981
A13: Southwest | B13: 31.43 | C13: 25.37 | D13: 28.43 | F13: =B13*About!$A$73 -> 22.708949 | G13: =C13*About!$A$73 -> 18.33045 | H13: =D13*About!$A$73 -> 20.541375
D17: 2025 | E17: 2026 | F17: 2027
A18: Alabama | B18: AL | C18: SERC | D18: =SUMIFS(F$3:F$13,$A$3:$A$13,$C18) -> 29.919744 | E18: =SUMIFS(G$3:G$13,$A$3:$A$13,$C18) -> 32.094544 | F18: =SUMIFS(H$3:H$13,$A$3:$A$13,$C18) -> 29.840267
A19: Arizona | B19: AZ | C19: Southwest | D19: =SUMIFS(F$3:F$13,$A$3:$A$13,$C19) -> 22.708949 | E19: =SUMIFS(G$3:G$13,$A$3:$A$13,$C19) -> 18.33045 | F19: =SUMIFS(H$3:H$13,$A$3:$A$13,$C19) -> 20.541375
A20: Arkansas | B20: AR | C20: MISO | D20: =SUMIFS(F$3:F$13,$A$3:$A$13,$C20) -> 33.828603 | E20: =SUMIFS(G$3:G$13,$A$3:$A$13,$C20) -> 33.387863 | F20: =SUMIFS(H$3:H$13,$A$3:$A$13,$C20) -> 32.549734
A21: California | B21: CA | C21: CAISO | D21: =SUMIFS(F$3:F$13,$A$3:$A$13,$C21) -> 20.635303 | E21: =SUMIFS(G$3:G$13,$A$3:$A$13,$C21) -> 16.625291 | F21: =SUMIFS(H$3:H$13,$A$3:$A$13,$C21) -> 18.684487
A22: Colorado | B22: CO | C22: Southwest | D22: =SUMIFS(F$3:F$13,$A$3:$A$13,$C22) -> 22.708949 | E22: =SUMIFS(G$3:G$13,$A$3:$A$13,$C22) -> 18.33045 | F22: =SUMIFS(H$3:H$13,$A$3:$A$13,$C22) -> 20.541375
A23: Connecticut | B23: CT | C23: ISO-NE | D23: =SUMIFS(F$3:F$13,$A$3:$A$13,$C23) -> 54.608411 | E23: =SUMIFS(G$3:G$13,$A$3:$A$13,$C23) -> 52.0868 | F23: =SUMIFS(H$3:H$13,$A$3:$A$13,$C23) -> 39.76053
A24: Delaware | B24: DE | C24: PJM | D24: =SUMIFS(F$3:F$13,$A$3:$A$13,$C24) -> 43.416504 | E24: =SUMIFS(G$3:G$13,$A$3:$A$13,$C24) -> 52.859901 | F24: =SUMIFS(H$3:H$13,$A$3:$A$13,$C24) -> 48.662033
A25: Florida | B25: FL | C25: SERC | D25: =SUMIFS(F$3:F$13,$A$3:$A$13,$C25) -> 29.919744 | E25: =SUMIFS(G$3:G$13,$A$3:$A$13,$C25) -> 32.094544 | F25: =SUMIFS(H$3:H$13,$A$3:$A$13,$C25) -> 29.840267
A26: Georgia | B26: GA | C26: SERC | D26: =SUMIFS(F$3:F$13,$A$3:$A$13,$C26) -> 29.919744 | E26: =SUMIFS(G$3:G$13,$A$3:$A$13,$C26) -> 32.094544 | F26: =SUMIFS(H$3:H$13,$A$3:$A$13,$C26) -> 29.840267
A27: Idaho | B27: ID | C27: Northwest | D27: =SUMIFS(F$3:F$13,$A$3:$A$13,$C27) -> 32.925447 | E27: =SUMIFS(G$3:G$13,$A$3:$A$13,$C27) -> 20.68588 | F27: =SUMIFS(H$3:H$13,$A$3:$A$13,$C27) -> 21.458981
A28: Illinois | B28: IL | C28: MISO | D28: =SUMIFS(F$3:F$13,$A$3:$A$13,$C28) -> 33.828603 | E28: =SUMIFS(G$3:G$13,$A$3:$A$13,$C28) -> 33.387863 | F28: =SUMIFS(H$3:H$13,$A$3:$A$13,$C28) -> 32.549734
A29: Indiana | B29: IN | C29: MISO | D29: =SUMIFS(F$3:F$13,$A$3:$A$13,$C29) -> 33.828603 | E29: =SUMIFS(G$3:G$13,$A$3:$A$13,$C29) -> 33.387863 | F29: =SUMIFS(H$3:H$13,$A$3:$A$13,$C29) -> 32.549734
... A65: Wyoming | B65: WY | C65: Northwest | D65: =SUMIFS(F$3:F$13,$A$3:$A$13,$C65) -> 32.925447 | E65: =SUMIFS(G$3:G$13,$A$3:$A$13,$C65) -> 20.68588 | F65: =SUMIFS(H$3:H$13,$A$3:$A$13,$C65) -> 21.458981

Sheet Intl Imports
D1: Import Mexico? | E1: Import from Canada?
B2: Alabama | C2: AL | D2: FALSE | E2: FALSE
B3: Alaska | C3: AK | D3: FALSE | E3: FALSE
B4: Arizona | C4: AZ | D4: FALSE | E4: FALSE
B5: Arkansas | C5: AR | D5: FALSE | E5: FALSE
B6: California | C6: CA | D6: TRUE | E6: FALSE
B7: Colorado | C7: CO | D7: FALSE | E7: FALSE
B8: Connecticut | C8: CT | D8: FALSE | E8: FALSE
B9: Delaware | C9: DE | D9: FALSE | E9: FALSE
B10: Florida | C10: FL | D10: FALSE | E10: FALSE
B11: Georgia | C11: GA | D11: FALSE | E11: FALSE
B12: Hawaii | C12: HI | D12: FALSE | E12: FALSE
B13: Idaho | C13: ID | D13: FALSE | E13: FALSE
... B51: Wyoming | C51: WY | D51: FALSE | E51: FALSE

Sheet IRA-BIL_IRA-BIL - Mid_annual_st
W1: =INDEX('REEDS crosswalk'!$C:$C,MATCH(W$2,'REEDS crosswalk'!$B:$B,0)) -> battery | X1: =INDEX('REEDS crosswalk'!$C:$C,MATCH(X$2,'REEDS crosswalk'!$B:$B,0)) -> biomass | Y1: =INDEX('REEDS crosswalk'!$C:$C,MATCH(Y$2,'REEDS crosswalk'!$B:$B,0)) -> 0 | Z1: =INDEX('REEDS crosswalk'!$C:$C,MATCH(Z$2,'REEDS crosswalk'!$B:$B,0)) -> hard coal | AA1: =INDEX('REEDS crosswalk'!$C:$C,MATCH(AA$2,'REEDS crosswalk'!$B:$B,0)) -> hard coal | AB1: =INDEX('REEDS crosswalk'!$C:$C,MATCH(AB$2,'REEDS crosswalk'!$B:$B,0)) -> solar pv | AC1: =INDEX('REEDS crosswalk'!$C:$C,MATCH(AC$2,'REEDS crosswalk'!$B:$B,0)) -> 0 | AD1: =INDEX('REEDS crosswalk'!$C:$C,MATCH(AD$2,'REEDS crosswalk'!$B:$B,0)) -> natural gas steam turbine | ... AR1: =INDEX('REEDS crosswalk'!$C:$C,MATCH(AR$2,'REEDS crosswalk'!$B:$B,0)) -> 0
A2: state year | B2: state | C2: t | D2: battery_MW | E2: bio_MW | F2: coal_ccs_MW | G2: coal_MW | H2: csp_MW | I2: distpv_MW | J2: gas_cc_ccs_MW | K2: gas_cc_MW | L2: gas_ct_MW | M2: geo_MW | N2: hydro_MW | O2: nuclear_MW | P2: nuclear_smr_MW | Q2: o-g-s_MW | R2: pumped-hydro_MW | S2: re_ct_MW | T2: upv_MW | U2: wind_offshore_MW | V2: wind_onshore_MW | W2: battery_MWh | X2: bio_MWh | Y2: canada_MWh | Z2: coal_ccs_MWh | AA2: coal_MWh | AB2: csp_MWh | AC2: distpv_MWh | AD2: gas_cc_ccs_MWh | AE2: gas_cc_MWh | AF2: gas_ct_MWh | AG2: geo_MWh | AH2: hydro_MWh | AI2: nuclear_MWh | AJ2: nuclear_smr_MWh | AK2: o-g-s_MWh | AL2: pumped-hydro_MWh | AM2: re_ct_MWh | AN2: upv_MWh | AO2: wind_offshore_MWh | AP2: wind_onshore_MWh | AQ2: generation | AR2: co2_c_mmt
A3: =B3&"_"&C3 -> AL_2022 | B3: AL | C3: 2022 | D3: 0 | E3: 6.4 | F3: 0 | G3: 5790.7 | H3: 0 | I3: 31.2 | J3: 0 | K3: 9689 | L3: 2618.2 | M3: 0 | N3: 3334 | O3: 5544.5 | P3: 0 | Q3: 1738.7 | R3: 0 | S3: 0 | T3: 673.9 | U3: 0 | V3: 0 | W3: 0 | X3: 29415 | Y3: 0 | Z3: 0 | AA3: 33823351 | AB3: 0 | AC3: 47339 | AD3: 0 | AE3: 38649334 | AF3: 1743037 | AG3: 0 | AH3: 9704302 | AI3: 44519210 | AJ3: 0 | AK3: 1243712 | AL3: 0 | AM3: 0 | AN3: 1208752 | AO3: 0 | AP3: 0 | AQ3: 130968453 | AR3: 52
A4: =B4&"_"&C4 -> AL_2023 | B4: AL | C4: 2023 | D4: 0 | E4: 6.4 | F4: 0 | G4: 5790.7 | H4: 0 | I4: 46.8 | J4: 0 | K4: 11004 | L4: 2618.2 | M4: 0 | N4: 3334 | O4: 5544.5 | P4: 0 | Q4: 1738.7 | R4: 0 | S4: 0 | T4: 753.6 | U4: 0 | V4: 0 | W4: 0 | X4: 29415 | Y4: 0 | Z4: 0 | AA4: 32487520 | AB4: 0 | AC4: 70959 | AD4: 0 | AE4: 56967892 | AF4: 1990173 | AG4: 0 | AH4: 9703029 | AI4: 44519210 | AJ4: 0 | AK4: 1402943 | AL4: 0 | AM4: 0 | AN4: 1577345 | AO4: 0 | AP4: 0 | AQ4: 148748486 | AR4: 57.8
A5: =B5&"_"&C5 -> AL_2024 | B5: AL | C5: 2024 | D5: 0 | E5: 6.4 | F5: 0 | G5: 5750.2 | H5: 0 | I5: 62.4 | J5: 0 | K5: 11004 | L5: 1415 | M5: 0 | N5: 3337.2 | O5: 5544.5 | P5: 0 | Q5: 413.8 | R5: 0 | S5: 0 | T5: 757.2 | U5: 0 | V5: 0 | W5: 0 | X5: 29415 | Y5: 0 | Z5: 0 | AA5: 32487156 | AB5: 0 | AC5: 94580 | AD5: 0 | AE5: 63535342 | AF5: 1882275 | AG5: 0 | AH5: 9713363 | AI5: 44519210 | AJ5: 0 | AK5: 441841 | AL5: 0 | AM5: 0 | AN5: 1708516 | AO5: 0 | AP5: 0 | AQ5: 154411698 | AR5: 59.8
A6: =B6&"_"&C6 -> AL_2025 | B6: AL | C6: 2025 | D6: 0 | E6: 6.4 | F6: 3.1 | G6: 5697.6 | H6: 0 | I6: 107.8 | J6: 4.6 | K6: 10996.1 | L6: 1415 | M6: 0 | N6: 3425.3 | O6: 5544.5 | P6: 0 | Q6: 413.8 | R6: 0 | S6: 0 | T6: 758 | U6: 0 | V6: 0 | W6: 0 | X6: 29415 | Y6: 0 | Z6: 20504 | AA6: 32081701 | AB6: 0 | AC6: 163384 | AD6: 30115 | AE6: 59563016 | AF6: 2054863 | AG6: 0 | AH6: 10024547 | AI6: 44519210 | AJ6: 0 | AK6: 472991 | AL6: 0 | AM6: 0 | AN6: 1719481 | AO6: 0 | AP6: 0 | AQ6: 150679227 | AR6: 57.8
A7: =B7&"_"&C7 -> AL_2026 | B7: AL | C7: 2026 | D7: 3.1 | E7: 6.4 | F7: 6.2 | G7: 5643.9 | H7: 0 | I7: 153.2 | J7: 9.2 | K7: 10988.2 | L7: 1415 | M7: 0 | N7: 3428.5 | O7: 5544.5 | P7: 0 | Q7: 413.8 | R7: 0 | S7: 0 | T7: 1606.7 | U7: 0 | V7: 0 | W7: -1439 | X7: 29415 | Y7: 0 | Z7: 41007 | AA7: 31528190 | AB7: 0 | AC7: 95463 | AD7: 60230 | AE7: 52709144 | AF7: 2723312 | AG7: 0 | AH7: 10034680 | AI7: 44519210 | AJ7: 0 | AK7: 685367 | AL7: 0 | AM7: 0 | AN7: 2801553 | AO7: 0 | AP7: 0 | AQ7: 145226132 | AR7: 55
A8: =B8&"_"&C8 -> AL_2027 | B8: AL | C8: 2027 | D8: 61.6 | E8: 6.4 | F8: 9.4 | G8: 5581.4 | H8: 0 | I8: 263.4 | J8: 13.7 | K8: 10969.7 | L8: 1415 | M8: 0 | N8: 3461.7 | O8: 5544.5 | P8: 0 | Q8: 413.8 | R8: 0 | S8: 0 | T8: 3351 | U8: 0 | V8: 0 | W8: -26160 | X8: 29415 | Y8: 0 | Z8: 61511 | AA8: 29644436 | AB8: 0 | AC8: 2783 | AD8: 90345 | AE8: 48386136 | AF8: 2805653 | AG8: 0 | AH8: 10141830 | AI8: 44519210 | AJ8: 0 | AK8: 695939 | AL8: 0 | AM8: 0 | AN8: 6098368 | AO8: 0 | AP8: 0 | AQ8: 142449466 | AR8: 51.4
A9: =B9&"_"&C9 -> AL_2028 | B9: AL | C9: 2028 | D9: 450.2 | E9: 6.4 | F9: 3351.4 | G9: 1342.7 | H9: 0 | I9: 373.6 | J9: 18.3 | K9: 10951.2 | L9: 1415 | M9: 0 | N9: 3486.9 | O9: 5544.5 | P9: 0 | Q9: 413.8 | R9: 0 | S9: 0 | T9: 4790.9 | U9: 0 | V9: 0 | W9: -193341 | X9: 29415 | Y9: 0 | Z9: 23768654 | AA9: 1957399 | AB9: 0 | AC9: 445155 | AD9: 120461 | AE9: 39980532 | AF9: 3306552 | AG9: 0 | AH9: 10194938 | AI9: 44519210 | AJ9: 0 | AK9: 1121991 | AL9: 0 | AM9: 0 | AN9: 10000893 | AO9: 0 | AP9: 0 | AQ9: 135251859 | AR9: 23.7
A10: =B10&"_"&C10 -> AL_2029 | B10: AL | C10: 2029 | D10: 501.7 | E10: 6.4 | F10: 3524.5 | G10: 1326.4 | H10: 0 | I10: 572.1 | J10: 18.3 | K10: 10940.2 | L10: 1415 | M10: 0 | N10: 3490 | O10: 5544.5 | P10: 0 | Q10: 413.8 | R10: 0 | S10: 0 | T10: 8085.4 | U10: 0 | V10: 0 | W10: -150763 | X10: 29415 | Y10: 0 | Z10: 24996353 | AA10: 2293425 | AB10: 0 | AC10: 657804 | AD10: 120461 | AE10: 34593311 | AF10: 4535810 | AG10: 0 | AH10: 10201313 | AI10: 44519210 | AJ10: 0 | AK10: 909000 | AL10: 0 | AM10: 0 | AN10: 17513523 | AO10: 0 | AP10: 0 | AQ10: 140218861 | AR10: 22.6
A11: =B11&"_"&C11 -> AL_2030 | B11: AL | C11: 2030 | D11: 704.6 | E11: 6.4 | F11: 3524.5 | G11: 1306.1 | H11: 0 | I11: 770.5 | J11: 18.3 | K11: 10889.2 | L11: 1415 | M11: 0 | N11: 3493.2 | O11: 5544.5 | P11: 0 | Q11: 413.8 | R11: 0 | S11: 0 | T11: 9523 | U11: 0 | V11: 0 | W11: -255395 | X11: 29415 | Y11: 0 | Z11: 24996353 | AA11: 3113993 | AB11: 0 | AC11: 942856 | AD11: 120461 | AE11: 21979273 | AF11: 4215241 | AG11: 0 | AH11: 10213940 | AI11: 44519210 | AJ11: 0 | AK11: 1086251 | AL11: 0 | AM11: 0 | AN11: 21062677 | AO11: 0 | AP11: 0 | AQ11: 132024275 | AR11: 18.3
A12: =B12&"_"&C12 -> AR_2022 | B12: AR | C12: 2022 | D12: 0 | E12: 16.8 | F12: 0 | G12: 5128.1 | H12: 0 | I12: 87.6 | J12: 0 | K12: 4597 | L12: 715.6 | M12: 0 | N12: 1265.8 | O12: 1817.8 | P12: 0 | Q12: 787 | R12: 30 | S12: 0 | T12: 306.7 | U12: 0 | V12: 0 | W12: 0 | X12: 40369 | Y12: 0 | Z12: 0 | AA12: 29909120 | AB12: 0 | AC12: 129118 | AD12: 0 | AE12: 11577177 | AF12: 789123 | AG12: 0 | AH12: 2917131 | AI12: 14613013 | AJ12: 0 | AK12: 281525 | AL12: -6597 | AM12: 0 | AN12: 573458 | AO12: 0 | AP12: 0 | AQ12: 60823436 | AR12: 35.8
A13: =B13&"_"&C13 -> AR_2023 | B13: AR | C13: 2023 | D13: 0 | E13: 16.8 | F13: 0 | G13: 5128.1 | H13: 0 | I13: 181 | J13: 0 | K13: 4597 | L13: 715.6 | M13: 0 | N13: 1265.8 | O13: 1817.8 | P13: 0 | Q13: 787 | R13: 30 | S13: 0 | T13: 306.7 | U13: 0 | V13: 0 | W13: 0 | X13: 40369 | Y13: 0 | Z13: 0 | AA13: 15368075 | AB13: 0 | AC13: 266673 | AD13: 0 | AE13: 11735490 | AF13: 924812 | AG13: 0 | AH13: 2917131 | AI13: 14613013 | AJ13: 0 | AK13: 281525 | AL13: -4914 | AM13: 0 | AN13: 674270 | AO13: 0 | AP13: 0 | AQ13: 46816445 | AR13: 20.5
A14: =B14&"_"&C14 -> AR_2024 | B14: AR | C14: 2024 | D14: 0 | E14: 16.8 | F14: 0 | G14: 5124.4 | H14: 0 | I14: 274.4 | J14: 0 | K14: 4597 | L14: 705.4 | M14: 0 | N14: 1266.8 | O14: 1817.8 | P14: 0 | Q14: 352.4 | R14: 30 | S14: 0 | T14: 455.2 | U14: 0 | V14: 0 | W14: 0 | X14: 40369 | Y14: 0 | Z14: 0 | AA14: 13411216 | AB14: 0 | AC14: 383985 | AD14: 0 | AE14: 12566671 | AF14: 800487 | AG14: 0 | AH14: 2919630 | AI14: 14613013 | AJ14: 0 | AK14: 150536 | AL14: -4361 | AM14: 0 | AN14: 990857 | AO14: 0 | AP14: 0 | AQ14: 45872404 | AR14: 18.7
... A434: =B434&"_"&C434 -> WY_2030 | B434: WY | C434: 2030 | D434: 200.9 | E434: 0 | F434: 1550.5 | G434: 2419.2 | H434: 0 | I434: 37.5 | J434: 36.6 | K434: 93.4 | L434: 0 | M434: 0 | N434: 307.4 | O434: 0 | P434: 345 | Q434: 0 | R434: 0 | S434: 0 | T434: 92 | U434: 0 | V434: 17550.3 | W434: -44004 | X434: 0 | Y434: 0 | Z434: 10996147 | AA434: 1396334 | AB434: 0 | AC434: 43766 | AD434: 240921 | AE434: 56414 | AF434: 0 | AG434: 0 | AH434: 1037875 | AI434: 0 | AJ434: 1969158 | AK434: 0 | AL434: 0 | AM434: 0 | AN434: 139007 | AO434: 0 | AP434: 69156087 | AQ434: 84991706 | AR434: 3.1

Sheet REEDS crosswalk
B2: state
B3: t
B4: battery_MW | C4: battery
B5: bio_MW | C5: biomass
B6: coal_ccs_MW | C6: hard coal
B7: coal_MW | C7: hard coal
B8: csp_MW | C8: solar pv
B9: distpv_MW
B10: gas_cc_ccs_MW | C10: natural gas steam turbine
B11: gas_cc_MW | C11: natural gas steam turbine
B12: gas_ct_MW | C12: natural gas steam turbine
B13: geo_MW | C13: geothermal
B14: hydro_MW | C14: hydro
B15: nuclear_MW | C15: nuclear
B16: nuclear_smr_MW | C16: nuclear
B17: o-g-s_MW | C17: petroleum
B18: pumped-hydro_MW | C18: pumped hydro
B19: re_ct_MW
B20: upv_MW | C20: solar pv
B21: wind_offshore_MW | C21: offshore wind
B22: wind_onshore_MW | C22: onshore wind
B23: battery_MWh | C23: battery
B24: bio_MWh | C24: biomass
B25: canada_MWh
B26: coal_ccs_MWh | C26: hard coal
B27: coal_MWh | C27: hard coal
B28: csp_MWh | C28: solar pv
B29: distpv_MWh
B30: gas_cc_ccs_MWh | C30: natural gas steam turbine
B31: gas_cc_MWh | C31: natural gas steam turbine
B32: gas_ct_MWh | C32: natural gas steam turbine
B33: geo_MWh | C33: geothermal
B34: hydro_MWh | C34: hydro
B35: nuclear_MWh | C35: nuclear
B36: nuclear_smr_MWh | C36: nuclear
B37: o-g-s_MWh | C37: petroleum
B38: pumped-hydro_MWh | C38: pumped hydro
B39: re_ct_MWh
B40: upv_MWh | C40: solar pv
B41: wind_offshore_MWh | C41: offshore wind
...

Sheet REEDS summary
A1: REEDS Data Summarized | M1: Percent of Total
A2: AL | C2: =$A2&"_"&C3 -> AL_2022 | D2: =$A2&"_"&D3 -> AL_2023 | E2: =$A2&"_"&E3 -> AL_2024 | F2: =$A2&"_"&F3 -> AL_2025 | G2: =$A2&"_"&G3 -> AL_2026 | H2: =$A2&"_"&H3 -> AL_2027 | I2: =$A2&"_"&I3 -> AL_2028 | J2: =$A2&"_"&J3 -> AL_2029 | K2: =$A2&"_"&K3 -> AL_2030 | M2: =$A2&"_"&M3 -> AL_2022 | N2: =$A2&"_"&N3 -> AL_2023 | O2: =$A2&"_"&O3 -> AL_2024 | P2: =$A2&"_"&P3 -> AL_2025 | Q2: =$A2&"_"&Q3 -> AL_2026 | R2: =$A2&"_"&R3 -> AL_2027 | S2: =$A2&"_"&S3 -> AL_2028 | T2: =$A2&"_"&T3 -> AL_2029 | U2: =$A2&"_"&U3 -> AL_2030
C3: 2022 | D3: 2023 | E3: 2024 | F3: 2025 | G3: 2026 | H3: 2027 | I3: 2028 | J3: 2029 | K3: 2030 | M3: 2022 | N3: 2023 | O3: 2024 | P3: 2025 | Q3: 2026 | R3: 2027 | S3: 2028 | T3: 2029 | U3: 2030
A4: =A2 -> AL | B4: battery | C4: 0 | D4: 0 | E4: 0 | F4: 0 | G4: 0 | H4: 0 | I4: 0 | J4: 0 | K4: 0 | M4: 0 | N4: 0 | O4: 0 | P4: 0 | Q4: 0 | R4: 0 | S4: 0 | T4: 0 | U4: 0
A5: =A4 -> AL | B5: biomass | C5: =SUMIFS(INDEX('IRA-BIL_IRA-BIL - Mid_annual_st'!$W$3:$AR$434,MATCH(C2,'IRA-BIL_IRA-BIL - Mid_annual_st'!$A$3:$A$434,0),),'IRA-BIL_IRA-BIL - Mid_annual_st'!$W$1:$AR$1,$B5) -> 29415 | D5: =SUMIFS(INDEX('IRA-BIL_IRA-BIL - Mid_annual_st'!$W$3:$AR$434,MATCH(D2,'IRA-BIL_IRA-BIL - Mid_annual_st'!$A$3:$A$434,0),),'IRA-BIL_IRA-BIL - Mid_annual_st'!$W$1:$AR$1,$B5) -> 29415 | E5: =SUMIFS(INDEX('IRA-BIL_IRA-BIL - Mid_annual_st'!$W$3:$AR$434,MATCH(E2,'IRA-BIL_IRA-BIL - Mid_annual_st'!$A$3:$A$434,0),),'IRA-BIL_IRA-BIL - Mid_annual_st'!$W$1:$AR$1,$B5) -> 29415 | F5: =SUMIFS(INDEX('IRA-BIL_IRA-BIL - Mid_annual_st'!$W$3:$AR$434,MATCH(F2,'IRA-BIL_IRA-BIL - Mid_annual_st'!$A$3:$A$434,0),),'IRA-BIL_IRA-BIL - Mid_annual_st'!$W$1:$AR$1,$B5) -> 29415 | G5: =SUMIFS(INDEX('IRA-BIL_IRA-BIL - Mid_annual_st'!$W$3:$AR$434,MATCH(G2,'IRA-BIL_IRA-BIL - Mid_annual_st'!$A$3:$A$434,0),),'IRA-BIL_IRA-BIL - Mid_annual_st'!$W$1:$AR$1,$B5) -> 29415 | H5: =SUMIFS(INDEX('IRA-BIL_IRA-BIL - Mid_annual_st'!$W$3:$AR$434,MATCH(H2,'IRA-BIL_IRA-BIL - Mid_annual_st'!$A$3:$A$434,0),),'IRA-BIL_IRA-BIL - Mid_annual_st'!$W$1:$AR$1,$B5) -> 29415 | I5: =SUMIFS(INDEX('IRA-BIL_IRA-BIL - Mid_annual_st'!$W$3:$AR$434,MATCH(I2,'IRA-BIL_IRA-BIL - Mid_annual_st'!$A$3:$A$434,0),),'IRA-BIL_IRA-BIL - Mid_annual_st'!$W$1:$AR$1,$B5) -> 29415 | J5: =SUMIFS(INDEX('IRA-BIL_IRA-BIL - Mid_annual_st'!$W$3:$AR$434,MATCH(J2,'IRA-BIL_IRA-BIL - Mid_annual_st'!$A$3:$A$434,0),),'IRA-BIL_IRA-BIL - Mid_annual_st'!$W$1:$AR$1,$B5) -> 29415 | K5: =SUMIFS(INDEX('IRA-BIL_IRA-BIL - Mid_annual_st'!$W$3:$AR$434,MATCH(K2,'IRA-BIL_IRA-BIL - Mid_annual_st'!$A$3:$A$434,0),),'IRA-BIL_IRA-BIL - Mid_annual_st'!$W$1:$AR$1,$B5) -> 29415 | M5: =C5/SUM(C4:C15) -> 0.00022467728 | N5: =D5/SUM(D4:D15) -> 0.00019784429 | O5: =E5/SUM(E4:E15) -> 0.00019061398 | P5: =F5/SUM(F4:F15) -> 0.00019542793 | Q5: =G5/SUM(G4:G15) -> 0.00020267741 | R5: =H5/SUM(H4:H15) -> 0.0002064604 | S5: =I5/SUM(I4:I15) -> 0.00021788882 | T5: =J5/SUM(J4:J15) -> 0.00021054052 | U5: =K5/SUM(K4:K15) -> 0.00022396615
A6: =A5 -> AL | B6: hard coal | C6: =SUMIFS(INDEX('IRA-BIL_IRA-BIL - Mid_annual_st'!$W$3:$AR$434,MATCH(C2,'IRA-BIL_IRA-BIL - Mid_annual_st'!$A$3:$A$434,0),),'IRA-BIL_IRA-BIL - Mid_annual_st'!$W$1:$AR$1,$B6) -> 33823351 | D6: =SUMIFS(INDEX('IRA-BIL_IRA-BIL - Mid_annual_st'!$W$3:$AR$434,MATCH(D2,'IRA-BIL_IRA-BIL - Mid_annual_st'!$A$3:$A$434,0),),'IRA-BIL_IRA-BIL - Mid_annual_st'!$W$1:$AR$1,$B6) -> 32487520 | E6: =SUMIFS(INDEX('IRA-BIL_IRA-BIL - Mid_annual_st'!$W$3:$AR$434,MATCH(E2,'IRA-BIL_IRA-BIL - Mid_annual_st'!$A$3:$A$434,0),),'IRA-BIL_IRA-BIL - Mid_annual_st'!$W$1:$AR$1,$B6) -> 32487156 | F6: =SUMIFS(INDEX('IRA-BIL_IRA-BIL - Mid_annual_st'!$W$3:$AR$434,MATCH(F2,'IRA-BIL_IRA-BIL - Mid_annual_st'!$A$3:$A$434,0),),'IRA-BIL_IRA-BIL - Mid_annual_st'!$W$1:$AR$1,$B6) -> 32102205 | G6: =SUMIFS(INDEX('IRA-BIL_IRA-BIL - Mid_annual_st'!$W$3:$AR$434,MATCH(G2,'IRA-BIL_IRA-BIL - Mid_annual_st'!$A$3:$A$434,0),),'IRA-BIL_IRA-BIL - Mid_annual_st'!$W$1:$AR$1,$B6) -> 31569197 | H6: =SUMIFS(INDEX('IRA-BIL_IRA-BIL - Mid_annual_st'!$W$3:$AR$434,MATCH(H2,'IRA-BIL_IRA-BIL - Mid_annual_st'!$A$3:$A$434,0),),'IRA-BIL_IRA-BIL - Mid_annual_st'!$W$1:$AR$1,$B6) -> 29705947 | I6: =SUMIFS(INDEX('IRA-BIL_IRA-BIL - Mid_annual_st'!$W$3:$AR$434,MATCH(I2,'IRA-BIL_IRA-BIL - Mid_annual_st'!$A$3:$A$434,0),),'IRA-BIL_IRA-BIL - Mid_annual_st'!$W$1:$AR$1,$B6) -> 25726053 | J6: =SUMIFS(INDEX('IRA-BIL_IRA-BIL - Mid_annual_st'!$W$3:$AR$434,MATCH(J2,'IRA-BIL_IRA-BIL - Mid_annual_st'!$A$3:$A$434,0),),'IRA-BIL_IRA-BIL - Mid_annual_st'!$W$1:$AR$1,$B6) -> 27289778 | K6: =SUMIFS(INDEX('IRA-BIL_IRA-BIL - Mid_annual_st'!$W$3:$AR$434,MATCH(K2,'IRA-BIL_IRA-BIL - Mid_annual_st'!$A$3:$A$434,0),),'IRA-BIL_IRA-BIL - Mid_annual_st'!$W$1:$AR$1,$B6) -> 28110346 | M6: =C6/SUM(C4:C15) -> 0.25834909 | N6: =D6/SUM(D4:D15) -> 0.21850996 | O6: =E6/SUM(E4:E15) -> 0.21052205 | P6: =F6/SUM(F4:F15) -> 0.21328124 | Q6: =G6/SUM(G4:G15) -> 0.21752042 | R6: =H6/SUM(H4:H15) -> 0.20850252 | S6: =I6/SUM(I4:I15) -> 0.19056329 | T6: =J6/SUM(J4:J15) -> 0.19532906 | U6: =K6/SUM(K4:K15) -> 0.2140325
A7: =A6 -> AL | B7: geothermal | C7: =SUMIFS(INDEX('IRA-BIL_IRA-BIL - Mid_annual_st'!$W$3:$AR$434,MATCH(C2,'IRA-BIL_IRA-BIL - Mid_annual_st'!$A$3:$A$434,0),),'IRA-BIL_IRA-BIL - Mid_annual_st'!$W$1:$AR$1,$B7) -> 0 | D7: =SUMIFS(INDEX('IRA-BIL_IRA-BIL - Mid_annual_st'!$W$3:$AR$434,MATCH(D2,'IRA-BIL_IRA-BIL - Mid_annual_st'!$A$3:$A$434,0),),'IRA-BIL_IRA-BIL - Mid_annual_st'!$W$1:$AR$1,$B7) -> 0 | E7: =SUMIFS(INDEX('IRA-BIL_IRA-BIL - Mid_annual_st'!$W$3:$AR$434,MATCH(E2,'IRA-BIL_IRA-BIL - Mid_annual_st'!$A$3:$A$434,0),),'IRA-BIL_IRA-BIL - Mid_annual_st'!$W$1:$AR$1,$B7) -> 0 | F7: =SUMIFS(INDEX('IRA-BIL_IRA-BIL - Mid_annual_st'!$W$3:$AR$434,MATCH(F2,'IRA-BIL_IRA-BIL - Mid_annual_st'!$A$3:$A$434,0),),'IRA-BIL_IRA-BIL - Mid_annual_st'!$W$1:$AR$1,$B7) -> 0 | G7: =SUMIFS(INDEX('IRA-BIL_IRA-BIL - Mid_annual_st'!$W$3:$AR$434,MATCH(G2,'IRA-BIL_IRA-BIL - Mid_annual_st'!$A$3:$A$434,0),),'IRA-BIL_IRA-BIL - Mid_annual_st'!$W$1:$AR$1,$B7) -> 0 | H7: =SUMIFS(INDEX('IRA-BIL_IRA-BIL - Mid_annual_st'!$W$3:$AR$434,MATCH(H2,'IRA-BIL_IRA-BIL - Mid_annual_st'!$A$3:$A$434,0),),'IRA-BIL_IRA-BIL - Mid_annual_st'!$W$1:$AR$1,$B7) -> 0 | I7: =SUMIFS(INDEX('IRA-BIL_IRA-BIL - Mid_annual_st'!$W$3:$AR$434,MATCH(I2,'IRA-BIL_IRA-BIL - Mid_annual_st'!$A$3:$A$434,0),),'IRA-BIL_IRA-BIL - Mid_annual_st'!$W$1:$AR$1,$B7) -> 0 | J7: =SUMIFS(INDEX('IRA-BIL_IRA-BIL - Mid_annual_st'!$W$3:$AR$434,MATCH(J2,'IRA-BIL_IRA-BIL - Mid_annual_st'!$A$3:$A$434,0),),'IRA-BIL_IRA-BIL - Mid_annual_st'!$W$1:$AR$1,$B7) -> 0 | K7: =SUMIFS(INDEX('IRA-BIL_IRA-BIL - Mid_annual_st'!$W$3:$AR$434,MATCH(K2,'IRA-BIL_IRA-BIL - Mid_annual_st'!$A$3:$A$434,0),),'IRA-BIL_IRA-BIL - Mid_annual_st'!$W$1:$AR$1,$B7) -> 0 | M7: =C7/SUM(C4:C15) -> 0 | N7: =D7/SUM(D4:D15) -> 0 | O7: =E7/SUM(E4:E15) -> 0 | P7: =F7/SUM(F4:F15) -> 0 | Q7: =G7/SUM(G4:G15) -> 0 | R7: =H7/SUM(H4:H15) -> 0 | S7: =I7/SUM(I4:I15) -> 0 | T7: =J7/SUM(J4:J15) -> 0 | U7: =K7/SUM(K4:K15) -> 0
A8: =A7 -> AL | B8: hydro | C8: =SUMIFS(INDEX('IRA-BIL_IRA-BIL - Mid_annual_st'!$W$3:$AR$434,MATCH(C2,'IRA-BIL_IRA-BIL - Mid_annual_st'!$A$3:$A$434,0),),'IRA-BIL_IRA-BIL - Mid_annual_st'!$W$1:$AR$1,$B8) -> 9704302 | D8: =SUMIFS(INDEX('IRA-BIL_IRA-BIL - Mid_annual_st'!$W$3:$AR$434,MATCH(D2,'IRA-BIL_IRA-BIL - Mid_annual_st'!$A$3:$A$434,0),),'IRA-BIL_IRA-BIL - Mid_annual_st'!$W$1:$AR$1,$B8) -> 9703029 | E8: =SUMIFS(INDEX('IRA-BIL_IRA-BIL - Mid_annual_st'!$W$3:$AR$434,MATCH(E2,'IRA-BIL_IRA-BIL - Mid_annual_st'!$A$3:$A$434,0),),'IRA-BIL_IRA-BIL - Mid_annual_st'!$W$1:$AR$1,$B8) -> 9713363 | F8: =SUMIFS(INDEX('IRA-BIL_IRA-BIL - Mid_annual_st'!$W$3:$AR$434,MATCH(F2,'IRA-BIL_IRA-BIL - Mid_annual_st'!$A$3:$A$434,0),),'IRA-BIL_IRA-BIL - Mid_annual_st'!$W$1:$AR$1,$B8) -> 10024547 | G8: =SUMIFS(INDEX('IRA-BIL_IRA-BIL - Mid_annual_st'!$W$3:$AR$434,MATCH(G2,'IRA-BIL_IRA-BIL - Mid_annual_st'!$A$3:$A$434,0),),'IRA-BIL_IRA-BIL - Mid_annual_st'!$W$1:$AR$1,$B8) -> 10034680 | H8: =SUMIFS(INDEX('IRA-BIL_IRA-BIL - Mid_annual_st'!$W$3:$AR$434,MATCH(H2,'IRA-BIL_IRA-BIL - Mid_annual_st'!$A$3:$A$434,0),),'IRA-BIL_IRA-BIL - Mid_annual_st'!$W$1:$AR$1,$B8) -> 10141830 | I8: =SUMIFS(INDEX('IRA-BIL_IRA-BIL - Mid_annual_st'!$W$3:$AR$434,MATCH(I2,'IRA-BIL_IRA-BIL - Mid_annual_st'!$A$3:$A$434,0),),'IRA-BIL_IRA-BIL - Mid_annual_st'!$W$1:$AR$1,$B8) -> 10194938 | J8: =SUMIFS(INDEX('IRA-BIL_IRA-BIL - Mid_annual_st'!$W$3:$AR$434,MATCH(J2,'IRA-BIL_IRA-BIL - Mid_annual_st'!$A$3:$A$434,0),),'IRA-BIL_IRA-BIL - Mid_annual_st'!$W$1:$AR$1,$B8) -> 10201313 | K8: =SUMIFS(INDEX('IRA-BIL_IRA-BIL - Mid_annual_st'!$W$3:$AR$434,MATCH(K2,'IRA-BIL_IRA-BIL - Mid_annual_st'!$A$3:$A$434,0),),'IRA-BIL_IRA-BIL - Mid_annual_st'!$W$1:$AR$1,$B8) -> 10213940 | M8: =C8/SUM(C4:C15) -> 0.074123278 | N8: =D8/SUM(D4:D15) -> 0.065262244 | O8: =E8/SUM(E4:E15) -> 0.062944171 | P8: =F8/SUM(F4:F15) -> 0.066601275 | Q8: =G8/SUM(G4:G15) -> 0.069141695 | R8: =H8/SUM(H4:H15) -> 0.071184303 | S8: =I8/SUM(I4:I15) -> 0.075518034 | T8: =J8/SUM(J4:J15) -> 0.073016821 | U8: =K8/SUM(K4:K15) -> 0.077769056
A9: =A8 -> AL | B9: natural gas steam turbine | C9: =SUMIFS(INDEX('IRA-BIL_IRA-BIL - Mid_annual_st'!$W$3:$AR$434,MATCH(C2,'IRA-BIL_IRA-BIL - Mid_annual_st'!$A$3:$A$434,0),),'IRA-BIL_IRA-BIL - Mid_annual_st'!$W$1:$AR$1,$B9) -> 40392371 | D9: =SUMIFS(INDEX('IRA-BIL_IRA-BIL - Mid_annual_st'!$W$3:$AR$434,MATCH(D2,'IRA-BIL_IRA-BIL - Mid_annual_st'!$A$3:$A$434,0),),'IRA-BIL_IRA-BIL - Mid_annual_st'!$W$1:$AR$1,$B9) -> 58958065 | E9: =SUMIFS(INDEX('IRA-BIL_IRA-BIL - Mid_annual_st'!$W$3:$AR$434,MATCH(E2,'IRA-BIL_IRA-BIL - Mid_annual_st'!$A$3:$A$434,0),),'IRA-BIL_IRA-BIL - Mid_annual_st'!$W$1:$AR$1,$B9) -> 65417617 | F9: =SUMIFS(INDEX('IRA-BIL_IRA-BIL - Mid_annual_st'!$W$3:$AR$434,MATCH(F2,'IRA-BIL_IRA-BIL - Mid_annual_st'!$A$3:$A$434,0),),'IRA-BIL_IRA-BIL - Mid_annual_st'!$W$1:$AR$1,$B9) -> 61647994 | G9: =SUMIFS(INDEX('IRA-BIL_IRA-BIL - Mid_annual_st'!$W$3:$AR$434,MATCH(G2,'IRA-BIL_IRA-BIL - Mid_annual_st'!$A$3:$A$434,0),),'IRA-BIL_IRA-BIL - Mid_annual_st'!$W$1:$AR$1,$B9) -> 55492686 | H9: =SUMIFS(INDEX('IRA-BIL_IRA-BIL - Mid_annual_st'!$W$3:$AR$434,MATCH(H2,'IRA-BIL_IRA-BIL - Mid_annual_st'!$A$3:$A$434,0),),'IRA-BIL_IRA-BIL - Mid_annual_st'!$W$1:$AR$1,$B9) -> 51282134 | I9: =SUMIFS(INDEX('IRA-BIL_IRA-BIL - Mid_annual_st'!$W$3:$AR$434,MATCH(I2,'IRA-BIL_IRA-BIL - Mid_annual_st'!$A$3:$A$434,0),),'IRA-BIL_IRA-BIL - Mid_annual_st'!$W$1:$AR$1,$B9) -> 43407545 | J9: =SUMIFS(INDEX('IRA-BIL_IRA-BIL - Mid_annual_st'!$W$3:$AR$434,MATCH(J2,'IRA-BIL_IRA-BIL - Mid_annual_st'!$A$3:$A$434,0),),'IRA-BIL_IRA-BIL - Mid_annual_st'!$W$1:$AR$1,$B9) -> 39249582 | K9: =SUMIFS(INDEX('IRA-BIL_IRA-BIL - Mid_annual_st'!$W$3:$AR$434,MATCH(K2,'IRA-BIL_IRA-BIL - Mid_annual_st'!$A$3:$A$434,0),),'IRA-BIL_IRA-BIL - Mid_annual_st'!$W$1:$AR$1,$B9) -> 26314975 | M9: =C9/SUM(C4:C15) -> 0.3085245 | N9: =D9/SUM(D4:D15) -> 0.39654994 | O9: =E9/SUM(E4:E15) -> 0.42391679 | P9: =F9/SUM(F4:F15) -> 0.40957811 | Q9: =G9/SUM(G4:G15) -> 0.38235982 | R9: =H9/SUM(H4:H15) -> 0.35994322 | S9: =I9/SUM(I4:I15) -> 0.32153726 | T9: =J9/SUM(J4:J15) -> 0.28093243 | U9: =K9/SUM(K4:K15) -> 0.20036252
A10: =A9 -> AL | B10: nuclear | C10: =SUMIFS(INDEX('IRA-BIL_IRA-BIL - Mid_annual_st'!$W$3:$AR$434,MATCH(C2,'IRA-BIL_IRA-BIL - Mid_annual_st'!$A$3:$A$434,0),),'IRA-BIL_IRA-BIL - Mid_annual_st'!$W$1:$AR$1,$B10) -> 44519210 | D10: =SUMIFS(INDEX('IRA-BIL_IRA-BIL - Mid_annual_st'!$W$3:$AR$434,MATCH(D2,'IRA-BIL_IRA-BIL - Mid_annual_st'!$A$3:$A$434,0),),'IRA-BIL_IRA-BIL - Mid_annual_st'!$W$1:$AR$1,$B10) -> 44519210 | E10: =SUMIFS(INDEX('IRA-BIL_IRA-BIL - Mid_annual_st'!$W$3:$AR$434,MATCH(E2,'IRA-BIL_IRA-BIL - Mid_annual_st'!$A$3:$A$434,0),),'IRA-BIL_IRA-BIL - Mid_annual_st'!$W$1:$AR$1,$B10) -> 44519210 | F10: =SUMIFS(INDEX('IRA-BIL_IRA-BIL - Mid_annual_st'!$W$3:$AR$434,MATCH(F2,'IRA-BIL_IRA-BIL - Mid_annual_st'!$A$3:$A$434,0),),'IRA-BIL_IRA-BIL - Mid_annual_st'!$W$1:$AR$1,$B10) -> 44519210 | G10: =SUMIFS(INDEX('IRA-BIL_IRA-BIL - Mid_annual_st'!$W$3:$AR$434,MATCH(G2,'IRA-BIL_IRA-BIL - Mid_annual_st'!$A$3:$A$434,0),),'IRA-BIL_IRA-BIL - Mid_annual_st'!$W$1:$AR$1,$B10) -> 44519210 | H10: =SUMIFS(INDEX('IRA-BIL_IRA-BIL - Mid_annual_st'!$W$3:$AR$434,MATCH(H2,'IRA-BIL_IRA-BIL - Mid_annual_st'!$A$3:$A$434,0),),'IRA-BIL_IRA-BIL - Mid_annual_st'!$W$1:$AR$1,$B10) -> 44519210 | I10: =SUMIFS(INDEX('IRA-BIL_IRA-BIL - Mid_annual_st'!$W$3:$AR$434,MATCH(I2,'IRA-BIL_IRA-BIL - Mid_annual_st'!$A$3:$A$434,0),),'IRA-BIL_IRA-BIL - Mid_annual_st'!$W$1:$AR$1,$B10) -> 44519210 | J10: =SUMIFS(INDEX('IRA-BIL_IRA-BIL - Mid_annual_st'!$W$3:$AR$434,MATCH(J2,'IRA-BIL_IRA-BIL - Mid_annual_st'!$A$3:$A$434,0),),'IRA-BIL_IRA-BIL - Mid_annual_st'!$W$1:$AR$1,$B10) -> 44519210 | K10: =SUMIFS(INDEX('IRA-BIL_IRA-BIL - Mid_annual_st'!$W$3:$AR$434,MATCH(K2,'IRA-BIL_IRA-BIL - Mid_annual_st'!$A$3:$A$434,0),),'IRA-BIL_IRA-BIL - Mid_annual_st'!$W$1:$AR$1,$B10) -> 44519210 | M10: =C10/SUM(C4:C15) -> 0.34004607 | N10: =D10/SUM(D4:D15) -> 0.2994347 | O10: =E10/SUM(E4:E15) -> 0.28849171 | P10: =F10/SUM(F4:F15) -> 0.29577757 | Q10: =G10/SUM(G4:G15) -> 0.30674956 | R10: =H10/SUM(H4:H15) -> 0.31247506 | S10: =I10/SUM(I4:I15) -> 0.32977182 | T10: =J10/SUM(J4:J15) -> 0.31865027 | U10: =K10/SUM(K4:K15) -> 0.33896977
A11: =A10 -> AL | B11: offshore wind | C11: =SUMIFS(INDEX('IRA-BIL_IRA-BIL - Mid_annual_st'!$W$3:$AR$434,MATCH(C2,'IRA-BIL_IRA-BIL - Mid_annual_st'!$A$3:$A$434,0),),'IRA-BIL_IRA-BIL - Mid_annual_st'!$W$1:$AR$1,$B11) -> 0 | D11: =SUMIFS(INDEX('IRA-BIL_IRA-BIL - Mid_annual_st'!$W$3:$AR$434,MATCH(D2,'IRA-BIL_IRA-BIL - Mid_annual_st'!$A$3:$A$434,0),),'IRA-BIL_IRA-BIL - Mid_annual_st'!$W$1:$AR$1,$B11) -> 0 | E11: =SUMIFS(INDEX('IRA-BIL_IRA-BIL - Mid_annual_st'!$W$3:$AR$434,MATCH(E2,'IRA-BIL_IRA-BIL - Mid_annual_st'!$A$3:$A$434,0),),'IRA-BIL_IRA-BIL - Mid_annual_st'!$W$1:$AR$1,$B11) -> 0 | F11: =SUMIFS(INDEX('IRA-BIL_IRA-BIL - Mid_annual_st'!$W$3:$AR$434,MATCH(F2,'IRA-BIL_IRA-BIL - Mid_annual_st'!$A$3:$A$434,0),),'IRA-BIL_IRA-BIL - Mid_annual_st'!$W$1:$AR$1,$B11) -> 0 | G11: =SUMIFS(INDEX('IRA-BIL_IRA-BIL - Mid_annual_st'!$W$3:$AR$434,MATCH(G2,'IRA-BIL_IRA-BIL - Mid_annual_st'!$A$3:$A$434,0),),'IRA-BIL_IRA-BIL - Mid_annual_st'!$W$1:$AR$1,$B11) -> 0 | H11: =SUMIFS(INDEX('IRA-BIL_IRA-BIL - Mid_annual_st'!$W$3:$AR$434,MATCH(H2,'IRA-BIL_IRA-BIL - Mid_annual_st'!$A$3:$A$434,0),),'IRA-BIL_IRA-BIL - Mid_annual_st'!$W$1:$AR$1,$B11) -> 0 | I11: =SUMIFS(INDEX('IRA-BIL_IRA-BIL - Mid_annual_st'!$W$3:$AR$434,MATCH(I2,'IRA-BIL_IRA-BIL - Mid_annual_st'!$A$3:$A$434,0),),'IRA-BIL_IRA-BIL - Mid_annual_st'!$W$1:$AR$1,$B11) -> 0 | J11: =SUMIFS(INDEX('IRA-BIL_IRA-BIL - Mid_annual_st'!$W$3:$AR$434,MATCH(J2,'IRA-BIL_IRA-BIL - Mid_annual_st'!$A$3:$A$434,0),),'IRA-BIL_IRA-BIL - Mid_annual_st'!$W$1:$AR$1,$B11) -> 0 | K11: =SUMIFS(INDEX('IRA-BIL_IRA-BIL - Mid_annual_st'!$W$3:$AR$434,MATCH(K2,'IRA-BIL_IRA-BIL - Mid_annual_st'!$A$3:$A$434,0),),'IRA-BIL_IRA-BIL - Mid_annual_st'!$W$1:$AR$1,$B11) -> 0 | M11: =C11/SUM(C4:C15) -> 0 | N11: =D11/SUM(D4:D15) -> 0 | O11: =E11/SUM(E4:E15) -> 0 | P11: =F11/SUM(F4:F15) -> 0 | Q11: =G11/SUM(G4:G15) -> 0 | R11: =H11/SUM(H4:H15) -> 0 | S11: =I11/SUM(I4:I15) -> 0 | T11: =J11/SUM(J4:J15) -> 0 | U11: =K11/SUM(K4:K15) -> 0
A12: =A11 -> AL | B12: petroleum | C12: =SUMIFS(INDEX('IRA-BIL_IRA-BIL - Mid_annual_st'!$W$3:$AR$434,MATCH(C2,'IRA-BIL_IRA-BIL - Mid_annual_st'!$A$3:$A$434,0),),'IRA-BIL_IRA-BIL - Mid_annual_st'!$W$1:$AR$1,$B12) -> 1243712 | D12: =SUMIFS(INDEX('IRA-BIL_IRA-BIL - Mid_annual_st'!$W$3:$AR$434,MATCH(D2,'IRA-BIL_IRA-BIL - Mid_annual_st'!$A$3:$A$434,0),),'IRA-BIL_IRA-BIL - Mid_annual_st'!$W$1:$AR$1,$B12) -> 1402943 | E12: =SUMIFS(INDEX('IRA-BIL_IRA-BIL - Mid_annual_st'!$W$3:$AR$434,MATCH(E2,'IRA-BIL_IRA-BIL - Mid_annual_st'!$A$3:$A$434,0),),'IRA-BIL_IRA-BIL - Mid_annual_st'!$W$1:$AR$1,$B12) -> 441841 | F12: =SUMIFS(INDEX('IRA-BIL_IRA-BIL - Mid_annual_st'!$W$3:$AR$434,MATCH(F2,'IRA-BIL_IRA-BIL - Mid_annual_st'!$A$3:$A$434,0),),'IRA-BIL_IRA-BIL - Mid_annual_st'!$W$1:$AR$1,$B12) -> 472991 | G12: =SUMIFS(INDEX('IRA-BIL_IRA-BIL - Mid_annual_st'!$W$3:$AR$434,MATCH(G2,'IRA-BIL_IRA-BIL - Mid_annual_st'!$A$3:$A$434,0),),'IRA-BIL_IRA-BIL - Mid_annual_st'!$W$1:$AR$1,$B12) -> 685367 | H12: =SUMIFS(INDEX('IRA-BIL_IRA-BIL - Mid_annual_st'!$W$3:$AR$434,MATCH(H2,'IRA-BIL_IRA-BIL - Mid_annual_st'!$A$3:$A$434,0),),'IRA-BIL_IRA-BIL - Mid_annual_st'!$W$1:$AR$1,$B12) -> 695939 | I12: =SUMIFS(INDEX('IRA-BIL_IRA-BIL - Mid_annual_st'!$W$3:$AR$434,MATCH(I2,'IRA-BIL_IRA-BIL - Mid_annual_st'!$A$3:$A$434,0),),'IRA-BIL_IRA-BIL - Mid_annual_st'!$W$1:$AR$1,$B12) -> 1121991 | J12: =SUMIFS(INDEX('IRA-BIL_IRA-BIL - Mid_annual_st'!$W$3:$AR$434,MATCH(J2,'IRA-BIL_IRA-BIL - Mid_annual_st'!$A$3:$A$434,0),),'IRA-BIL_IRA-BIL - Mid_annual_st'!$W$1:$AR$1,$B12) -> 909000 | K12: =SUMIFS(INDEX('IRA-BIL_IRA-BIL - Mid_annual_st'!$W$3:$AR$434,MATCH(K2,'IRA-BIL_IRA-BIL - Mid_annual_st'!$A$3:$A$434,0),),'IRA-BIL_IRA-BIL - Mid_annual_st'!$W$1:$AR$1,$B12) -> 1086251 | M12: =C12/SUM(C4:C15) -> 0.0094997054 | N12: =D12/SUM(D4:D15) -> 0.009436147 | O12: =E12/SUM(E4:E15) -> 0.0028632015 | P12: =F12/SUM(F4:F15) -> 0.0031424665 | Q12: =G12/SUM(G4:G15) -> 0.0047223665 | R12: =H12/SUM(H4:H15) -> 0.0048847134 | S12: =I12/SUM(I4:I15) -> 0.0083110417 | T12: =J12/SUM(J4:J15) -> 0.0065062497 | U12: =K12/SUM(K4:K15) -> 0.0082707275
A13: =A12 -> AL | B13: onshore wind | C13: =SUMIFS(INDEX('IRA-BIL_IRA-BIL - Mid_annual_st'!$W$3:$AR$434,MATCH(C2,'IRA-BIL_IRA-BIL - Mid_annual_st'!$A$3:$A$434,0),),'IRA-BIL_IRA-BIL - Mid_annual_st'!$W$1:$AR$1,$B13) -> 0 | D13: =SUMIFS(INDEX('IRA-BIL_IRA-BIL - Mid_annual_st'!$W$3:$AR$434,MATCH(D2,'IRA-BIL_IRA-BIL - Mid_annual_st'!$A$3:$A$434,0),),'IRA-BIL_IRA-BIL - Mid_annual_st'!$W$1:$AR$1,$B13) -> 0 | E13: =SUMIFS(INDEX('IRA-BIL_IRA-BIL - Mid_annual_st'!$W$3:$AR$434,MATCH(E2,'IRA-BIL_IRA-BIL - Mid_annual_st'!$A$3:$A$434,0),),'IRA-BIL_IRA-BIL - Mid_annual_st'!$W$1:$AR$1,$B13) -> 0 | F13: =SUMIFS(INDEX('IRA-BIL_IRA-BIL - Mid_annual_st'!$W$3:$AR$434,MATCH(F2,'IRA-BIL_IRA-BIL - Mid_annual_st'!$A$3:$A$434,0),),'IRA-BIL_IRA-BIL - Mid_annual_st'!$W$1:$AR$1,$B13) -> 0 | G13: =SUMIFS(INDEX('IRA-BIL_IRA-BIL - Mid_annual_st'!$W$3:$AR$434,MATCH(G2,'IRA-BIL_IRA-BIL - Mid_annual_st'!$A$3:$A$434,0),),'IRA-BIL_IRA-BIL - Mid_annual_st'!$W$1:$AR$1,$B13) -> 0 | H13: =SUMIFS(INDEX('IRA-BIL_IRA-BIL - Mid_annual_st'!$W$3:$AR$434,MATCH(H2,'IRA-BIL_IRA-BIL - Mid_annual_st'!$A$3:$A$434,0),),'IRA-BIL_IRA-BIL - Mid_annual_st'!$W$1:$AR$1,$B13) -> 0 | I13: =SUMIFS(INDEX('IRA-BIL_IRA-BIL - Mid_annual_st'!$W$3:$AR$434,MATCH(I2,'IRA-BIL_IRA-BIL - Mid_annual_st'!$A$3:$A$434,0),),'IRA-BIL_IRA-BIL - Mid_annual_st'!$W$1:$AR$1,$B13) -> 0 | J13: =SUMIFS(INDEX('IRA-BIL_IRA-BIL - Mid_annual_st'!$W$3:$AR$434,MATCH(J2,'IRA-BIL_IRA-BIL - Mid_annual_st'!$A$3:$A$434,0),),'IRA-BIL_IRA-BIL - Mid_annual_st'!$W$1:$AR$1,$B13) -> 0 | K13: =SUMIFS(INDEX('IRA-BIL_IRA-BIL - Mid_annual_st'!$W$3:$AR$434,MATCH(K2,'IRA-BIL_IRA-BIL - Mid_annual_st'!$A$3:$A$434,0),),'IRA-BIL_IRA-BIL - Mid_annual_st'!$W$1:$AR$1,$B13) -> 0 | M13: =C13/SUM(C4:C15) -> 0 | N13: =D13/SUM(D4:D15) -> 0 | O13: =E13/SUM(E4:E15) -> 0 | P13: =F13/SUM(F4:F15) -> 0 | Q13: =G13/SUM(G4:G15) -> 0 | R13: =H13/SUM(H4:H15) -> 0 | S13: =I13/SUM(I4:I15) -> 0 | T13: =J13/SUM(J4:J15) -> 0 | U13: =K13/SUM(K4:K15) -> 0
A14: =A13 -> AL | B14: pumped hydro | C14: 0 | D14: 0 | E14: 0 | F14: 0 | G14: 0 | H14: 0 | I14: 0 | J14: 0 | K14: 0 | M14: 0 | N14: 0 | O14: 0 | P14: 0 | Q14: 0 | R14: 0 | S14: 0 | T14: 0 | U14: 0
A15: =A14 -> AL | B15: solar pv | C15: =SUMIFS(INDEX('IRA-BIL_IRA-BIL - Mid_annual_st'!$W$3:$AR$434,MATCH(C2,'IRA-BIL_IRA-BIL - Mid_annual_st'!$A$3:$A$434,0),),'IRA-BIL_IRA-BIL - Mid_annual_st'!$W$1:$AR$1,$B15) -> 1208752 | D15: =SUMIFS(INDEX('IRA-BIL_IRA-BIL - Mid_annual_st'!$W$3:$AR$434,MATCH(D2,'IRA-BIL_IRA-BIL - Mid_annual_st'!$A$3:$A$434,0),),'IRA-BIL_IRA-BIL - Mid_annual_st'!$W$1:$AR$1,$B15) -> 1577345 | E15: =SUMIFS(INDEX('IRA-BIL_IRA-BIL - Mid_annual_st'!$W$3:$AR$434,MATCH(E2,'IRA-BIL_IRA-BIL - Mid_annual_st'!$A$3:$A$434,0),),'IRA-BIL_IRA-BIL - Mid_annual_st'!$W$1:$AR$1,$B15) -> 1708516 | F15: =SUMIFS(INDEX('IRA-BIL_IRA-BIL - Mid_annual_st'!$W$3:$AR$434,MATCH(F2,'IRA-BIL_IRA-BIL - Mid_annual_st'!$A$3:$A$434,0),),'IRA-BIL_IRA-BIL - Mid_annual_st'!$W$1:$AR$1,$B15) -> 1719481 | G15: =SUMIFS(INDEX('IRA-BIL_IRA-BIL - Mid_annual_st'!$W$3:$AR$434,MATCH(G2,'IRA-BIL_IRA-BIL - Mid_annual_st'!$A$3:$A$434,0),),'IRA-BIL_IRA-BIL - Mid_annual_st'!$W$1:$AR$1,$B15) -> 2801553 | H15: =SUMIFS(INDEX('IRA-BIL_IRA-BIL - Mid_annual_st'!$W$3:$AR$434,MATCH(H2,'IRA-BIL_IRA-BIL - Mid_annual_st'!$A$3:$A$434,0),),'IRA-BIL_IRA-BIL - Mid_annual_st'!$W$1:$AR$1,$B15) -> 6098368 | I15: =SUMIFS(INDEX('IRA-BIL_IRA-BIL - Mid_annual_st'!$W$3:$AR$434,MATCH(I2,'IRA-BIL_IRA-BIL - Mid_annual_st'!$A$3:$A$434,0),),'IRA-BIL_IRA-BIL - Mid_annual_st'!$W$1:$AR$1,$B15) -> 10000893 | J15: =SUMIFS(INDEX('IRA-BIL_IRA-BIL - Mid_annual_st'!$W$3:$AR$434,MATCH(J2,'IRA-BIL_IRA-BIL - Mid_annual_st'!$A$3:$A$434,0),),'IRA-BIL_IRA-BIL - Mid_annual_st'!$W$1:$AR$1,$B15) -> 17513523 | K15: =SUMIFS(INDEX('IRA-BIL_IRA-BIL - Mid_annual_st'!$W$3:$AR$434,MATCH(K2,'IRA-BIL_IRA-BIL - Mid_annual_st'!$A$3:$A$434,0),),'IRA-BIL_IRA-BIL - Mid_annual_st'!$W$1:$AR$1,$B15) -> 21062677 | M15: =C15/SUM(C4:C15) -> 0.0092326743 | N15: =D15/SUM(D4:D15) -> 0.010609169 | O15: =E15/SUM(E4:E15) -> 0.011071461 | P15: =F15/SUM(F4:F15) -> 0.01142392 | Q15: =G15/SUM(G4:G15) -> 0.019303468 | R15: =H15/SUM(H4:H15) -> 0.042803722 | S15: =I15/SUM(I4:I15) -> 0.074080664 | T15: =J15/SUM(J4:J15) -> 0.12535463 | U15: =K15/SUM(K4:K15) -> 0.16037146
A16: AZ | C16: =$A16&"_"&C17 -> AZ_2022 | D16: =$A16&"_"&D17 -> AZ_2023 | E16: =$A16&"_"&E17 -> AZ_2024 | F16: =$A16&"_"&F17 -> AZ_2025 | G16: =$A16&"_"&G17 -> AZ_2026 | H16: =$A16&"_"&H17 -> AZ_2027 | I16: =$A16&"_"&I17 -> AZ_2028 | J16: =$A16&"_"&J17 -> AZ_2029 | K16: =$A16&"_"&K17 -> AZ_2030 | M16: =$A16&"_"&M17 -> AZ_2022 | N16: =$A16&"_"&N17 -> AZ_2023 | O16: =$A16&"_"&O17 -> AZ_2024 | P16: =$A16&"_"&P17 -> AZ_2025 | Q16: =$A16&"_"&Q17 -> AZ_2026 | R16: =$A16&"_"&R17 -> AZ_2027 | S16: =$A16&"_"&S17 -> AZ_2028 | T16: =$A16&"_"&T17 -> AZ_2029 | U16: =$A16&"_"&U17 -> AZ_2030
C17: 2022 | D17: 2023 | E17: 2024 | F17: 2025 | G17: 2026 | H17: 2027 | I17: 2028 | J17: 2029 | K17: 2030 | M17: 2022 | N17: 2023 | O17: 2024 | P17: 2025 | Q17: 2026 | R17: 2027 | S17: 2028 | T17: 2029 | U17: 2030
A18: =A16 -> AZ | B18: battery | C18: 0 | D18: 0 | E18: 0 | F18: 0 | G18: 0 | H18: 0 | I18: 0 | J18: 0 | K18: 0 | M18: 0 | N18: 0 | O18: 0 | P18: 0 | Q18: 0 | R18: 0 | S18: 0 | T18: 0 | U18: 0
A19: =A18 -> AZ | B19: biomass | C19: =SUMIFS(INDEX('IRA-BIL_IRA-BIL - Mid_annual_st'!$W$3:$AR$434,MATCH(C16,'IRA-BIL_IRA-BIL - Mid_annual_st'!$A$3:$A$434,0),),'IRA-BIL_IRA-BIL - Mid_annual_st'!$W$1:$AR$1,$B19) -> 27577 | D19: =SUMIFS(INDEX('IRA-BIL_IRA-BIL - Mid_annual_st'!$W$3:$AR$434,MATCH(D16,'IRA-BIL_IRA-BIL - Mid_annual_st'!$A$3:$A$434,0),),'IRA-BIL_IRA-BIL - Mid_annual_st'!$W$1:$AR$1,$B19) -> 27577 | E19: =SUMIFS(INDEX('IRA-BIL_IRA-BIL - Mid_annual_st'!$W$3:$AR$434,MATCH(E16,'IRA-BIL_IRA-BIL - Mid_annual_st'!$A$3:$A$434,0),),'IRA-BIL_IRA-BIL - Mid_annual_st'!$W$1:$AR$1,$B19) -> 27577 | F19: =SUMIFS(INDEX('IRA-BIL_IRA-BIL - Mid_annual_st'!$W$3:$AR$434,MATCH(F16,'IRA-BIL_IRA-BIL - Mid_annual_st'!$A$3:$A$434,0),),'IRA-BIL_IRA-BIL - Mid_annual_st'!$W$1:$AR$1,$B19) -> 27577 | G19: =SUMIFS(INDEX('IRA-BIL_IRA-BIL - Mid_annual_st'!$W$3:$AR$434,MATCH(G16,'IRA-BIL_IRA-BIL - Mid_annual_st'!$A$3:$A$434,0),),'IRA-BIL_IRA-BIL - Mid_annual_st'!$W$1:$AR$1,$B19) -> 27577 | H19: =SUMIFS(INDEX('IRA-BIL_IRA-BIL - Mid_annual_st'!$W$3:$AR$434,MATCH(H16,'IRA-BIL_IRA-BIL - Mid_annual_st'!$A$3:$A$434,0),),'IRA-BIL_IRA-BIL - Mid_annual_st'!$W$1:$AR$1,$B19) -> 27577 | I19: =SUMIFS(INDEX('IRA-BIL_IRA-BIL - Mid_annual_st'!$W$3:$AR$434,MATCH(I16,'IRA-BIL_IRA-BIL - Mid_annual_st'!$A$3:$A$434,0),),'IRA-BIL_IRA-BIL - Mid_annual_st'!$W$1:$AR$1,$B19) -> 27577 | J19: =SUMIFS(INDEX('IRA-BIL_IRA-BIL - Mid_annual_st'!$W$3:$AR$434,MATCH(J16,'IRA-BIL_IRA-BIL - Mid_annual_st'!$A$3:$A$434,0),),'IRA-BIL_IRA-BIL - Mid_annual_st'!$W$1:$AR$1,$B19) -> 25707 | K19: =SUMIFS(INDEX('IRA-BIL_IRA-BIL - Mid_annual_st'!$W$3:$AR$434,MATCH(K16,'IRA-BIL_IRA-BIL - Mid_annual_st'!$A$3:$A$434,0),),'IRA-BIL_IRA-BIL - Mid_annual_st'!$W$1:$AR$1,$B19) -> 25707 | M19: =C19/SUM(C18:C29) -> 0.00027121217 | N19: =D19/SUM(D18:D29) -> 0.00030667645 | O19: =E19/SUM(E18:E29) -> 0.0002950779 | P19: =F19/SUM(F18:F29) -> 0.00029907087 | Q19: =G19/SUM(G18:G29) -> 0.00029518933 | R19: =H19/SUM(H18:H29) -> 0.00029945835 | S19: =I19/SUM(I18:I29) -> 0.00029667341 | T19: =J19/SUM(J18:J29) -> 0.00026591537 | U19: =K19/SUM(K18:K29) -> 0.00026756319
A20: =A19 -> AZ | B20: hard coal | C20: =SUMIFS(INDEX('IRA-BIL_IRA-BIL - Mid_annual_st'!$W$3:$AR$434,MATCH(C16,'IRA-BIL_IRA-BIL - Mid_annual_st'!$A$3:$A$434,0),),'IRA-BIL_IRA-BIL - Mid_annual_st'!$W$1:$AR$1,$B20) -> 20872123 | D20: =SUMIFS(INDEX('IRA-BIL_IRA-BIL - Mid_annual_st'!$W$3:$AR$434,MATCH(D16,'IRA-BIL_IRA-BIL - Mid_annual_st'!$A$3:$A$434,0),),'IRA-BIL_IRA-BIL - Mid_annual_st'!$W$1:$AR$1,$B20) -> 19029980 | E20: =SUMIFS(INDEX('IRA-BIL_IRA-BIL - Mid_annual_st'!$W$3:$AR$434,MATCH(E16,'IRA-BIL_IRA-BIL - Mid_annual_st'!$A$3:$A$434,0),),'IRA-BIL_IRA-BIL - Mid_annual_st'!$W$1:$AR$1,$B20) -> 18467787 | F20: =SUMIFS(INDEX('IRA-BIL_IRA-BIL - Mid_annual_st'!$W$3:$AR$434,MATCH(F16,'IRA-BIL_IRA-BIL - Mid_annual_st'!$A$3:$A$434,0),),'IRA-BIL_IRA-BIL - Mid_annual_st'!$W$1:$AR$1,$B20) -> 17363540 | G20: =SUMIFS(INDEX('IRA-BIL_IRA-BIL - Mid_annual_st'!$W$3:$AR$434,MATCH(G16,'IRA-BIL_IRA-BIL - Mid_annual_st'!$A$3:$A$434,0),),'IRA-BIL_IRA-BIL - Mid_annual_st'!$W$1:$AR$1,$B20) -> 15864171 | H20: =SUMIFS(INDEX('IRA-BIL_IRA-BIL - Mid_annual_st'!$W$3:$AR$434,MATCH(H16,'IRA-BIL_IRA-BIL - Mid_annual_st'!$A$3:$A$434,0),),'IRA-BIL_IRA-BIL - Mid_annual_st'!$W$1:$AR$1,$B20) -> 15377456 | I20: =SUMIFS(INDEX('IRA-BIL_IRA-BIL - Mid_annual_st'!$W$3:$AR$434,MATCH(I16,'IRA-BIL_IRA-BIL - Mid_annual_st'!$A$3:$A$434,0),),'IRA-BIL_IRA-BIL - Mid_annual_st'!$W$1:$AR$1,$B20) -> 7898588 | J20: =SUMIFS(INDEX('IRA-BIL_IRA-BIL - Mid_annual_st'!$W$3:$AR$434,MATCH(J16,'IRA-BIL_IRA-BIL - Mid_annual_st'!$A$3:$A$434,0),),'IRA-BIL_IRA-BIL - Mid_annual_st'!$W$1:$AR$1,$B20) -> 8012938 | K20: =SUMIFS(INDEX('IRA-BIL_IRA-BIL - Mid_annual_st'!$W$3:$AR$434,MATCH(K16,'IRA-BIL_IRA-BIL - Mid_annual_st'!$A$3:$A$434,0),),'IRA-BIL_IRA-BIL - Mid_annual_st'!$W$1:$AR$1,$B20) -> 6519503 | M20: =C20/SUM(C18:C29) -> 0.20527156 | N20: =D20/SUM(D18:D29) -> 0.21162733 | O20: =E20/SUM(E18:E29) -> 0.197608 | P20: =F20/SUM(F18:F29) -> 0.18830653 | Q20: =G20/SUM(G18:G29) -> 0.16981303 | R20: =H20/SUM(H18:H29) -> 0.16698363 | S20: =I20/SUM(I18:I29) -> 0.084973021 | T20: =J20/SUM(J18:J29) -> 0.082886503 | U20: =K20/SUM(K18:K29) -> 0.067856187
A21: =A20 -> AZ | B21: geothermal | C21: =SUMIFS(INDEX('IRA-BIL_IRA-BIL - Mid_annual_st'!$W$3:$AR$434,MATCH(C16,'IRA-BIL_IRA-BIL - Mid_annual_st'!$A$3:$A$434,0),),'IRA-BIL_IRA-BIL - Mid_annual_st'!$W$1:$AR$1,$B21) -> 0 | D21: =SUMIFS(INDEX('IRA-BIL_IRA-BIL - Mid_annual_st'!$W$3:$AR$434,MATCH(D16,'IRA-BIL_IRA-BIL - Mid_annual_st'!$A$3:$A$434,0),),'IRA-BIL_IRA-BIL - Mid_annual_st'!$W$1:$AR$1,$B21) -> 0 | E21: =SUMIFS(INDEX('IRA-BIL_IRA-BIL - Mid_annual_st'!$W$3:$AR$434,MATCH(E16,'IRA-BIL_IRA-BIL - Mid_annual_st'!$A$3:$A$434,0),),'IRA-BIL_IRA-BIL - Mid_annual_st'!$W$1:$AR$1,$B21) -> 0 | F21: =SUMIFS(INDEX('IRA-BIL_IRA-BIL - Mid_annual_st'!$W$3:$AR$434,MATCH(F16,'IRA-BIL_IRA-BIL - Mid_annual_st'!$A$3:$A$434,0),),'IRA-BIL_IRA-BIL - Mid_annual_st'!$W$1:$AR$1,$B21) -> 0 | G21: =SUMIFS(INDEX('IRA-BIL_IRA-BIL - Mid_annual_st'!$W$3:$AR$434,MATCH(G16,'IRA-BIL_IRA-BIL - Mid_annual_st'!$A$3:$A$434,0),),'IRA-BIL_IRA-BIL - Mid_annual_st'!$W$1:$AR$1,$B21) -> 0 | H21: =SUMIFS(INDEX('IRA-BIL_IRA-BIL - Mid_annual_st'!$W$3:$AR$434,MATCH(H16,'IRA-BIL_IRA-BIL - Mid_annual_st'!$A$3:$A$434,0),),'IRA-BIL_IRA-BIL - Mid_annual_st'!$W$1:$AR$1,$B21) -> 0 | I21: =SUMIFS(INDEX('IRA-BIL_IRA-BIL - Mid_annual_st'!$W$3:$AR$434,MATCH(I16,'IRA-BIL_IRA-BIL - Mid_annual_st'!$A$3:$A$434,0),),'IRA-BIL_IRA-BIL - Mid_annual_st'!$W$1:$AR$1,$B21) -> 0 | J21: =SUMIFS(INDEX('IRA-BIL_IRA-BIL - Mid_annual_st'!$W$3:$AR$434,MATCH(J16,'IRA-BIL_IRA-BIL - Mid_annual_st'!$A$3:$A$434,0),),'IRA-BIL_IRA-BIL - Mid_annual_st'!$W$1:$AR$1,$B21) -> 0 | K21: =SUMIFS(INDEX('IRA-BIL_IRA-BIL - Mid_annual_st'!$W$3:$AR$434,MATCH(K16,'IRA-BIL_IRA-BIL - Mid_annual_st'!$A$3:$A$434,0),),'IRA-BIL_IRA-BIL - Mid_annual_st'!$W$1:$AR$1,$B21) -> 0 | M21: =C21/SUM(C18:C29) -> 0 | N21: =D21/SUM(D18:D29) -> 0 | O21: =E21/SUM(E18:E29) -> 0 | P21: =F21/SUM(F18:F29) -> 0 | Q21: =G21/SUM(G18:G29) -> 0 | R21: =H21/SUM(H18:H29) -> 0 | S21: =I21/SUM(I18:I29) -> 0 | T21: =J21/SUM(J18:J29) -> 0 | U21: =K21/SUM(K18:K29) -> 0
A22: =A21 -> AZ | B22: hydro | C22: =SUMIFS(INDEX('IRA-BIL_IRA-BIL - Mid_annual_st'!$W$3:$AR$434,MATCH(C16,'IRA-BIL_IRA-BIL - Mid_annual_st'!$A$3:$A$434,0),),'IRA-BIL_IRA-BIL - Mid_annual_st'!$W$1:$AR$1,$B22) -> 7246652 | D22: =SUMIFS(INDEX('IRA-BIL_IRA-BIL - Mid_annual_st'!$W$3:$AR$434,MATCH(D16,'IRA-BIL_IRA-BIL - Mid_annual_st'!$A$3:$A$434,0),),'IRA-BIL_IRA-BIL - Mid_annual_st'!$W$1:$AR$1,$B22) -> 7246652 | E22: =SUMIFS(INDEX('IRA-BIL_IRA-BIL - Mid_annual_st'!$W$3:$AR$434,MATCH(E16,'IRA-BIL_IRA-BIL - Mid_annual_st'!$A$3:$A$434,0),),'IRA-BIL_IRA-BIL - Mid_annual_st'!$W$1:$AR$1,$B22) -> 7246804 | F22: =SUMIFS(INDEX('IRA-BIL_IRA-BIL - Mid_annual_st'!$W$3:$AR$434,MATCH(F16,'IRA-BIL_IRA-BIL - Mid_annual_st'!$A$3:$A$434,0),),'IRA-BIL_IRA-BIL - Mid_annual_st'!$W$1:$AR$1,$B22) -> 8628376 | G22: =SUMIFS(INDEX('IRA-BIL_IRA-BIL - Mid_annual_st'!$W$3:$AR$434,MATCH(G16,'IRA-BIL_IRA-BIL - Mid_annual_st'!$A$3:$A$434,0),),'IRA-BIL_IRA-BIL - Mid_annual_st'!$W$1:$AR$1,$B22) -> 8628528 | H22: =SUMIFS(INDEX('IRA-BIL_IRA-BIL - Mid_annual_st'!$W$3:$AR$434,MATCH(H16,'IRA-BIL_IRA-BIL - Mid_annual_st'!$A$3:$A$434,0),),'IRA-BIL_IRA-BIL - Mid_annual_st'!$W$1:$AR$1,$B22) -> 8637626 | I22: =SUMIFS(INDEX('IRA-BIL_IRA-BIL - Mid_annual_st'!$W$3:$AR$434,MATCH(I16,'IRA-BIL_IRA-BIL - Mid_annual_st'!$A$3:$A$434,0),),'IRA-BIL_IRA-BIL - Mid_annual_st'!$W$1:$AR$1,$B22) -> 8630449 | J22: =SUMIFS(INDEX('IRA-BIL_IRA-BIL - Mid_annual_st'!$W$3:$AR$434,MATCH(J16,'IRA-BIL_IRA-BIL - Mid_annual_st'!$A$3:$A$434,0),),'IRA-BIL_IRA-BIL - Mid_annual_st'!$W$1:$AR$1,$B22) -> 8636154 | K22: =SUMIFS(INDEX('IRA-BIL_IRA-BIL - Mid_annual_st'!$W$3:$AR$434,MATCH(K16,'IRA-BIL_IRA-BIL - Mid_annual_st'!$A$3:$A$434,0),),'IRA-BIL_IRA-BIL - Mid_annual_st'!$W$1:$AR$1,$B22) -> 8616548 | M22: =C22/SUM(C18:C29) -> 0.07126882 | N22: =D22/SUM(D18:D29) -> 0.080588082 | O22: =E22/SUM(E18:E29) -> 0.077541854 | P22: =F22/SUM(F18:F29) -> 0.093574208 | Q22: =G22/SUM(G18:G29) -> 0.092361366 | R22: =H22/SUM(H18:H29) -> 0.09379589 | S22: =I22/SUM(I18:I29) -> 0.092846383 | T22: =J22/SUM(J18:J29) -> 0.089333102 | U22: =K22/SUM(K18:K29) -> 0.089682618
A23: =A22 -> AZ | B23: natural gas steam turbine | C23: =SUMIFS(INDEX('IRA-BIL_IRA-BIL - Mid_annual_st'!$W$3:$AR$434,MATCH(C16,'IRA-BIL_IRA-BIL - Mid_annual_st'!$A$3:$A$434,0),),'IRA-BIL_IRA-BIL - Mid_annual_st'!$W$1:$AR$1,$B23) -> 31617311 | D23: =SUMIFS(INDEX('IRA-BIL_IRA-BIL - Mid_annual_st'!$W$3:$AR$434,MATCH(D16,'IRA-BIL_IRA-BIL - Mid_annual_st'!$A$3:$A$434,0),),'IRA-BIL_IRA-BIL - Mid_annual_st'!$W$1:$AR$1,$B23) -> 20325118 | E23: =SUMIFS(INDEX('IRA-BIL_IRA-BIL - Mid_annual_st'!$W$3:$AR$434,MATCH(E16,'IRA-BIL_IRA-BIL - Mid_annual_st'!$A$3:$A$434,0),),'IRA-BIL_IRA-BIL - Mid_annual_st'!$W$1:$AR$1,$B23) -> 18395143 | F23: =SUMIFS(INDEX('IRA-BIL_IRA-BIL - Mid_annual_st'!$W$3:$AR$434,MATCH(F16,'IRA-BIL_IRA-BIL - Mid_annual_st'!$A$3:$A$434,0),),'IRA-BIL_IRA-BIL - Mid_annual_st'!$W$1:$AR$1,$B23) -> 16093789 | G23: =SUMIFS(INDEX('IRA-BIL_IRA-BIL - Mid_annual_st'!$W$3:$AR$434,MATCH(G16,'IRA-BIL_IRA-BIL - Mid_annual_st'!$A$3:$A$434,0),),'IRA-BIL_IRA-BIL - Mid_annual_st'!$W$1:$AR$1,$B23) -> 16074622 | H23: =SUMIFS(INDEX('IRA-BIL_IRA-BIL - Mid_annual_st'!$W$3:$AR$434,MATCH(H16,'IRA-BIL_IRA-BIL - Mid_annual_st'!$A$3:$A$434,0),),'IRA-BIL_IRA-BIL - Mid_annual_st'!$W$1:$AR$1,$B23) -> 12969138 | I23: =SUMIFS(INDEX('IRA-BIL_IRA-BIL - Mid_annual_st'!$W$3:$AR$434,MATCH(I16,'IRA-BIL_IRA-BIL - Mid_annual_st'!$A$3:$A$434,0),),'IRA-BIL_IRA-BIL - Mid_annual_st'!$W$1:$AR$1,$B23) -> 9178381 | J23: =SUMIFS(INDEX('IRA-BIL_IRA-BIL - Mid_annual_st'!$W$3:$AR$434,MATCH(J16,'IRA-BIL_IRA-BIL - Mid_annual_st'!$A$3:$A$434,0),),'IRA-BIL_IRA-BIL - Mid_annual_st'!$W$1:$AR$1,$B23) -> 8495528 | K23: =SUMIFS(INDEX('IRA-BIL_IRA-BIL - Mid_annual_st'!$W$3:$AR$434,MATCH(K16,'IRA-BIL_IRA-BIL - Mid_annual_st'!$A$3:$A$434,0),),'IRA-BIL_IRA-BIL - Mid_annual_st'!$W$1:$AR$1,$B23) -> 8387745 | M23: =C23/SUM(C18:C29) -> 0.31094752 | N23: =D23/SUM(D18:D29) -> 0.22603021 | O23: =E23/SUM(E18:E29) -> 0.1968307 | P23: =F23/SUM(F18:F29) -> 0.17453615 | Q23: =G23/SUM(G18:G29) -> 0.17206574 | R23: =H23/SUM(H18:H29) -> 0.14083173 | S23: =I23/SUM(I18:I29) -> 0.098741036 | T23: =J23/SUM(J18:J29) -> 0.087878455 | U23: =K23/SUM(K18:K29) -> 0.087301194
A24: =A23 -> AZ | B24: nuclear | C24: =SUMIFS(INDEX('IRA-BIL_IRA-BIL - Mid_annual_st'!$W$3:$AR$434,MATCH(C16,'IRA-BIL_IRA-BIL - Mid_annual_st'!$A$3:$A$434,0),),'IRA-BIL_IRA-BIL - Mid_annual_st'!$W$1:$AR$1,$B24) -> 31618584 | D24: =SUMIFS(INDEX('IRA-BIL_IRA-BIL - Mid_annual_st'!$W$3:$AR$434,MATCH(D16,'IRA-BIL_IRA-BIL - Mid_annual_st'!$A$3:$A$434,0),),'IRA-BIL_IRA-BIL - Mid_annual_st'!$W$1:$AR$1,$B24) -> 31618584 | E24: =SUMIFS(INDEX('IRA-BIL_IRA-BIL - Mid_annual_st'!$W$3:$AR$434,MATCH(E16,'IRA-BIL_IRA-BIL - Mid_annual_st'!$A$3:$A$434,0),),'IRA-BIL_IRA-BIL - Mid_annual_st'!$W$1:$AR$1,$B24) -> 31618584 | F24: =SUMIFS(INDEX('IRA-BIL_IRA-BIL - Mid_annual_st'!$W$3:$AR$434,MATCH(F16,'IRA-BIL_IRA-BIL - Mid_annual_st'!$A$3:$A$434,0),),'IRA-BIL_IRA-BIL - Mid_annual_st'!$W$1:$AR$1,$B24) -> 31618584 | G24: =SUMIFS(INDEX('IRA-BIL_IRA-BIL - Mid_annual_st'!$W$3:$AR$434,MATCH(G16,'IRA-BIL_IRA-BIL - Mid_annual_st'!$A$3:$A$434,0),),'IRA-BIL_IRA-BIL - Mid_annual_st'!$W$1:$AR$1,$B24) -> 31618584 | H24: =SUMIFS(INDEX('IRA-BIL_IRA-BIL - Mid_annual_st'!$W$3:$AR$434,MATCH(H16,'IRA-BIL_IRA-BIL - Mid_annual_st'!$A$3:$A$434,0),),'IRA-BIL_IRA-BIL - Mid_annual_st'!$W$1:$AR$1,$B24) -> 31618584 | I24: =SUMIFS(INDEX('IRA-BIL_IRA-BIL - Mid_annual_st'!$W$3:$AR$434,MATCH(I16,'IRA-BIL_IRA-BIL - Mid_annual_st'!$A$3:$A$434,0),),'IRA-BIL_IRA-BIL - Mid_annual_st'!$W$1:$AR$1,$B24) -> 30552162 | J24: =SUMIFS(INDEX('IRA-BIL_IRA-BIL - Mid_annual_st'!$W$3:$AR$434,MATCH(J16,'IRA-BIL_IRA-BIL - Mid_annual_st'!$A$3:$A$434,0),),'IRA-BIL_IRA-BIL - Mid_annual_st'!$W$1:$AR$1,$B24) -> 30552162 | K24: =SUMIFS(INDEX('IRA-BIL_IRA-BIL - Mid_annual_st'!$W$3:$AR$434,MATCH(K16,'IRA-BIL_IRA-BIL - Mid_annual_st'!$A$3:$A$434,0),),'IRA-BIL_IRA-BIL - Mid_annual_st'!$W$1:$AR$1,$B24) -> 30449033 | M24: =C24/SUM(C18:C29) -> 0.31096004 | N24: =D24/SUM(D18:D29) -> 0.35162183 | O24: =E24/SUM(E18:E29) -> 0.33832344 | P24: =F24/SUM(F18:F29) -> 0.3429016 | Q24: =G24/SUM(G18:G29) -> 0.33845119 | R24: =H24/SUM(H18:H29) -> 0.34334587 | S24: =I24/SUM(I18:I29) -> 0.3286802 | T24: =J24/SUM(J18:J29) -> 0.31603413 | U24: =K24/SUM(K18:K29) -> 0.31691914
A25: =A24 -> AZ | B25: offshore wind | C25: =SUMIFS(INDEX('IRA-BIL_IRA-BIL - Mid_annual_st'!$W$3:$AR$434,MATCH(C16,'IRA-BIL_IRA-BIL - Mid_annual_st'!$A$3:$A$434,0),),'IRA-BIL_IRA-BIL - Mid_annual_st'!$W$1:$AR$1,$B25) -> 0 | D25: =SUMIFS(INDEX('IRA-BIL_IRA-BIL - Mid_annual_st'!$W$3:$AR$434,MATCH(D16,'IRA-BIL_IRA-BIL - Mid_annual_st'!$A$3:$A$434,0),),'IRA-BIL_IRA-BIL - Mid_annual_st'!$W$1:$AR$1,$B25) -> 0 | E25: =SUMIFS(INDEX('IRA-BIL_IRA-BIL - Mid_annual_st'!$W$3:$AR$434,MATCH(E16,'IRA-BIL_IRA-BIL - Mid_annual_st'!$A$3:$A$434,0),),'IRA-BIL_IRA-BIL - Mid_annual_st'!$W$1:$AR$1,$B25) -> 0 | F25: =SUMIFS(INDEX('IRA-BIL_IRA-BIL - Mid_annual_st'!$W$3:$AR$434,MATCH(F16,'IRA-BIL_IRA-BIL - Mid_annual_st'!$A$3:$A$434,0),),'IRA-BIL_IRA-BIL - Mid_annual_st'!$W$1:$AR$1,$B25) -> 0 | G25: =SUMIFS(INDEX('IRA-BIL_IRA-BIL - Mid_annual_st'!$W$3:$AR$434,MATCH(G16,'IRA-BIL_IRA-BIL - Mid_annual_st'!$A$3:$A$434,0),),'IRA-BIL_IRA-BIL - Mid_annual_st'!$W$1:$AR$1,$B25) -> 0 | H25: =SUMIFS(INDEX('IRA-BIL_IRA-BIL - Mid_annual_st'!$W$3:$AR$434,MATCH(H16,'IRA-BIL_IRA-BIL - Mid_annual_st'!$A$3:$A$434,0),),'IRA-BIL_IRA-BIL - Mid_annual_st'!$W$1:$AR$1,$B25) -> 0 | I25: =SUMIFS(INDEX('IRA-BIL_IRA-BIL - Mid_annual_st'!$W$3:$AR$434,MATCH(I16,'IRA-BIL_IRA-BIL - Mid_annual_st'!$A$3:$A$434,0),),'IRA-BIL_IRA-BIL - Mid_annual_st'!$W$1:$AR$1,$B25) -> 0 | J25: =SUMIFS(INDEX('IRA-BIL_IRA-BIL - Mid_annual_st'!$W$3:$AR$434,MATCH(J16,'IRA-BIL_IRA-BIL - Mid_annual_st'!$A$3:$A$434,0),),'IRA-BIL_IRA-BIL - Mid_annual_st'!$W$1:$AR$1,$B25) -> 0 | K25: =SUMIFS(INDEX('IRA-BIL_IRA-BIL - Mid_annual_st'!$W$3:$AR$434,MATCH(K16,'IRA-BIL_IRA-BIL - Mid_annual_st'!$A$3:$A$434,0),),'IRA-BIL_IRA-BIL - Mid_annual_st'!$W$1:$AR$1,$B25) -> 0 | M25: =C25/SUM(C18:C29) -> 0 | N25: =D25/SUM(D18:D29) -> 0 | O25: =E25/SUM(E18:E29) -> 0 | P25: =F25/SUM(F18:F29) -> 0 | Q25: =G25/SUM(G18:G29) -> 0 | R25: =H25/SUM(H18:H29) -> 0 | S25: =I25/SUM(I18:I29) -> 0 | T25: =J25/SUM(J18:J29) -> 0 | U25: =K25/SUM(K18:K29) -> 0
A26: =A25 -> AZ | B26: petroleum | C26: =SUMIFS(INDEX('IRA-BIL_IRA-BIL - Mid_annual_st'!$W$3:$AR$434,MATCH(C16,'IRA-BIL_IRA-BIL - Mid_annual_st'!$A$3:$A$434,0),),'IRA-BIL_IRA-BIL - Mid_annual_st'!$W$1:$AR$1,$B26) -> 1113957 | D26: =SUMIFS(INDEX('IRA-BIL_IRA-BIL - Mid_annual_st'!$W$3:$AR$434,MATCH(D16,'IRA-BIL_IRA-BIL - Mid_annual_st'!$A$3:$A$434,0),),'IRA-BIL_IRA-BIL - Mid_annual_st'!$W$1:$AR$1,$B26) -> 1113957 | E26: =SUMIFS(INDEX('IRA-BIL_IRA-BIL - Mid_annual_st'!$W$3:$AR$434,MATCH(E16,'IRA-BIL_IRA-BIL - Mid_annual_st'!$A$3:$A$434,0),),'IRA-BIL_IRA-BIL - Mid_annual_st'!$W$1:$AR$1,$B26) -> 587621 | F26: =SUMIFS(INDEX('IRA-BIL_IRA-BIL - Mid_annual_st'!$W$3:$AR$434,MATCH(F16,'IRA-BIL_IRA-BIL - Mid_annual_st'!$A$3:$A$434,0),),'IRA-BIL_IRA-BIL - Mid_annual_st'!$W$1:$AR$1,$B26) -> 587621 | G26: =SUMIFS(INDEX('IRA-BIL_IRA-BIL - Mid_annual_st'!$W$3:$AR$434,MATCH(G16,'IRA-BIL_IRA-BIL - Mid_annual_st'!$A$3:$A$434,0),),'IRA-BIL_IRA-BIL - Mid_annual_st'!$W$1:$AR$1,$B26) -> 587621 | H26: =SUMIFS(INDEX('IRA-BIL_IRA-BIL - Mid_annual_st'!$W$3:$AR$434,MATCH(H16,'IRA-BIL_IRA-BIL - Mid_annual_st'!$A$3:$A$434,0),),'IRA-BIL_IRA-BIL - Mid_annual_st'!$W$1:$AR$1,$B26) -> 450965 | I26: =SUMIFS(INDEX('IRA-BIL_IRA-BIL - Mid_annual_st'!$W$3:$AR$434,MATCH(I16,'IRA-BIL_IRA-BIL - Mid_annual_st'!$A$3:$A$434,0),),'IRA-BIL_IRA-BIL - Mid_annual_st'!$W$1:$AR$1,$B26) -> 440453 | J26: =SUMIFS(INDEX('IRA-BIL_IRA-BIL - Mid_annual_st'!$W$3:$AR$434,MATCH(J16,'IRA-BIL_IRA-BIL - Mid_annual_st'!$A$3:$A$434,0),),'IRA-BIL_IRA-BIL - Mid_annual_st'!$W$1:$AR$1,$B26) -> 384739 | K26: =SUMIFS(INDEX('IRA-BIL_IRA-BIL - Mid_annual_st'!$W$3:$AR$434,MATCH(K16,'IRA-BIL_IRA-BIL - Mid_annual_st'!$A$3:$A$434,0),),'IRA-BIL_IRA-BIL - Mid_annual_st'!$W$1:$AR$1,$B26) -> 307476 | M26: =C26/SUM(C18:C29) -> 0.010955459 | N26: =D26/SUM(D18:D29) -> 0.012388018 | O26: =E26/SUM(E18:E29) -> 0.0062876299 | P26: =F26/SUM(F18:F29) -> 0.0063727137 | Q26: =G26/SUM(G18:G29) -> 0.0062900043 | R26: =H26/SUM(H18:H29) -> 0.0048970242 | S26: =I26/SUM(I18:I29) -> 0.004738394 | T26: =J26/SUM(J18:J29) -> 0.0039797725 | U26: =K26/SUM(K18:K29) -> 0.0032002668
A27: =A26 -> AZ | B27: onshore wind | C27: =SUMIFS(INDEX('IRA-BIL_IRA-BIL - Mid_annual_st'!$W$3:$AR$434,MATCH(C16,'IRA-BIL_IRA-BIL - Mid_annual_st'!$A$3:$A$434,0),),'IRA-BIL_IRA-BIL - Mid_annual_st'!$W$1:$AR$1,$B27) -> 1676683 | D27: =SUMIFS(INDEX('IRA-BIL_IRA-BIL - Mid_annual_st'!$W$3:$AR$434,MATCH(D16,'IRA-BIL_IRA-BIL - Mid_annual_st'!$A$3:$A$434,0),),'IRA-BIL_IRA-BIL - Mid_annual_st'!$W$1:$AR$1,$B27) -> 1688417 | E27: =SUMIFS(INDEX('IRA-BIL_IRA-BIL - Mid_annual_st'!$W$3:$AR$434,MATCH(E16,'IRA-BIL_IRA-BIL - Mid_annual_st'!$A$3:$A$434,0),),'IRA-BIL_IRA-BIL - Mid_annual_st'!$W$1:$AR$1,$B27) -> 1685885 | F27: =SUMIFS(INDEX('IRA-BIL_IRA-BIL - Mid_annual_st'!$W$3:$AR$434,MATCH(F16,'IRA-BIL_IRA-BIL - Mid_annual_st'!$A$3:$A$434,0),),'IRA-BIL_IRA-BIL - Mid_annual_st'!$W$1:$AR$1,$B27) -> 1701411 | G27: =SUMIFS(INDEX('IRA-BIL_IRA-BIL - Mid_annual_st'!$W$3:$AR$434,MATCH(G16,'IRA-BIL_IRA-BIL - Mid_annual_st'!$A$3:$A$434,0),),'IRA-BIL_IRA-BIL - Mid_annual_st'!$W$1:$AR$1,$B27) -> 1989930 | H27: =SUMIFS(INDEX('IRA-BIL_IRA-BIL - Mid_annual_st'!$W$3:$AR$434,MATCH(H16,'IRA-BIL_IRA-BIL - Mid_annual_st'!$A$3:$A$434,0),),'IRA-BIL_IRA-BIL - Mid_annual_st'!$W$1:$AR$1,$B27) -> 2008713 | I27: =SUMIFS(INDEX('IRA-BIL_IRA-BIL - Mid_annual_st'!$W$3:$AR$434,MATCH(I16,'IRA-BIL_IRA-BIL - Mid_annual_st'!$A$3:$A$434,0),),'IRA-BIL_IRA-BIL - Mid_annual_st'!$W$1:$AR$1,$B27) -> 2693408 | J27: =SUMIFS(INDEX('IRA-BIL_IRA-BIL - Mid_annual_st'!$W$3:$AR$434,MATCH(J16,'IRA-BIL_IRA-BIL - Mid_annual_st'!$A$3:$A$434,0),),'IRA-BIL_IRA-BIL - Mid_annual_st'!$W$1:$AR$1,$B27) -> 2762852 | K27: =SUMIFS(INDEX('IRA-BIL_IRA-BIL - Mid_annual_st'!$W$3:$AR$434,MATCH(K16,'IRA-BIL_IRA-BIL - Mid_annual_st'!$A$3:$A$434,0),),'IRA-BIL_IRA-BIL - Mid_annual_st'!$W$1:$AR$1,$B27) -> 2764866 | M27: =C27/SUM(C18:C29) -> 0.016489714 | N27: =D27/SUM(D18:D29) -> 0.018776435 | O27: =E27/SUM(E18:E29) -> 0.018039214 | P27: =F27/SUM(F18:F29) -> 0.018451698 | Q27: =G27/SUM(G18:G29) -> 0.02130058 | R27: =H27/SUM(H18:H29) -> 0.021812593 | S27: =I27/SUM(I18:I29) -> 0.028975687 | T27: =J27/SUM(J18:J29) -> 0.028579173 | U27: =K27/SUM(K18:K29) -> 0.028777234
A28: =A27 -> AZ | B28: pumped hydro | C28: 0 | D28: 0 | E28: 0 | F28: 0 | G28: 0 | H28: 0 | I28: 0 | J28: 0 | K28: 0 | M28: 0 | N28: 0 | O28: 0 | P28: 0 | Q28: 0 | R28: 0 | S28: 0 | T28: 0 | U28: 0
