Workbook

Sheet About
A1: BCTR - BAU Carbon Tax Rate | B1: North Dakota | C1: 46190
A2: State abbr (derived): | B2: =IFERROR(INDEX(Keys!$A:$A,MATCH($B$1,Keys!$B:$B,0)),"") -> ND
A3: Program (derived): | B3: =IFERROR(INDEX(Keys!$C:$C,MATCH($B$1,Keys!$B:$B,0)),"none") -> none
A6: Type any state into B1 (yellow). B2/B3 derive the abbreviation and carbon-pricing program.
A8: Raw data is embedded verbatim with full source columns: RGGI_auctions (price/volume time
A9: series), RGGI_Auction66_states (state-level proceeds/allowances), CA_auctions (CARB joint-auction
A10: summary), WA_prices. All downstream values are formulas: Calcs averages the clearing/settlement
A11: price column per year, deflates to 2012$, regresses 2018-2025, and forecasts; BCTR picks the
A12: active state program via INDEX/MATCH.
A14: RGGI states -> electricity only; clearing price avg x CPI deflator x 0.90718 (short->metric),
A15: linear regression 2018-2025 -> forecast to 2050.
A16: California -> all sectors; settlement price avg x CPI deflator (2012$), regression 2018-2025,
A17: forecast 2026-2030, flat 2031-2050 (AB 398 extends cap authority to 2030).
A18: Washington -> all sectors except industry & LULUCF; most recent observed auction
A19: settlement price deflated to 2012$ and HELD CONSTANT 2023-2050.
... A73: Built as a clean, formula-driven rebuild with raw data embedded verbatim. Inputs for staff review.

Sheet BCTR
A1: Unit: $/metric ton CO2e | B1: 2020 | C1: 2021 | D1: 2022 | E1: 2023 | F1: 2024 | G1: 2025 | H1: 2026 | I1: 2027 | J1: 2028 | K1: 2029 | L1: 2030 | M1: 2031 | N1: 2032 | O1: 2033 | P1: 2034 | Q1: 2035 | R1: 2036 | S1: 2037 | T1: 2038 | U1: 2039 | V1: 2040 | W1: 2041 | X1: 2042 | Y1: 2043 | Z1: 2044 | AA1: 2045 | AB1: 2046 | AC1: 2047 | AD1: 2048 | AE1: 2049 | AF1: 2050
A2: transportation sector | B2: =IFERROR(INDEX(Calcs!$B$30:$AF$33,MATCH(About!$B$3,Calcs!$A$30:$A$33,0),MATCH(B$1,Calcs!$B$29:$AF$29,0))*INDEX(Keys!$F$2:$M$5,MATCH(About!$B$3,Keys!$E$2:$E$5,0),MATCH($A2,Keys!$F$1:$M$1,0)),0) -> 0 | C2: =IFERROR(INDEX(Calcs!$B$30:$AF$33,MATCH(About!$B$3,Calcs!$A$30:$A$33,0),MATCH(C$1,Calcs!$B$29:$AF$29,0))*INDEX(Keys!$F$2:$M$5,MATCH(About!$B$3,Keys!$E$2:$E$5,0),MATCH($A2,Keys!$F$1:$M$1,0)),0) -> 0 | D2: =IFERROR(INDEX(Calcs!$B$30:$AF$33,MATCH(About!$B$3,Calcs!$A$30:$A$33,0),MATCH(D$1,Calcs!$B$29:$AF$29,0))*INDEX(Keys!$F$2:$M$5,MATCH(About!$B$3,Keys!$E$2:$E$5,0),MATCH($A2,Keys!$F$1:$M$1,0)),0) -> 0 | E2: =IFERROR(INDEX(Calcs!$B$30:$AF$33,MATCH(About!$B$3,Calcs!$A$30:$A$33,0),MATCH(E$1,Calcs!$B$29:$AF$29,0))*INDEX(Keys!$F$2:$M$5,MATCH(About!$B$3,Keys!$E$2:$E$5,0),MATCH($A2,Keys!$F$1:$M$1,0)),0) -> 0 | F2: =IFERROR(INDEX(Calcs!$B$30:$AF$33,MATCH(About!$B$3,Calcs!$A$30:$A$33,0),MATCH(F$1,Calcs!$B$29:$AF$29,0))*INDEX(Keys!$F$2:$M$5,MATCH(About!$B$3,Keys!$E$2:$E$5,0),MATCH($A2,Keys!$F$1:$M$1,0)),0) -> 0 | G2: =IFERROR(INDEX(Calcs!$B$30:$AF$33,MATCH(About!$B$3,Calcs!$A$30:$A$33,0),MATCH(G$1,Calcs!$B$29:$AF$29,0))*INDEX(Keys!$F$2:$M$5,MATCH(About!$B$3,Keys!$E$2:$E$5,0),MATCH($A2,Keys!$F$1:$M$1,0)),0) -> 0 | H2: =IFERROR(INDEX(Calcs!$B$30:$AF$33,MATCH(About!$B$3,Calcs!$A$30:$A$33,0),MATCH(H$1,Calcs!$B$29:$AF$29,0))*INDEX(Keys!$F$2:$M$5,MATCH(About!$B$3,Keys!$E$2:$E$5,0),MATCH($A2,Keys!$F$1:$M$1,0)),0) -> 0 | I2: =IFERROR(INDEX(Calcs!$B$30:$AF$33,MATCH(About!$B$3,Calcs!$A$30:$A$33,0),MATCH(I$1,Calcs!$B$29:$AF$29,0))*INDEX(Keys!$F$2:$M$5,MATCH(About!$B$3,Keys!$E$2:$E$5,0),MATCH($A2,Keys!$F$1:$M$1,0)),0) -> 0 | ... AF2: =IFERROR(INDEX(Calcs!$B$30:$AF$33,MATCH(About!$B$3,Calcs!$A$30:$A$33,0),MATCH(AF$1,Calcs!$B$29:$AF$29,0))*INDEX(Keys!$F$2:$M$5,MATCH(About!$B$3,Keys!$E$2:$E$5,0),MATCH($A2,Keys!$F$1:$M$1,0)),0) -> 0
A3: electricity sector | B3: =IFERROR(INDEX(Calcs!$B$30:$AF$33,MATCH(About!$B$3,Calcs!$A$30:$A$33,0),MATCH(B$1,Calcs!$B$29:$AF$29,0))*INDEX(Keys!$F$2:$M$5,MATCH(About!$B$3,Keys!$E$2:$E$5,0),MATCH($A3,Keys!$F$1:$M$1,0)),0) -> 0 | C3: =IFERROR(INDEX(Calcs!$B$30:$AF$33,MATCH(About!$B$3,Calcs!$A$30:$A$33,0),MATCH(C$1,Calcs!$B$29:$AF$29,0))*INDEX(Keys!$F$2:$M$5,MATCH(About!$B$3,Keys!$E$2:$E$5,0),MATCH($A3,Keys!$F$1:$M$1,0)),0) -> 0 | D3: =IFERROR(INDEX(Calcs!$B$30:$AF$33,MATCH(About!$B$3,Calcs!$A$30:$A$33,0),MATCH(D$1,Calcs!$B$29:$AF$29,0))*INDEX(Keys!$F$2:$M$5,MATCH(About!$B$3,Keys!$E$2:$E$5,0),MATCH($A3,Keys!$F$1:$M$1,0)),0) -> 0 | E3: =IFERROR(INDEX(Calcs!$B$30:$AF$33,MATCH(About!$B$3,Calcs!$A$30:$A$33,0),MATCH(E$1,Calcs!$B$29:$AF$29,0))*INDEX(Keys!$F$2:$M$5,MATCH(About!$B$3,Keys!$E$2:$E$5,0),MATCH($A3,Keys!$F$1:$M$1,0)),0) -> 0 | F3: =IFERROR(INDEX(Calcs!$B$30:$AF$33,MATCH(About!$B$3,Calcs!$A$30:$A$33,0),MATCH(F$1,Calcs!$B$29:$AF$29,0))*INDEX(Keys!$F$2:$M$5,MATCH(About!$B$3,Keys!$E$2:$E$5,0),MATCH($A3,Keys!$F$1:$M$1,0)),0) -> 0 | G3: =IFERROR(INDEX(Calcs!$B$30:$AF$33,MATCH(About!$B$3,Calcs!$A$30:$A$33,0),MATCH(G$1,Calcs!$B$29:$AF$29,0))*INDEX(Keys!$F$2:$M$5,MATCH(About!$B$3,Keys!$E$2:$E$5,0),MATCH($A3,Keys!$F$1:$M$1,0)),0) -> 0 | H3: =IFERROR(INDEX(Calcs!$B$30:$AF$33,MATCH(About!$B$3,Calcs!$A$30:$A$33,0),MATCH(H$1,Calcs!$B$29:$AF$29,0))*INDEX(Keys!$F$2:$M$5,MATCH(About!$B$3,Keys!$E$2:$E$5,0),MATCH($A3,Keys!$F$1:$M$1,0)),0) -> 0 | I3: =IFERROR(INDEX(Calcs!$B$30:$AF$33,MATCH(About!$B$3,Calcs!$A$30:$A$33,0),MATCH(I$1,Calcs!$B$29:$AF$29,0))*INDEX(Keys!$F$2:$M$5,MATCH(About!$B$3,Keys!$E$2:$E$5,0),MATCH($A3,Keys!$F$1:$M$1,0)),0) -> 0 | ... AF3: =IFERROR(INDEX(Calcs!$B$30:$AF$33,MATCH(About!$B$3,Calcs!$A$30:$A$33,0),MATCH(AF$1,Calcs!$B$29:$AF$29,0))*INDEX(Keys!$F$2:$M$5,MATCH(About!$B$3,Keys!$E$2:$E$5,0),MATCH($A3,Keys!$F$1:$M$1,0)),0) -> 0
A4: residential buildings sector | B4: =IFERROR(INDEX(Calcs!$B$30:$AF$33,MATCH(About!$B$3,Calcs!$A$30:$A$33,0),MATCH(B$1,Calcs!$B$29:$AF$29,0))*INDEX(Keys!$F$2:$M$5,MATCH(About!$B$3,Keys!$E$2:$E$5,0),MATCH($A4,Keys!$F$1:$M$1,0)),0) -> 0 | C4: =IFERROR(INDEX(Calcs!$B$30:$AF$33,MATCH(About!$B$3,Calcs!$A$30:$A$33,0),MATCH(C$1,Calcs!$B$29:$AF$29,0))*INDEX(Keys!$F$2:$M$5,MATCH(About!$B$3,Keys!$E$2:$E$5,0),MATCH($A4,Keys!$F$1:$M$1,0)),0) -> 0 | D4: =IFERROR(INDEX(Calcs!$B$30:$AF$33,MATCH(About!$B$3,Calcs!$A$30:$A$33,0),MATCH(D$1,Calcs!$B$29:$AF$29,0))*INDEX(Keys!$F$2:$M$5,MATCH(About!$B$3,Keys!$E$2:$E$5,0),MATCH($A4,Keys!$F$1:$M$1,0)),0) -> 0 | E4: =IFERROR(INDEX(Calcs!$B$30:$AF$33,MATCH(About!$B$3,Calcs!$A$30:$A$33,0),MATCH(E$1,Calcs!$B$29:$AF$29,0))*INDEX(Keys!$F$2:$M$5,MATCH(About!$B$3,Keys!$E$2:$E$5,0),MATCH($A4,Keys!$F$1:$M$1,0)),0) -> 0 | F4: =IFERROR(INDEX(Calcs!$B$30:$AF$33,MATCH(About!$B$3,Calcs!$A$30:$A$33,0),MATCH(F$1,Calcs!$B$29:$AF$29,0))*INDEX(Keys!$F$2:$M$5,MATCH(About!$B$3,Keys!$E$2:$E$5,0),MATCH($A4,Keys!$F$1:$M$1,0)),0) -> 0 | G4: =IFERROR(INDEX(Calcs!$B$30:$AF$33,MATCH(About!$B$3,Calcs!$A$30:$A$33,0),MATCH(G$1,Calcs!$B$29:$AF$29,0))*INDEX(Keys!$F$2:$M$5,MATCH(About!$B$3,Keys!$E$2:$E$5,0),MATCH($A4,Keys!$F$1:$M$1,0)),0) -> 0 | H4: =IFERROR(INDEX(Calcs!$B$30:$AF$33,MATCH(About!$B$3,Calcs!$A$30:$A$33,0),MATCH(H$1,Calcs!$B$29:$AF$29,0))*INDEX(Keys!$F$2:$M$5,MATCH(About!$B$3,Keys!$E$2:$E$5,0),MATCH($A4,Keys!$F$1:$M$1,0)),0) -> 0 | I4: =IFERROR(INDEX(Calcs!$B$30:$AF$33,MATCH(About!$B$3,Calcs!$A$30:$A$33,0),MATCH(I$1,Calcs!$B$29:$AF$29,0))*INDEX(Keys!$F$2:$M$5,MATCH(About!$B$3,Keys!$E$2:$E$5,0),MATCH($A4,Keys!$F$1:$M$1,0)),0) -> 0 | ... AF4: =IFERROR(INDEX(Calcs!$B$30:$AF$33,MATCH(About!$B$3,Calcs!$A$30:$A$33,0),MATCH(AF$1,Calcs!$B$29:$AF$29,0))*INDEX(Keys!$F$2:$M$5,MATCH(About!$B$3,Keys!$E$2:$E$5,0),MATCH($A4,Keys!$F$1:$M$1,0)),0) -> 0
A5: commercial buildings sector | B5: =IFERROR(INDEX(Calcs!$B$30:$AF$33,MATCH(About!$B$3,Calcs!$A$30:$A$33,0),MATCH(B$1,Calcs!$B$29:$AF$29,0))*INDEX(Keys!$F$2:$M$5,MATCH(About!$B$3,Keys!$E$2:$E$5,0),MATCH($A5,Keys!$F$1:$M$1,0)),0) -> 0 | C5: =IFERROR(INDEX(Calcs!$B$30:$AF$33,MATCH(About!$B$3,Calcs!$A$30:$A$33,0),MATCH(C$1,Calcs!$B$29:$AF$29,0))*INDEX(Keys!$F$2:$M$5,MATCH(About!$B$3,Keys!$E$2:$E$5,0),MATCH($A5,Keys!$F$1:$M$1,0)),0) -> 0 | D5: =IFERROR(INDEX(Calcs!$B$30:$AF$33,MATCH(About!$B$3,Calcs!$A$30:$A$33,0),MATCH(D$1,Calcs!$B$29:$AF$29,0))*INDEX(Keys!$F$2:$M$5,MATCH(About!$B$3,Keys!$E$2:$E$5,0),MATCH($A5,Keys!$F$1:$M$1,0)),0) -> 0 | E5: =IFERROR(INDEX(Calcs!$B$30:$AF$33,MATCH(About!$B$3,Calcs!$A$30:$A$33,0),MATCH(E$1,Calcs!$B$29:$AF$29,0))*INDEX(Keys!$F$2:$M$5,MATCH(About!$B$3,Keys!$E$2:$E$5,0),MATCH($A5,Keys!$F$1:$M$1,0)),0) -> 0 | F5: =IFERROR(INDEX(Calcs!$B$30:$AF$33,MATCH(About!$B$3,Calcs!$A$30:$A$33,0),MATCH(F$1,Calcs!$B$29:$AF$29,0))*INDEX(Keys!$F$2:$M$5,MATCH(About!$B$3,Keys!$E$2:$E$5,0),MATCH($A5,Keys!$F$1:$M$1,0)),0) -> 0 | G5: =IFERROR(INDEX(Calcs!$B$30:$AF$33,MATCH(About!$B$3,Calcs!$A$30:$A$33,0),MATCH(G$1,Calcs!$B$29:$AF$29,0))*INDEX(Keys!$F$2:$M$5,MATCH(About!$B$3,Keys!$E$2:$E$5,0),MATCH($A5,Keys!$F$1:$M$1,0)),0) -> 0 | H5: =IFERROR(INDEX(Calcs!$B$30:$AF$33,MATCH(About!$B$3,Calcs!$A$30:$A$33,0),MATCH(H$1,Calcs!$B$29:$AF$29,0))*INDEX(Keys!$F$2:$M$5,MATCH(About!$B$3,Keys!$E$2:$E$5,0),MATCH($A5,Keys!$F$1:$M$1,0)),0) -> 0 | I5: =IFERROR(INDEX(Calcs!$B$30:$AF$33,MATCH(About!$B$3,Calcs!$A$30:$A$33,0),MATCH(I$1,Calcs!$B$29:$AF$29,0))*INDEX(Keys!$F$2:$M$5,MATCH(About!$B$3,Keys!$E$2:$E$5,0),MATCH($A5,Keys!$F$1:$M$1,0)),0) -> 0 | ... AF5: =IFERROR(INDEX(Calcs!$B$30:$AF$33,MATCH(About!$B$3,Calcs!$A$30:$A$33,0),MATCH(AF$1,Calcs!$B$29:$AF$29,0))*INDEX(Keys!$F$2:$M$5,MATCH(About!$B$3,Keys!$E$2:$E$5,0),MATCH($A5,Keys!$F$1:$M$1,0)),0) -> 0
A6: industry sector | B6: =IFERROR(INDEX(Calcs!$B$30:$AF$33,MATCH(About!$B$3,Calcs!$A$30:$A$33,0),MATCH(B$1,Calcs!$B$29:$AF$29,0))*INDEX(Keys!$F$2:$M$5,MATCH(About!$B$3,Keys!$E$2:$E$5,0),MATCH($A6,Keys!$F$1:$M$1,0)),0) -> 0 | C6: =IFERROR(INDEX(Calcs!$B$30:$AF$33,MATCH(About!$B$3,Calcs!$A$30:$A$33,0),MATCH(C$1,Calcs!$B$29:$AF$29,0))*INDEX(Keys!$F$2:$M$5,MATCH(About!$B$3,Keys!$E$2:$E$5,0),MATCH($A6,Keys!$F$1:$M$1,0)),0) -> 0 | D6: =IFERROR(INDEX(Calcs!$B$30:$AF$33,MATCH(About!$B$3,Calcs!$A$30:$A$33,0),MATCH(D$1,Calcs!$B$29:$AF$29,0))*INDEX(Keys!$F$2:$M$5,MATCH(About!$B$3,Keys!$E$2:$E$5,0),MATCH($A6,Keys!$F$1:$M$1,0)),0) -> 0 | E6: =IFERROR(INDEX(Calcs!$B$30:$AF$33,MATCH(About!$B$3,Calcs!$A$30:$A$33,0),MATCH(E$1,Calcs!$B$29:$AF$29,0))*INDEX(Keys!$F$2:$M$5,MATCH(About!$B$3,Keys!$E$2:$E$5,0),MATCH($A6,Keys!$F$1:$M$1,0)),0) -> 0 | F6: =IFERROR(INDEX(Calcs!$B$30:$AF$33,MATCH(About!$B$3,Calcs!$A$30:$A$33,0),MATCH(F$1,Calcs!$B$29:$AF$29,0))*INDEX(Keys!$F$2:$M$5,MATCH(About!$B$3,Keys!$E$2:$E$5,0),MATCH($A6,Keys!$F$1:$M$1,0)),0) -> 0 | G6: =IFERROR(INDEX(Calcs!$B$30:$AF$33,MATCH(About!$B$3,Calcs!$A$30:$A$33,0),MATCH(G$1,Calcs!$B$29:$AF$29,0))*INDEX(Keys!$F$2:$M$5,MATCH(About!$B$3,Keys!$E$2:$E$5,0),MATCH($A6,Keys!$F$1:$M$1,0)),0) -> 0 | H6: =IFERROR(INDEX(Calcs!$B$30:$AF$33,MATCH(About!$B$3,Calcs!$A$30:$A$33,0),MATCH(H$1,Calcs!$B$29:$AF$29,0))*INDEX(Keys!$F$2:$M$5,MATCH(About!$B$3,Keys!$E$2:$E$5,0),MATCH($A6,Keys!$F$1:$M$1,0)),0) -> 0 | I6: =IFERROR(INDEX(Calcs!$B$30:$AF$33,MATCH(About!$B$3,Calcs!$A$30:$A$33,0),MATCH(I$1,Calcs!$B$29:$AF$29,0))*INDEX(Keys!$F$2:$M$5,MATCH(About!$B$3,Keys!$E$2:$E$5,0),MATCH($A6,Keys!$F$1:$M$1,0)),0) -> 0 | ... AF6: =IFERROR(INDEX(Calcs!$B$30:$AF$33,MATCH(About!$B$3,Calcs!$A$30:$A$33,0),MATCH(AF$1,Calcs!$B$29:$AF$29,0))*INDEX(Keys!$F$2:$M$5,MATCH(About!$B$3,Keys!$E$2:$E$5,0),MATCH($A6,Keys!$F$1:$M$1,0)),0) -> 0
A7: district heat and hydrogen sector | B7: =IFERROR(INDEX(Calcs!$B$30:$AF$33,MATCH(About!$B$3,Calcs!$A$30:$A$33,0),MATCH(B$1,Calcs!$B$29:$AF$29,0))*INDEX(Keys!$F$2:$M$5,MATCH(About!$B$3,Keys!$E$2:$E$5,0),MATCH($A7,Keys!$F$1:$M$1,0)),0) -> 0 | C7: =IFERROR(INDEX(Calcs!$B$30:$AF$33,MATCH(About!$B$3,Calcs!$A$30:$A$33,0),MATCH(C$1,Calcs!$B$29:$AF$29,0))*INDEX(Keys!$F$2:$M$5,MATCH(About!$B$3,Keys!$E$2:$E$5,0),MATCH($A7,Keys!$F$1:$M$1,0)),0) -> 0 | D7: =IFERROR(INDEX(Calcs!$B$30:$AF$33,MATCH(About!$B$3,Calcs!$A$30:$A$33,0),MATCH(D$1,Calcs!$B$29:$AF$29,0))*INDEX(Keys!$F$2:$M$5,MATCH(About!$B$3,Keys!$E$2:$E$5,0),MATCH($A7,Keys!$F$1:$M$1,0)),0) -> 0 | E7: =IFERROR(INDEX(Calcs!$B$30:$AF$33,MATCH(About!$B$3,Calcs!$A$30:$A$33,0),MATCH(E$1,Calcs!$B$29:$AF$29,0))*INDEX(Keys!$F$2:$M$5,MATCH(About!$B$3,Keys!$E$2:$E$5,0),MATCH($A7,Keys!$F$1:$M$1,0)),0) -> 0 | F7: =IFERROR(INDEX(Calcs!$B$30:$AF$33,MATCH(About!$B$3,Calcs!$A$30:$A$33,0),MATCH(F$1,Calcs!$B$29:$AF$29,0))*INDEX(Keys!$F$2:$M$5,MATCH(About!$B$3,Keys!$E$2:$E$5,0),MATCH($A7,Keys!$F$1:$M$1,0)),0) -> 0 | G7: =IFERROR(INDEX(Calcs!$B$30:$AF$33,MATCH(About!$B$3,Calcs!$A$30:$A$33,0),MATCH(G$1,Calcs!$B$29:$AF$29,0))*INDEX(Keys!$F$2:$M$5,MATCH(About!$B$3,Keys!$E$2:$E$5,0),MATCH($A7,Keys!$F$1:$M$1,0)),0) -> 0 | H7: =IFERROR(INDEX(Calcs!$B$30:$AF$33,MATCH(About!$B$3,Calcs!$A$30:$A$33,0),MATCH(H$1,Calcs!$B$29:$AF$29,0))*INDEX(Keys!$F$2:$M$5,MATCH(About!$B$3,Keys!$E$2:$E$5,0),MATCH($A7,Keys!$F$1:$M$1,0)),0) -> 0 | I7: =IFERROR(INDEX(Calcs!$B$30:$AF$33,MATCH(About!$B$3,Calcs!$A$30:$A$33,0),MATCH(I$1,Calcs!$B$29:$AF$29,0))*INDEX(Keys!$F$2:$M$5,MATCH(About!$B$3,Keys!$E$2:$E$5,0),MATCH($A7,Keys!$F$1:$M$1,0)),0) -> 0 | ... AF7: =IFERROR(INDEX(Calcs!$B$30:$AF$33,MATCH(About!$B$3,Calcs!$A$30:$A$33,0),MATCH(AF$1,Calcs!$B$29:$AF$29,0))*INDEX(Keys!$F$2:$M$5,MATCH(About!$B$3,Keys!$E$2:$E$5,0),MATCH($A7,Keys!$F$1:$M$1,0)),0) -> 0
A8: LULUCF sector (does not use fuel) | B8: =IFERROR(INDEX(Calcs!$B$30:$AF$33,MATCH(About!$B$3,Calcs!$A$30:$A$33,0),MATCH(B$1,Calcs!$B$29:$AF$29,0))*INDEX(Keys!$F$2:$M$5,MATCH(About!$B$3,Keys!$E$2:$E$5,0),MATCH($A8,Keys!$F$1:$M$1,0)),0) -> 0 | C8: =IFERROR(INDEX(Calcs!$B$30:$AF$33,MATCH(About!$B$3,Calcs!$A$30:$A$33,0),MATCH(C$1,Calcs!$B$29:$AF$29,0))*INDEX(Keys!$F$2:$M$5,MATCH(About!$B$3,Keys!$E$2:$E$5,0),MATCH($A8,Keys!$F$1:$M$1,0)),0) -> 0 | D8: =IFERROR(INDEX(Calcs!$B$30:$AF$33,MATCH(About!$B$3,Calcs!$A$30:$A$33,0),MATCH(D$1,Calcs!$B$29:$AF$29,0))*INDEX(Keys!$F$2:$M$5,MATCH(About!$B$3,Keys!$E$2:$E$5,0),MATCH($A8,Keys!$F$1:$M$1,0)),0) -> 0 | E8: =IFERROR(INDEX(Calcs!$B$30:$AF$33,MATCH(About!$B$3,Calcs!$A$30:$A$33,0),MATCH(E$1,Calcs!$B$29:$AF$29,0))*INDEX(Keys!$F$2:$M$5,MATCH(About!$B$3,Keys!$E$2:$E$5,0),MATCH($A8,Keys!$F$1:$M$1,0)),0) -> 0 | F8: =IFERROR(INDEX(Calcs!$B$30:$AF$33,MATCH(About!$B$3,Calcs!$A$30:$A$33,0),MATCH(F$1,Calcs!$B$29:$AF$29,0))*INDEX(Keys!$F$2:$M$5,MATCH(About!$B$3,Keys!$E$2:$E$5,0),MATCH($A8,Keys!$F$1:$M$1,0)),0) -> 0 | G8: =IFERROR(INDEX(Calcs!$B$30:$AF$33,MATCH(About!$B$3,Calcs!$A$30:$A$33,0),MATCH(G$1,Calcs!$B$29:$AF$29,0))*INDEX(Keys!$F$2:$M$5,MATCH(About!$B$3,Keys!$E$2:$E$5,0),MATCH($A8,Keys!$F$1:$M$1,0)),0) -> 0 | H8: =IFERROR(INDEX(Calcs!$B$30:$AF$33,MATCH(About!$B$3,Calcs!$A$30:$A$33,0),MATCH(H$1,Calcs!$B$29:$AF$29,0))*INDEX(Keys!$F$2:$M$5,MATCH(About!$B$3,Keys!$E$2:$E$5,0),MATCH($A8,Keys!$F$1:$M$1,0)),0) -> 0 | I8: =IFERROR(INDEX(Calcs!$B$30:$AF$33,MATCH(About!$B$3,Calcs!$A$30:$A$33,0),MATCH(I$1,Calcs!$B$29:$AF$29,0))*INDEX(Keys!$F$2:$M$5,MATCH(About!$B$3,Keys!$E$2:$E$5,0),MATCH($A8,Keys!$F$1:$M$1,0)),0) -> 0 | ... AF8: =IFERROR(INDEX(Calcs!$B$30:$AF$33,MATCH(About!$B$3,Calcs!$A$30:$A$33,0),MATCH(AF$1,Calcs!$B$29:$AF$29,0))*INDEX(Keys!$F$2:$M$5,MATCH(About!$B$3,Keys!$E$2:$E$5,0),MATCH($A8,Keys!$F$1:$M$1,0)),0) -> 0
A9: geoengineering sector (uses industry sector rate) | B9: =IFERROR(INDEX(Calcs!$B$30:$AF$33,MATCH(About!$B$3,Calcs!$A$30:$A$33,0),MATCH(B$1,Calcs!$B$29:$AF$29,0))*INDEX(Keys!$F$2:$M$5,MATCH(About!$B$3,Keys!$E$2:$E$5,0),MATCH($A9,Keys!$F$1:$M$1,0)),0) -> 0 | C9: =IFERROR(INDEX(Calcs!$B$30:$AF$33,MATCH(About!$B$3,Calcs!$A$30:$A$33,0),MATCH(C$1,Calcs!$B$29:$AF$29,0))*INDEX(Keys!$F$2:$M$5,MATCH(About!$B$3,Keys!$E$2:$E$5,0),MATCH($A9,Keys!$F$1:$M$1,0)),0) -> 0 | D9: =IFERROR(INDEX(Calcs!$B$30:$AF$33,MATCH(About!$B$3,Calcs!$A$30:$A$33,0),MATCH(D$1,Calcs!$B$29:$AF$29,0))*INDEX(Keys!$F$2:$M$5,MATCH(About!$B$3,Keys!$E$2:$E$5,0),MATCH($A9,Keys!$F$1:$M$1,0)),0) -> 0 | E9: =IFERROR(INDEX(Calcs!$B$30:$AF$33,MATCH(About!$B$3,Calcs!$A$30:$A$33,0),MATCH(E$1,Calcs!$B$29:$AF$29,0))*INDEX(Keys!$F$2:$M$5,MATCH(About!$B$3,Keys!$E$2:$E$5,0),MATCH($A9,Keys!$F$1:$M$1,0)),0) -> 0 | F9: =IFERROR(INDEX(Calcs!$B$30:$AF$33,MATCH(About!$B$3,Calcs!$A$30:$A$33,0),MATCH(F$1,Calcs!$B$29:$AF$29,0))*INDEX(Keys!$F$2:$M$5,MATCH(About!$B$3,Keys!$E$2:$E$5,0),MATCH($A9,Keys!$F$1:$M$1,0)),0) -> 0 | G9: =IFERROR(INDEX(Calcs!$B$30:$AF$33,MATCH(About!$B$3,Calcs!$A$30:$A$33,0),MATCH(G$1,Calcs!$B$29:$AF$29,0))*INDEX(Keys!$F$2:$M$5,MATCH(About!$B$3,Keys!$E$2:$E$5,0),MATCH($A9,Keys!$F$1:$M$1,0)),0) -> 0 | H9: =IFERROR(INDEX(Calcs!$B$30:$AF$33,MATCH(About!$B$3,Calcs!$A$30:$A$33,0),MATCH(H$1,Calcs!$B$29:$AF$29,0))*INDEX(Keys!$F$2:$M$5,MATCH(About!$B$3,Keys!$E$2:$E$5,0),MATCH($A9,Keys!$F$1:$M$1,0)),0) -> 0 | I9: =IFERROR(INDEX(Calcs!$B$30:$AF$33,MATCH(About!$B$3,Calcs!$A$30:$A$33,0),MATCH(I$1,Calcs!$B$29:$AF$29,0))*INDEX(Keys!$F$2:$M$5,MATCH(About!$B$3,Keys!$E$2:$E$5,0),MATCH($A9,Keys!$F$1:$M$1,0)),0) -> 0 | ... AF9: =IFERROR(INDEX(Calcs!$B$30:$AF$33,MATCH(About!$B$3,Calcs!$A$30:$A$33,0),MATCH(AF$1,Calcs!$B$29:$AF$29,0))*INDEX(Keys!$F$2:$M$5,MATCH(About!$B$3,Keys!$E$2:$E$5,0),MATCH($A9,Keys!$F$1:$M$1,0)),0) -> 0

Sheet Keys
A1: state_abbr | B1: state_name | C1: program | E1: program | F1: transportation sector | G1: electricity sector | H1: residential buildings sector | I1: commercial buildings sector | J1: industry sector | K1: district heat and hydrogen sector | L1: LULUCF sector (does not use fuel) | M1: geoengineering sector (uses industry sector rate)
A2: AL | B2: Alabama | C2: none | E2: RGGI | F2: 0 | G2: 1 | H2: 0 | I2: 0 | J2: 0 | K2: 0 | L2: 0 | M2: 0
A3: AR | B3: Arkansas | C3: none | E3: CA | F3: 1 | G3: 1 | H3: 1 | I3: 1 | J3: 1 | K3: 1 | L3: 1 | M3: 1
A4: AZ | B4: Arizona | C4: none | E4: WA | F4: 1 | G4: 1 | H4: 1 | I4: 1 | J4: 0 | K4: 1 | L4: 0 | M4: 1
A5: CA | B5: California | C5: CA | E5: none | F5: 0 | G5: 0 | H5: 0 | I5: 0 | J5: 0 | K5: 0 | L5: 0 | M5: 0
A6: CO | B6: Colorado | C6: none
A7: CT | B7: Connecticut | C7: RGGI
A8: DE | B8: Delaware | C8: RGGI
A9: FL | B9: Florida | C9: none
A10: GA | B10: Georgia | C10: none
A11: IA | B11: Iowa | C11: none
A12: ID | B12: Idaho | C12: none
A13: IL | B13: Illinois | C13: none
A14: IN | B14: Indiana | C14: none
A15: KS | B15: Kansas | C15: none
A16: KY | B16: Kentucky | C16: none
A17: LA | B17: Louisiana | C17: none
... A49: WY | B49: Wyoming | C49: none
A51: CPI deflators to 2012$ (CPI_2012/CPI_year)
A52: year | B52: deflator_2012 | D52: short_to_metric | E52: 2025 deflator uses CPI_2025=322.0 (estimate); 2026 uses CPI-U May 2026 monthly NSA=335.123 (verify vs final BLS CPI-U)
A53: 2018 | B53: 0.91432736 | D53: 0.90718
A54: 2019 | B54: 0.89805482
A55: 2020 | B55: 0.88711067
A56: 2021 | B56: 0.84730413
A57: 2022 | B57: 0.78452102
A58: 2023 | B58: 0.75350342
A59: 2024 | B59: 0.73189034
A60: 2025 | B60: 0.71302484
A61: 2026 | B61: 0.68510368

Sheet RGGI_auctions
A1: Year | B1: Auction | C1: Date | D1: Quantity Offered | E1: CCR Sold | F1: Quantity Sold | G1: Clearing Price | H1: Total Proceeds
A2: 2024 | B2: Auction 64 | C2: 45448 | D2: 16053188 | E2: 0 | F2: 16053188 | G2: 21.03 | H2: 3.3759854e+08
A3: 2024 | B3: Auction 63 | C3: 45364 | D3: 15855879 | E3: 8416278 | F3: 24272157 | G3: 16 | H3: 388354512
A4: 2023 | B4: Auction 62 | C4: 45266 | D4: 22090709 | E4: 5565291 | F4: 27656000 | G4: 14.88 | H4: 411521280
A5: 2023 | B5: Auction 61 | C5: 45175 | D5: 21948358 | E5: 0 | F5: 21948358 | G5: 13.85 | H5: 3.0398476e+08
A6: 2023 | B6: Auction 60 | C6: 45084 | D6: 22026639 | E6: 0 | F6: 22026639 | G6: 12.73 | H6: 2.8039911e+08
A7: 2023 | B7: Auction 59 | C7: 44993 | D7: 21522877 | E7: 0 | F7: 21522877 | G7: 12.5 | H7: 2.6903596e+08
A8: 2022 | B8: Auction 58 | C8: 44902 | D8: 22233203 | E8: 0 | F8: 22233203 | G8: 12.99 | H8: 2.8880931e+08
A9: 2022 | B9: Auction 57 | C9: 44811 | D9: 22404023 | E9: 0 | F9: 22404023 | G9: 13.45 | H9: 3.0133411e+08
A10: 2022 | B10: Auction 56 | C10: 44713 | D10: 22280473 | E10: 0 | F10: 22280473 | G10: 13.9 | H10: 3.0969857e+08
A11: 2022 | B11: Auction 55 | C11: 44629 | D11: 21761269 | E11: 0 | F11: 21761269 | G11: 13.5 | H11: 2.9377713e+08
A12: 2021 | B12: Auction 54 | C12: 44531 | D12: 23121518 | E12: 3919482 | F12: 27041000 | G12: 13 | H12: 351533000
A13: 2021 | B13: Auction 53 | C13: 44447 | D13: 22911423 | E13: 0 | F13: 22911423 | G13: 9.3 | H13: 2.1307623e+08
... A27: 2018 | B27: Auction 39 | C27: 43173 | D27: 13553767 | E27: 0 | F27: 13553767 | G27: 3.79 | H27: 51368777
B28: Auction 38 | C28: 43075 | D28: 14687989 | E28: 0 | F28: 14687989 | G28: 3.8 | H28: 55814358
B29: Auction 37 | C29: 42984 | D29: 14371585 | E29: 0 | F29: 14371585 | G29: 4.35 | H29: 62516395
B30: Auction 36 | C30: 42893 | D30: 14597470 | E30: 0 | F30: 14597470 | G30: 2.53 | H30: 36931599
B31: Auction 35 | C31: 42802 | D31: 14371300 | E31: 0 | F31: 14371300 | G31: 3 | H31: 43113900
B32: Auction 34 | C32: 42711 | D32: 14791315 | E32: 0 | F32: 14791315 | G32: 3.55 | H32: 52509168
B33: Auction 33 | C33: 42620 | D33: 14911315 | E33: 0 | F33: 14911315 | G33: 4.54 | H33: 67697370
B34: Auction 32 | C34: 42522 | D34: 15089652 | E34: 0 | F34: 15089652 | G34: 4.53 | H34: 68356124
B35: Auction 31 | C35: 42438 | D35: 14838732 | E35: 0 | F35: 14838732 | G35: 5.25 | H35: 77903343
B36: Auction 30 | C36: 42340 | D36: 15374274 | E36: 0 | F36: 15374274 | G36: 7.5 | H36: 115307055
B37: Auction 29 | C37: 42256 | D37: 15374294 | E37: 10000000 | F37: 25374294 | G37: 6.02 | H37: 1.5275325e+08
B38: Auction 28 | C38: 42158 | D38: 15507571 | E38: 0 | F38: 15507571 | G38: 5.5 | H38: 85291640
B39: Auction 27 | C39: 42074 | D39: 15272670 | E39: 0 | F39: 15272670 | G39: 5.41 | H39: 82625145
... B43: Auction 23 | C43: 41703 | D43: 18491350 | E43: 5000000 | F43: 23491350 | G43: 4 | H43: 93965400
B44: Auction 22 | C44: 41612 | D44: 38329378 | E44: -- | F44: 38329378 | G44: 3 | H44: 114988134
B45: Auction 21 | C45: 41521 | D45: 38409043 | E45: -- | F45: 38409043 | G45: 2.67 | H45: 1.0255214e+08
B46: Auction 20 | C46: 41430 | D46: 38782076 | E46: -- | F46: 38782076 | G46: 3.21 | H46: 1.2449046e+08
B47: Auction 19 | C47: 41346 | D47: 37835405 | E47: -- | F47: 37835405 | G47: 2.8 | H47: 105939134
B48: Auction 18 | C48: 41248 | D48: 37563083 | E48: -- | F48: 19774000 | G48: 1.93 | H48: 38163820
B49: Auction 17 | C49: 41157 | D49: 37949558 | E49: -- | F49: 24589000 | G49: 1.93 | H49: 47456770
B50: Auction 16 | C50: 41066 | D50: 36426008 | E50: -- | F50: 20941000 | G50: 1.93 | H50: 40416130
B51: Auction 15 | C51: 40982 | D51: 34843858 | E51: -- | F51: 21559000 | G51: 1.93 | H51: 41608870
B52: Auction 14 | C52: 40884 | D52: 42983482 | E52: -- | F52: 27293000 | G52: 1.89 | H52: 51583770
B53: Auction 14 (Future) | C53: 40884 | D53: 1864951 | E53: -- | F53: 0 | G53: -- | H53: --
B54: Auction 13 | C54: 40793 | D54: 42189685 | E54: -- | F54: 7487000 | G54: 1.89 | H54: 14150430
B55: Auction 13 (Future) | C55: 40793 | D55: 1864951 | E55: -- | F55: 0 | G55: -- | H55: --
B56: Auction 12 | C56: 40702 | D56: 42034184 | E56: -- | F56: 12537000 | G56: 1.89 | H56: 25477200
...

Sheet CA_auctions
A1: Year | B1: Auction Name | C1: Curr Allow Offered | D1: Curr Allow Sold | E1: Current Auction Settlement Price | F1: Adv Offered | G1: Adv Sold | H1: Adv Settlement Price
B2: California-Quebec Joint Auctions (Aug 2018 - present)
A3: 2026 | B3: May 2026 Joint Auction #47 | C3: 49647415 | D3: 49647415 | E3: 28.81 | F3: 6481750 | G3: 6481750 | H3: 28.76
A4: 2026 | B4: February 2026 Joint Auction #46 | C4: 54975757 | D4: 54975757 | E4: 27.94 | F4: 6481750 | G4: 6263000 | H4: 27.94
A5: 2025 | B5: November 2025 Joint Auction #45 | C5: 51253305 | D5: 51253305 | E5: 28.32 | F5: 6847750 | G5: 6847750 | H5: 29.61
A6: 2025 | B6: August 2025 Joint Auction #44 | C6: 51883970 | D6: 51883970 | E6: 28.76 | F6: 6847750 | G6: 6847750 | H6: 28.5
A7: 2025 | B7: May 2025 Joint Auction #43 | C7: 51069285 | D7: 43865000 | E7: 25.87 | F7: 6847750 | G7: 6847750 | H7: 26.15
A8: 2025 | B8: February 2025 Joint Auction #42 | C8: 51466028 | D8: 51466028 | E8: 29.27 | F8: 6847750 | G8: 6847750 | H8: 28
A9: 2024 | B9: November 2024 Joint Auction #41 | C9: 52629612 | D9: 52629612 | E9: 31.91 | F9: 7211000 | G9: 7211000 | H9: 30.16
A10: 2024 | B10: August 2024 Joint Auction #40 | C10: 51179715 | D10: 51179715 | E10: 30.24 | F10: 7211000 | G10: 7211000 | H10: 29.75
A11: 2024 | B11: May 2024 Joint Auction #39 | C11: 51589488 | D11: 51589488 | E11: 37.02 | F11: 7211000 | G11: 7211000 | H11: 38.35
A12: 2024 | B12: February 2024 Joint Auction #38 | C12: 51216056 | D12: 51216056 | E12: 41.76 | F12: 7211000 | G12: 7211000 | H12: 41
A13: 2023 | B13: November 2023 Joint Auction #37 | C13: 57617565 | D13: 57617565 | E13: 38.73 | F13: 7577000 | G13: 7577000 | H13: 37.4
A14: 2023 | B14: August 2023 Joint Auction #36 | C14: 55760384 | D14: 55760384 | E14: 35.2 | F14: 7577000 | G14: 7577000 | H14: 34.16
... A34: 2018 | B34: August 2018 Joint Auction #16 | C34: 79421265 | D34: 79421265 | E34: 15.05 | F34: 9401500 | G34: 9401500 | H34: 14.9
B35: California-Ontario-Quebec Joint Auctions (Feb-May 2018)
A36: 2018 | B36: May 2018 Joint Auction #15 | C36: 90587738 | D36: 90587738 | E36: 14.65 | F36: 12427950 | G36: 6057000 | H36: 14.53
A37: 2018 | B37: February 2018 Joint Auction #14 | C37: 98215920 | D37: 98215920 | E37: 14.61 | F37: 12427950 | G37: 8576000 | H37: 14.53
B38: California-Quebec Joint Auctions (Nov 2014 - Nov 2017)
A39: 2017 | B39: November 2017 Joint Auction #13 | C39: 79548286 | D39: 79548286 | E39: 15.06 | F39: 9723500 | G39: 9723500 | H39: 14.76
A40: 2017 | B40: August 2017 Joint Auction #12 | C40: 63887833 | D40: 63887833 | E40: 14.75 | F40: 9723500 | G40: 9723500 | H40: 14.55
A41: 2017 | B41: May 2017 Joint Auction #11 | C41: 75311960 | D41: 75311960 | E41: 13.8 | F41: 9723500 | G41: 2117000 | H41: 13.57
A42: 2017 | B42: February 2017 Joint Auction #10 | C42: 65104273 | D42: 11673000 | E42: 13.57 | F42: 9723500 | G42: 701000 | H42: 13.57
A43: 2016 | B43: November 2016 Joint Auction #9 | C43: 87069495 | D43: 76960000 | E43: 12.73 | F43: 10078750 | G43: 1020000 | H43: 12.73
A44: 2016 | B44: August 2016 Joint Auction #8 | C44: 86278410 | D44: 30021000 | E44: 12.73 | F44: 10078750 | G44: 769000 | H44: 12.73
A45: 2016 | B45: May 2016 Joint Auction #7 | C45: 67675951 | D45: 7260000 | E45: 12.73 | F45: 10078750 | G45: 914000 | H45: 12.73
A46: 2016 | B46: February 2016 Joint Auction #6 | C46: 71555827 | D46: 68026000 | E46: 12.73 | F46: 10078750 | G46: 9361000 | H46: 12.73
A47: 2015 | B47: November 2015 Joint Auction #5 | C47: 75113008 | D47: 75113008 | E47: 12.73 | F47: 10431500 | G47: 10431500 | H47: 12.65
A48: 2015 | B48: August 2015 Joint Auction #4 | C48: 73429360 | D48: 73429360 | E48: 12.52 | F48: 10431500 | G48: 10431500 | H48: 12.3
A49: 2015 | B49: May 2015 Joint Auction #3 | C49: 76931627 | D49: 76931627 | E49: 12.29 | F49: 10431500 | G49: 9812000 | H49: 12.1
A50: 2015 | B50: February 2015 Joint Auction #2 | C50: 73610528 | D50: 73610528 | E50: 12.21 | F50: 10431500 | G50: 10431500 | H50: 12.1
A51: 2014 | B51: November 2014 Joint Auction #1 | C51: 23070987 | D51: 23070987 | E51: 12.1 | F51: 10787000 | G51: 10787000 | H51: 11.86
B52: California-Only Auctions (Nov 2012 - Aug 2014)
A53: 2014 | B53: August 2014 Auction #8 | C53: 22473043 | D53: 22473043 | E53: 11.5 | F53: 9260000 | G53: 6470000 | H53: 11.34
A54: 2014 | B54: May 2014 Auction #7 | C54: 16947080 | D54: 16947080 | E54: 11.5 | F54: 9260000 | G54: 4036000 | H54: 11.34
A55: 2014 | B55: February 2014 Auction #6 | C55: 19538695 | D55: 19538695 | E55: 11.48 | F55: 9260000 | G55: 9260000 | H55: 11.38
A56: 2013 | B56: November 2013 Auction #5 | C56: 16614526 | D56: 16614526 | E56: 11.48 | F56: 9560000 | G56: 9560000 | H56: 11.1
A57: 2013 | B57: August 2013 Auction #4 | C57: 13865422 | D57: 13865422 | E57: 12.22 | F57: 9560000 | G57: 9560000 | H57: 11.1
A58: 2013 | B58: May 2013 Auction #3 | C58: 14522048 | D58: 14522048 | E58: 14 | F58: 9560000 | G58: 7515000 | H58: 10.71
A59: 2013 | B59: February 2013 Auction #2 | C59: 12924822 | D59: 12924822 | E59: 13.62 | F59: 9560000 | G59: 4440000 | H59: 10.71
...

Sheet RGGI_Auction66_states
A1: RGGI Auction 66 (June 4, 2025) - State Proceeds and Allowances
A2: State | B2: Auction 66 Allowances Sold | C2: Cumulative Allowances Sold (Auctions 1-66) | D2: Auction 66 Proceeds ($) | E2: Cumulative Proceeds (Auctions 1-66) ($)
A3: Connecticut | B3: 870037 | C3: 86481149 | D3: 17444242 | E3: 4.6987367e+08
A4: Delaware | B4: 634114 | C4: 51272316 | D4: 12713986 | E4: 3.1041372e+08
A5: Maine | B5: 502730 | C5: 43590682 | D5: 10079736 | E5: 2.4613619e+08
A6: Maryland | B6: 2782327 | C6: 264974892 | D6: 55785656 | E6: 1.4139133e+09
A7: Massachusetts | B7: 2150772 | C7: 216223402 | D7: 43122979 | E7: 1.162143e+09
A8: New Hampshire | B8: 725342 | C8: 61911412 | D8: 14543107 | E8: 3.6264681e+08
A9: New Jersey | B9: 2984471 | C9: 114644934 | D9: 59838644 | E9: 9.4534043e+08
A10: New York | B10: 4845845 | C10: 494923792 | D10: 97159192 | E10: 2.6506868e+09
A11: Rhode Island | B11: 347656 | C11: 28268588 | D11: 6970502.8 | E11: 1.7389994e+08
A12: Vermont | B12: 100314 | C12: 9952168 | D12: 2011295.7 | E12: 53611149
A13: Sub-Total | B13: 15943608 | C13: 1372243335 | D13: 3.1966934e+08 | E13: 7.788665e+09
A14: Virginia (Total for Auctions 51 to 62) | C14: 68122314 | E14: 8.2772119e+08
A15: Total Cumulative | C15: 1440365649 | E15: 8.6163862e+09

Sheet WA_prices
A1: Washington Cap-and-Invest - most recent auction settlement price (held constant)
A2: Auction | B2: Auction #14 (June 4, 2026)
A3: Auction date | B3: 46177
A4: Current-vintage settlement price, $/metric ton CO2e (nominal) | B4: 64.56
A5: Deflator to 2012$ (CPI_2012/CPI_2026) | B5: =Keys!$B$61 -> 0.68510368
A6: Settlement price (2012$/metric ton CO2e) - HELD CONSTANT all years | B6: =B4*B5 -> 44.230293
A7: Future-vintage settlement price (nominal $/metric ton, reference only) | B7: 30
A8: WA Cap-and-Invest program start year | B8: 2023
A9: Source | B9: https://ecology.wa.gov/air-climate/climate-commitment-act/cap-and-invest/auctions-and-market

Sheet Calcs
A1: RGGI derivation (clearing price -> 2012$/metric ton)
A2: year | B2: avg $/short ton | C2: 2012$/short ton | D2: 2012$/metric ton
A3: 2018 | B3: =AVERAGEIFS(RGGI_auctions!$G:$G,RGGI_auctions!$A:$A,A3) -> 4.415 | C3: =B3*Keys!$B$53 -> 4.0367553 | D3: =C3*Keys!$D$53 -> 3.6620637
A4: 2019 | B4: =AVERAGEIFS(RGGI_auctions!$G:$G,RGGI_auctions!$A:$A,A4) -> 5.425 | C4: =B4*Keys!$B$54 -> 4.8719474 | D4: =C4*Keys!$D$53 -> 4.4197332
A5: 2020 | B5: =AVERAGEIFS(RGGI_auctions!$G:$G,RGGI_auctions!$A:$A,A5) -> 6.4075 | C5: =B5*Keys!$B$55 -> 5.6841616 | D5: =C5*Keys!$D$53 -> 5.1565577
A6: 2021 | B6: =AVERAGEIFS(RGGI_auctions!$G:$G,RGGI_auctions!$A:$A,A6) -> 9.4675 | C6: =B6*Keys!$B$56 -> 8.0218518 | D6: =C6*Keys!$D$53 -> 7.2772636
A7: 2022 | B7: =AVERAGEIFS(RGGI_auctions!$G:$G,RGGI_auctions!$A:$A,A7) -> 13.46 | C7: =B7*Keys!$B$57 -> 10.559653 | D7: =C7*Keys!$D$53 -> 9.579506
A8: 2023 | B8: =AVERAGEIFS(RGGI_auctions!$G:$G,RGGI_auctions!$A:$A,A8) -> 13.49 | C8: =B8*Keys!$B$58 -> 10.164761 | D8: =C8*Keys!$D$53 -> 9.221268
A9: 2024 | B9: =AVERAGEIFS(RGGI_auctions!$G:$G,RGGI_auctions!$A:$A,A9) -> 20.7075 | C9: =B9*Keys!$B$59 -> 15.155619 | D9: =C9*Keys!$D$53 -> 13.748875
A10: 2025 | B10: =AVERAGEIFS(RGGI_auctions!$G:$G,RGGI_auctions!$A:$A,A10) -> 22.0925 | C10: =B10*Keys!$B$60 -> 15.752501 | D10: =C10*Keys!$D$53 -> 14.290354
A12: slope | B12: =SLOPE(D3:D10,A3:A10) -> 1.6135728
A13: intercept | B13: =INTERCEPT(D3:D10,A3:A10) -> -3253.4179
A15: CA derivation (settlement price -> 2012$/metric ton)
A16: year | B16: avg $/metric ton | C16: 2012$/metric ton
A17: 2018 | B17: =AVERAGEIFS(CA_auctions!$E:$E,CA_auctions!$A:$A,A17) -> 14.905 | C17: =B17*Keys!$B$53 -> 13.628049
A18: 2019 | B18: =AVERAGEIFS(CA_auctions!$E:$E,CA_auctions!$A:$A,A18) -> 16.835 | C18: =B18*Keys!$B$54 -> 15.118753
A19: 2020 | B19: =AVERAGEIFS(CA_auctions!$E:$E,CA_auctions!$A:$A,A19) -> 17.04 | C19: =B19*Keys!$B$55 -> 15.116366
A20: 2021 | B20: =AVERAGEIFS(CA_auctions!$E:$E,CA_auctions!$A:$A,A20) -> 22.04 | C20: =B20*Keys!$B$56 -> 18.674583
A21: 2022 | B21: =AVERAGEIFS(CA_auctions!$E:$E,CA_auctions!$A:$A,A21) -> 28.45 | C21: =B21*Keys!$B$57 -> 22.319623
A22: 2023 | B22: =AVERAGEIFS(CA_auctions!$E:$E,CA_auctions!$A:$A,A22) -> 33.0275 | C22: =B22*Keys!$B$58 -> 24.886334
A23: 2024 | B23: =AVERAGEIFS(CA_auctions!$E:$E,CA_auctions!$A:$A,A23) -> 35.2325 | C23: =B23*Keys!$B$59 -> 25.786326
A24: 2025 | B24: =AVERAGEIFS(CA_auctions!$E:$E,CA_auctions!$A:$A,A24) -> 28.055 | C24: =B24*Keys!$B$60 -> 20.003912
A25: slope | B25: =SLOPE(C17:C24,A17:A24) -> 1.5586173
A26: intercept | B26: =INTERCEPT(C17:C24,A17:A24) -> -3131.3031
A28: Program price by year (2012$/metric ton; WA nominal)
A29: program | B29: 2020 | C29: 2021 | D29: 2022 | E29: 2023 | F29: 2024 | G29: 2025 | H29: 2026 | I29: 2027 | J29: 2028 | K29: 2029 | L29: 2030 | M29: 2031 | N29: 2032 | O29: 2033 | P29: 2034 | Q29: 2035 | R29: 2036 | S29: 2037 | T29: 2038 | U29: 2039 | V29: 2040 | W29: 2041 | X29: 2042 | Y29: 2043 | Z29: 2044 | AA29: 2045 | AB29: 2046 | AC29: 2047 | AD29: 2048 | AE29: 2049 | AF29: 2050
A30: RGGI | B30: =D5 -> 5.1565577 | C30: =D6 -> 7.2772636 | D30: =D7 -> 9.579506 | E30: =D8 -> 9.221268 | F30: =D9 -> 13.748875 | G30: =D10 -> 14.290354 | H30: =2026*$B$12+$B$13 -> 15.68053 | I30: =2027*$B$12+$B$13 -> 17.294103 | J30: =2028*$B$12+$B$13 -> 18.907676 | K30: =2029*$B$12+$B$13 -> 20.521249 | L30: =2030*$B$12+$B$13 -> 22.134821 | M30: =2031*$B$12+$B$13 -> 23.748394 | N30: =2032*$B$12+$B$13 -> 25.361967 | O30: =2033*$B$12+$B$13 -> 26.97554 | P30: =2034*$B$12+$B$13 -> 28.589113 | Q30: =2035*$B$12+$B$13 -> 30.202685 | R30: =2036*$B$12+$B$13 -> 31.816258 | S30: =2037*$B$12+$B$13 -> 33.429831 | T30: =2038*$B$12+$B$13 -> 35.043404 | U30: =2039*$B$12+$B$13 -> 36.656976 | V30: =2040*$B$12+$B$13 -> 38.270549 | W30: =2041*$B$12+$B$13 -> 39.884122 | X30: =2042*$B$12+$B$13 -> 41.497695 | Y30: =2043*$B$12+$B$13 -> 43.111268 | Z30: =2044*$B$12+$B$13 -> 44.72484 | AA30: =2045*$B$12+$B$13 -> 46.338413 | AB30: =2046*$B$12+$B$13 -> 47.951986 | AC30: =2047*$B$12+$B$13 -> 49.565559 | AD30: =2048*$B$12+$B$13 -> 51.179132 | AE30: =2049*$B$12+$B$13 -> 52.792704 | AF30: =2050*$B$12+$B$13 -> 54.406277
A31: CA | B31: =C19 -> 15.116366 | C31: =C20 -> 18.674583 | D31: =C21 -> 22.319623 | E31: =C22 -> 24.886334 | F31: =C23 -> 25.786326 | G31: =C24 -> 20.003912 | H31: =2026*$B$25+$B$26 -> 26.455521 | I31: =2027*$B$25+$B$26 -> 28.014138 | J31: =2028*$B$25+$B$26 -> 29.572756 | K31: =2029*$B$25+$B$26 -> 31.131373 | L31: =2030*$B$25+$B$26 -> 32.68999 | M31: =L31 -> 32.68999 | N31: =M31 -> 32.68999 | O31: =N31 -> 32.68999 | P31: =O31 -> 32.68999 | Q31: =P31 -> 32.68999 | R31: =Q31 -> 32.68999 | S31: =R31 -> 32.68999 | T31: =S31 -> 32.68999 | ... AF31: =AE31 -> 32.68999
A32: WA | B32: 0 | C32: 0 | D32: 0 | E32: =WA_prices!$B$6 -> 44.230293 | F32: =WA_prices!$B$6 -> 44.230293 | G32: =WA_prices!$B$6 -> 44.230293 | H32: =WA_prices!$B$6 -> 44.230293 | I32: =WA_prices!$B$6 -> 44.230293 | J32: =WA_prices!$B$6 -> 44.230293 | K32: =WA_prices!$B$6 -> 44.230293 | L32: =WA_prices!$B$6 -> 44.230293 | ... AF32: =WA_prices!$B$6 -> 44.230293
A33: none | B33: 0 | C33: 0 | D33: 0 | E33: 0 | F33: 0 | G33: 0 | H33: 0 | I33: 0 | J33: 0 | K33: 0 | L33: 0 | M33: 0 | N33: 0 | O33: 0 | P33: 0 | Q33: 0 | R33: 0 | S33: 0 | T33: 0 | U33: 0 | V33: 0 | W33: 0 | X33: 0 | Y33: 0 | Z33: 0 | AA33: 0 | AB33: 0 | AC33: 0 | AD33: 0 | AE33: 0 | AF33: 0
