Workbook

Sheet About
A1: State-level SYSHECF Pipeline Output - North Dakota | B1: North Dakota
A3: Pipeline: elec_timeslice_pipeline v1.2 (consolidated workbooks + literature-standard validation suite)
A4: Run date: 2026-07-27 16:28
A6: Methodology (SYSHECF-focused):
A7: Variable techs (solar PV, distributed PV, onshore wind, offshore wind, hydro, etc.) derive hourly capacity factors from Cambium 2022 Mid-case state hourly generation divided by Cambium annual capacity (anchor year 2024).
A8: Non-variable techs (lignite, hydrogen, SMR, MSW, steam-turbine, etc.) use legacy SYSHECF templates where present, falling back to flat constant CF profiles otherwise.
A9: 6 timeslices: Winter / Spring / Summer / Fall + Summer Peak (top-5 days) + Winter Peak (top-5 days). Per-slice CF = mean of hourly CFs across days in that slice.
A11: Weather-year basis: Cambium 2022 underlying weather year is 2012, mapped to the 2018 calendar via a 1-day shift to align day-of-week patterns.
A13: Curtailment treatment:
A14: Cambium 2022 state files contain NO explicit curtailment columns; per-tech generation is reported AFTER curtailment. EPS expects pre-curtailment resource availability. Optional per-tech, per-state scaling factor is supported via preset YAML key `curtailment_addback`. Effective CF = cf_observed / (1 - f_t), clipped to [0, 1].
A15: Active addback factors: (none)
A18: Sources & References
A21: Cambium 2022 Mid-case scenario:
... A39: natural gas peaker, petroleum and hydrogen-CT are EXCEL-AUTHORITATIVE: their SYSHECF tabs are live formulas tracing to staged raw tabs (923 2024/2025 Source, BHRaSYC Capacity Source, Cambium Peaker Source, Clustering, Peaker Keys, Peaker Targets). Level = observed fleet CF, mean(2024,2025), over BHRaSYC capacity, / RAF (=1.0). Shape = Cambium gas-ct, rescaled with 6 clip-compensating multiplicative passes plus 4 additive water-fill passes, so hours saturate at 100% and growth shifts to unsaturated hours. Petroleum and hydrogen-CT mirror the peaker verbatim; the observed petroleum CF stays on Peaker Targets as input to the follow-on BGDPbES/HYECFCA recalibration. The exported CSVs for these three techs are read from the computed tabs, not from Python. Plan: state-data-forecast/docs/plans/syshecf-peaker-petroleum-2026-08-26.md.

Sheet Hourly Renewable CFs
A1: timestamp_lst | B1: solar-pv | C1: solar-pv-dist | D1: solar-thermal | E1: onshore-wind | F1: offshore-wind | G1: hydro | H1: pumped-hydro | I1: nuclear | J1: combined-cycle | K1: combined-cycle-CCS | L1: natural-gas-peaker | M1: hard-coal | N1: hard-coal-CCS | O1: biomass | P1: biomass-CCS | Q1: geothermal | R1: petroleum
A2: capacity_MW | B2: 0 | C2: 82.2 | D2: 0 | E2: 4727.9 | F2: 0 | G2: 510 | H2: 0 | I2: 0 | J2: 0 | K2: 0 | L2: 425.2 | M2: 2679 | N2: 0 | O2: 0 | P2: 0 | Q2: 0 | R2: 148.8
A3: 2018-01-01 00:00:00 | B3: 0 | C3: 0 | D3: 0 | E3: 0.093804861 | F3: 0 | G3: 0.20921569 | H3: 0 | I3: 0 | J3: 0 | K3: 0 | L3: 0 | M3: 0.62814483 | N3: 0 | O3: 0 | P3: 0 | Q3: 0 | R3: 0
A4: 2018-01-01 01:00:00 | B4: 0 | C4: 0 | D4: 0 | E4: 0.10156729 | F4: 0 | G4: 0.20921569 | H4: 0 | I4: 0 | J4: 0 | K4: 0 | L4: 0 | M4: 0.62814483 | N4: 0 | O4: 0 | P4: 0 | Q4: 0 | R4: 0
A5: 2018-01-01 02:00:00 | B5: 0 | C5: 0 | D5: 0 | E5: 0.11070454 | F5: 0 | G5: 0.20921569 | H5: 0 | I5: 0 | J5: 0 | K5: 0 | L5: 0 | M5: 0.62814483 | N5: 0 | O5: 0 | P5: 0 | Q5: 0 | R5: 0
A6: 2018-01-01 03:00:00 | B6: 0 | C6: 0 | D6: 0 | E6: 0.11303116 | F6: 0 | G6: 0.20921569 | H6: 0 | I6: 0 | J6: 0 | K6: 0 | L6: 0 | M6: 0.62814483 | N6: 0 | O6: 0 | P6: 0 | Q6: 0 | R6: 0
A7: 2018-01-01 04:00:00 | B7: 0 | C7: 0 | D7: 0 | E7: 0.1181074 | F7: 0 | G7: 0.20921569 | H7: 0 | I7: 0 | J7: 0 | K7: 0 | L7: 0 | M7: 0.62814483 | N7: 0 | O7: 0 | P7: 0 | Q7: 0 | R7: 0
A8: 2018-01-01 05:00:00 | B8: 0 | C8: 0 | D8: 0 | E8: 0.11948222 | F8: 0 | G8: 1 | H8: 0 | I8: 0 | J8: 0 | K8: 0 | L8: 0 | M8: 0.78697275 | N8: 0 | O8: 0 | P8: 0 | Q8: 0 | R8: 0
A9: 2018-01-01 06:00:00 | B9: 0 | C9: 0 | D9: 0 | E9: 0.11937647 | F9: 0 | G9: 1 | H9: 0 | I9: 0 | J9: 0 | K9: 0 | L9: 0 | M9: 0.78697275 | N9: 0 | O9: 0 | P9: 0 | Q9: 0 | R9: 0
A10: 2018-01-01 07:00:00 | B10: 0 | C10: 0.00486618 | D10: 0 | E10: 0.1219992 | F10: 0 | G10: 1 | H10: 0 | I10: 0 | J10: 0 | K10: 0 | L10: 0 | M10: 0.78697275 | N10: 0 | O10: 0 | P10: 0 | Q10: 0 | R10: 0
A11: 2018-01-01 08:00:00 | B11: 0 | C11: 0.085158151 | D11: 0 | E11: 0.12707545 | F11: 0 | G11: 1 | H11: 0 | I11: 0 | J11: 0 | K11: 0 | L11: 0 | M11: 0.70992908 | N11: 0 | O11: 0 | P11: 0 | Q11: 0 | R11: 0
A12: 2018-01-01 09:00:00 | B12: 0 | C12: 0.16180049 | D12: 0 | E12: 0.12895789 | F12: 0 | G12: 1 | H12: 0 | I12: 0 | J12: 0 | K12: 0 | L12: 0 | M12: 0.78697275 | N12: 0 | O12: 0 | P12: 0 | Q12: 0 | R12: 0
A13: 2018-01-01 10:00:00 | B13: 0 | C13: 0.16788321 | D13: 0 | E13: 0.10992195 | F13: 0 | G13: 1 | H13: 0 | I13: 0 | J13: 0 | K13: 0 | L13: 0 | M13: 0.78697275 | N13: 0 | O13: 0 | P13: 0 | Q13: 0 | R13: 0
... A8762: 2018-12-31 23:00:00 | B8762: 0 | C8762: 0 | D8762: 0 | E8762: 0.07976057 | F8762: 0 | G8762: 0.20921569 | H8762: 0 | I8762: 0 | J8762: 0 | K8762: 0 | L8762: 0 | M8762: 0.62814483 | N8762: 0 | O8762: 0 | P8762: 0 | Q8762: 0 | R8762: 0

Sheet SYSHECF-hard-coal
A1: hard coal | B1: Hour0 | C1: Hour1 | D1: Hour2 | E1: Hour3 | F1: Hour4 | G1: Hour5 | H1: Hour6 | I1: Hour7 | J1: Hour8 | K1: Hour9 | L1: Hour10 | M1: Hour11 | N1: Hour12 | O1: Hour13 | P1: Hour14 | Q1: Hour15 | R1: Hour16 | S1: Hour17 | T1: Hour18 | U1: Hour19 | V1: Hour20 | W1: Hour21 | X1: Hour22 | Y1: Hour23
A2: Winter | B2: 0.8313 | C2: 0.8313 | D2: 0.8313 | E2: 0.8313 | F2: 0.8313 | G2: 0.8313 | H2: 0.8313 | I2: 0.8313 | J2: 0.8313 | K2: 0.8313 | L2: 0.8313 | M2: 0.8313 | N2: 0.8313 | O2: 0.8313 | P2: 0.8313 | Q2: 0.8313 | R2: 0.8313 | S2: 0.8313 | T2: 0.8313 | U2: 0.8313 | V2: 0.8313 | W2: 0.8313 | X2: 0.8313 | Y2: 0.8313
A3: Spring | B3: 0.8313 | C3: 0.8313 | D3: 0.8313 | E3: 0.8313 | F3: 0.8313 | G3: 0.8313 | H3: 0.8313 | I3: 0.8313 | J3: 0.8313 | K3: 0.8313 | L3: 0.8313 | M3: 0.8313 | N3: 0.8313 | O3: 0.8313 | P3: 0.8313 | Q3: 0.8313 | R3: 0.8313 | S3: 0.8313 | T3: 0.8313 | U3: 0.8313 | V3: 0.8313 | W3: 0.8313 | X3: 0.8313 | Y3: 0.8313
A4: Summer | B4: 0.8313 | C4: 0.8313 | D4: 0.8313 | E4: 0.8313 | F4: 0.8313 | G4: 0.8313 | H4: 0.8313 | I4: 0.8313 | J4: 0.8313 | K4: 0.8313 | L4: 0.8313 | M4: 0.8313 | N4: 0.8313 | O4: 0.8313 | P4: 0.8313 | Q4: 0.8313 | R4: 0.8313 | S4: 0.8313 | T4: 0.8313 | U4: 0.8313 | V4: 0.8313 | W4: 0.8313 | X4: 0.8313 | Y4: 0.8313
A5: Fall | B5: 0.8313 | C5: 0.8313 | D5: 0.8313 | E5: 0.8313 | F5: 0.8313 | G5: 0.8313 | H5: 0.8313 | I5: 0.8313 | J5: 0.8313 | K5: 0.8313 | L5: 0.8313 | M5: 0.8313 | N5: 0.8313 | O5: 0.8313 | P5: 0.8313 | Q5: 0.8313 | R5: 0.8313 | S5: 0.8313 | T5: 0.8313 | U5: 0.8313 | V5: 0.8313 | W5: 0.8313 | X5: 0.8313 | Y5: 0.8313
A6: Summer Peak | B6: 0.8313 | C6: 0.8313 | D6: 0.8313 | E6: 0.8313 | F6: 0.8313 | G6: 0.8313 | H6: 0.8313 | I6: 0.8313 | J6: 0.8313 | K6: 0.8313 | L6: 0.8313 | M6: 0.8313 | N6: 0.8313 | O6: 0.8313 | P6: 0.8313 | Q6: 0.8313 | R6: 0.8313 | S6: 0.8313 | T6: 0.8313 | U6: 0.8313 | V6: 0.8313 | W6: 0.8313 | X6: 0.8313 | Y6: 0.8313
A7: Winter Peak | B7: 0.8313 | C7: 0.8313 | D7: 0.8313 | E7: 0.8313 | F7: 0.8313 | G7: 0.8313 | H7: 0.8313 | I7: 0.8313 | J7: 0.8313 | K7: 0.8313 | L7: 0.8313 | M7: 0.8313 | N7: 0.8313 | O7: 0.8313 | P7: 0.8313 | Q7: 0.8313 | R7: 0.8313 | S7: 0.8313 | T7: 0.8313 | U7: 0.8313 | V7: 0.8313 | W7: 0.8313 | X7: 0.8313 | Y7: 0.8313

Sheet SYSHECF-steam-turbine
A1: natural gas steam turbine | B1: Hour0 | C1: Hour1 | D1: Hour2 | E1: Hour3 | F1: Hour4 | G1: Hour5 | H1: Hour6 | I1: Hour7 | J1: Hour8 | K1: Hour9 | L1: Hour10 | M1: Hour11 | N1: Hour12 | O1: Hour13 | P1: Hour14 | Q1: Hour15 | R1: Hour16 | S1: Hour17 | T1: Hour18 | U1: Hour19 | V1: Hour20 | W1: Hour21 | X1: Hour22 | Y1: Hour23
A2: Winter | B2: 0.1815 | C2: 0.1815 | D2: 0.1815 | E2: 0.1815 | F2: 0.1815 | G2: 0.1815 | H2: 0.1815 | I2: 0.1815 | J2: 0.1815 | K2: 0.1815 | L2: 0.1815 | M2: 0.1815 | N2: 0.1815 | O2: 0.1815 | P2: 0.1815 | Q2: 0.1815 | R2: 0.1815 | S2: 0.1815 | T2: 0.1815 | U2: 0.1815 | V2: 0.1815 | W2: 0.1815 | X2: 0.1815 | Y2: 0.1815
A3: Spring | B3: 0.1815 | C3: 0.1815 | D3: 0.1815 | E3: 0.1815 | F3: 0.1815 | G3: 0.1815 | H3: 0.1815 | I3: 0.1815 | J3: 0.1815 | K3: 0.1815 | L3: 0.1815 | M3: 0.1815 | N3: 0.1815 | O3: 0.1815 | P3: 0.1815 | Q3: 0.1815 | R3: 0.1815 | S3: 0.1815 | T3: 0.1815 | U3: 0.1815 | V3: 0.1815 | W3: 0.1815 | X3: 0.1815 | Y3: 0.1815
A4: Summer | B4: 0.1815 | C4: 0.1815 | D4: 0.1815 | E4: 0.1815 | F4: 0.1815 | G4: 0.1815 | H4: 0.1815 | I4: 0.1815 | J4: 0.1815 | K4: 0.1815 | L4: 0.1815 | M4: 0.1815 | N4: 0.1815 | O4: 0.1815 | P4: 0.1815 | Q4: 0.1815 | R4: 0.1815 | S4: 0.1815 | T4: 0.1815 | U4: 0.1815 | V4: 0.1815 | W4: 0.1815 | X4: 0.1815 | Y4: 0.1815
A5: Fall | B5: 0.1815 | C5: 0.1815 | D5: 0.1815 | E5: 0.1815 | F5: 0.1815 | G5: 0.1815 | H5: 0.1815 | I5: 0.1815 | J5: 0.1815 | K5: 0.1815 | L5: 0.1815 | M5: 0.1815 | N5: 0.1815 | O5: 0.1815 | P5: 0.1815 | Q5: 0.1815 | R5: 0.1815 | S5: 0.1815 | T5: 0.1815 | U5: 0.1815 | V5: 0.1815 | W5: 0.1815 | X5: 0.1815 | Y5: 0.1815
A6: Summer Peak | B6: 0.1815 | C6: 0.1815 | D6: 0.1815 | E6: 0.1815 | F6: 0.1815 | G6: 0.1815 | H6: 0.1815 | I6: 0.1815 | J6: 0.1815 | K6: 0.1815 | L6: 0.1815 | M6: 0.1815 | N6: 0.1815 | O6: 0.1815 | P6: 0.1815 | Q6: 0.1815 | R6: 0.1815 | S6: 0.1815 | T6: 0.1815 | U6: 0.1815 | V6: 0.1815 | W6: 0.1815 | X6: 0.1815 | Y6: 0.1815
A7: Winter Peak | B7: 0.1815 | C7: 0.1815 | D7: 0.1815 | E7: 0.1815 | F7: 0.1815 | G7: 0.1815 | H7: 0.1815 | I7: 0.1815 | J7: 0.1815 | K7: 0.1815 | L7: 0.1815 | M7: 0.1815 | N7: 0.1815 | O7: 0.1815 | P7: 0.1815 | Q7: 0.1815 | R7: 0.1815 | S7: 0.1815 | T7: 0.1815 | U7: 0.1815 | V7: 0.1815 | W7: 0.1815 | X7: 0.1815 | Y7: 0.1815

Sheet SYSHECF-combined-cycle
A1: natural gas combined cycle | B1: Hour0 | C1: Hour1 | D1: Hour2 | E1: Hour3 | F1: Hour4 | G1: Hour5 | H1: Hour6 | I1: Hour7 | J1: Hour8 | K1: Hour9 | L1: Hour10 | M1: Hour11 | N1: Hour12 | O1: Hour13 | P1: Hour14 | Q1: Hour15 | R1: Hour16 | S1: Hour17 | T1: Hour18 | U1: Hour19 | V1: Hour20 | W1: Hour21 | X1: Hour22 | Y1: Hour23
A2: Winter | B2: 0.51288244 | C2: 0.50118473 | D2: 0.49747419 | E2: 0.49706277 | F2: 0.50551723 | G2: 0.53032072 | H2: 0.55984556 | I2: 0.56291333 | J2: 0.53694384 | K2: 0.51566533 | L2: 0.4998576 | M2: 0.49327545 | N2: 0.48929492 | O2: 0.48246649 | P2: 0.48119019 | Q2: 0.49393253 | R2: 0.53573738 | S2: 0.58821038 | T2: 0.62477939 | U2: 0.63343994 | V2: 0.62549776 | W2: 0.60774708 | X2: 0.57809728 | Y2: 0.54177447
A3: Spring | B3: 0.44931427 | C3: 0.42684909 | D3: 0.4191351 | E3: 0.4191086 | F3: 0.42996891 | G3: 0.45307614 | H3: 0.45238249 | I3: 0.43844532 | J3: 0.42596647 | K3: 0.42267969 | L3: 0.43255287 | M3: 0.44506839 | N3: 0.45684524 | O3: 0.46607646 | P3: 0.47509399 | Q3: 0.48853051 | R3: 0.51364725 | S3: 0.55173884 | T3: 0.57698797 | U3: 0.60021422 | V3: 0.60561196 | W3: 0.59039553 | X3: 0.54861863 | Y3: 0.49616634
A4: Summer | B4: 0.62444426 | C4: 0.58494536 | D4: 0.56332557 | E4: 0.55672146 | F4: 0.55930507 | G4: 0.56424852 | H4: 0.55166578 | I4: 0.55584313 | J4: 0.55833162 | K4: 0.5803769 | L4: 0.62334362 | M4: 0.66617151 | N4: 0.69838981 | O4: 0.71895184 | P4: 0.73216384 | Q4: 0.74328999 | R4: 0.75295318 | S4: 0.7644301 | T4: 0.77800855 | U4: 0.7889056 | V4: 0.79348347 | W4: 0.7863306 | X4: 0.73609538 | Y4: 0.6733693
A5: Fall | B5: 0.51956621 | C5: 0.50106475 | D5: 0.49322185 | E5: 0.49081831 | F5: 0.4972334 | G5: 0.52191991 | H5: 0.53336859 | I5: 0.51312427 | J5: 0.50024416 | K5: 0.489994 | L5: 0.50469143 | M5: 0.5267817 | N5: 0.54572355 | O5: 0.55944662 | P5: 0.56964668 | Q5: 0.58929025 | R5: 0.62511064 | S5: 0.65670033 | T5: 0.69157633 | U5: 0.70049806 | V5: 0.6896596 | W5: 0.65646097 | X5: 0.60557472 | Y5: 0.55595307
A6: Summer Peak | B6: 0.69596251 | C6: 0.64811975 | D6: 0.62143965 | E6: 0.60759672 | F6: 0.60744554 | G6: 0.61101147 | H6: 0.58448018 | I6: 0.6140232 | J6: 0.63774209 | K6: 0.68197669 | L6: 0.73029786 | M6: 0.77589979 | N6: 0.79267037 | O6: 0.79989972 | P6: 0.80537018 | Q6: 0.80960003 | R6: 0.81539338 | S6: 0.81992874 | T6: 0.8301114 | U6: 0.83458558 | V6: 0.84432932 | W6: 0.85809488 | X6: 0.83285078 | Y6: 0.77615596
A7: Winter Peak | B7: 0.61300008 | C7: 0.60308543 | D7: 0.59977805 | E7: 0.59698776 | F7: 0.60464419 | G7: 0.63444931 | H7: 0.67070183 | I7: 0.66537466 | J7: 0.63035722 | K7: 0.5880161 | L7: 0.57152222 | M7: 0.5569009 | N7: 0.54534618 | O7: 0.5188962 | P7: 0.51555369 | Q7: 0.54249154 | R7: 0.60515575 | S7: 0.6545036 | T7: 0.69006417 | U7: 0.69570476 | V7: 0.69071507 | W7: 0.69218501 | X7: 0.67357936 | Y7: 0.63713816

Sheet SYSHECF-nuclear
A1: nuclear | B1: Hour0 | C1: Hour1 | D1: Hour2 | E1: Hour3 | F1: Hour4 | G1: Hour5 | H1: Hour6 | I1: Hour7 | J1: Hour8 | K1: Hour9 | L1: Hour10 | M1: Hour11 | N1: Hour12 | O1: Hour13 | P1: Hour14 | Q1: Hour15 | R1: Hour16 | S1: Hour17 | T1: Hour18 | U1: Hour19 | V1: Hour20 | W1: Hour21 | X1: Hour22 | Y1: Hour23
A2: Winter | B2: 0.909 | C2: 0.909 | D2: 0.909 | E2: 0.909 | F2: 0.909 | G2: 0.909 | H2: 0.909 | I2: 0.909 | J2: 0.909 | K2: 0.909 | L2: 0.909 | M2: 0.909 | N2: 0.909 | O2: 0.909 | P2: 0.909 | Q2: 0.909 | R2: 0.909 | S2: 0.909 | T2: 0.909 | U2: 0.909 | V2: 0.909 | W2: 0.909 | X2: 0.909 | Y2: 0.909
A3: Spring | B3: 0.909 | C3: 0.909 | D3: 0.909 | E3: 0.909 | F3: 0.909 | G3: 0.909 | H3: 0.909 | I3: 0.909 | J3: 0.909 | K3: 0.909 | L3: 0.909 | M3: 0.909 | N3: 0.909 | O3: 0.909 | P3: 0.909 | Q3: 0.909 | R3: 0.909 | S3: 0.909 | T3: 0.909 | U3: 0.909 | V3: 0.909 | W3: 0.909 | X3: 0.909 | Y3: 0.909
A4: Summer | B4: 0.909 | C4: 0.909 | D4: 0.909 | E4: 0.909 | F4: 0.909 | G4: 0.909 | H4: 0.909 | I4: 0.909 | J4: 0.909 | K4: 0.909 | L4: 0.909 | M4: 0.909 | N4: 0.909 | O4: 0.909 | P4: 0.909 | Q4: 0.909 | R4: 0.909 | S4: 0.909 | T4: 0.909 | U4: 0.909 | V4: 0.909 | W4: 0.909 | X4: 0.909 | Y4: 0.909
A5: Fall | B5: 0.909 | C5: 0.909 | D5: 0.909 | E5: 0.909 | F5: 0.909 | G5: 0.909 | H5: 0.909 | I5: 0.909 | J5: 0.909 | K5: 0.909 | L5: 0.909 | M5: 0.909 | N5: 0.909 | O5: 0.909 | P5: 0.909 | Q5: 0.909 | R5: 0.909 | S5: 0.909 | T5: 0.909 | U5: 0.909 | V5: 0.909 | W5: 0.909 | X5: 0.909 | Y5: 0.909
A6: Summer Peak | B6: 0.909 | C6: 0.909 | D6: 0.909 | E6: 0.909 | F6: 0.909 | G6: 0.909 | H6: 0.909 | I6: 0.909 | J6: 0.909 | K6: 0.909 | L6: 0.909 | M6: 0.909 | N6: 0.909 | O6: 0.909 | P6: 0.909 | Q6: 0.909 | R6: 0.909 | S6: 0.909 | T6: 0.909 | U6: 0.909 | V6: 0.909 | W6: 0.909 | X6: 0.909 | Y6: 0.909
A7: Winter Peak | B7: 0.909 | C7: 0.909 | D7: 0.909 | E7: 0.909 | F7: 0.909 | G7: 0.909 | H7: 0.909 | I7: 0.909 | J7: 0.909 | K7: 0.909 | L7: 0.909 | M7: 0.909 | N7: 0.909 | O7: 0.909 | P7: 0.909 | Q7: 0.909 | R7: 0.909 | S7: 0.909 | T7: 0.909 | U7: 0.909 | V7: 0.909 | W7: 0.909 | X7: 0.909 | Y7: 0.909

Sheet SYSHECF-hydro
A1: hydro | B1: Hour0 | C1: Hour1 | D1: Hour2 | E1: Hour3 | F1: Hour4 | G1: Hour5 | H1: Hour6 | I1: Hour7 | J1: Hour8 | K1: Hour9 | L1: Hour10 | M1: Hour11 | N1: Hour12 | O1: Hour13 | P1: Hour14 | Q1: Hour15 | R1: Hour16 | S1: Hour17 | T1: Hour18 | U1: Hour19 | V1: Hour20 | W1: Hour21 | X1: Hour22 | Y1: Hour23
A2: Winter | B2: 0.24004597 | C2: 0.22957126 | D2: 0.23411837 | E2: 0.23407039 | F2: 0.26363206 | G2: 0.34876007 | H2: 0.38301278 | I2: 0.37615831 | J2: 0.35925658 | K2: 0.39309057 | L2: 0.4753093 | M2: 0.50352537 | N2: 0.44978224 | O2: 0.42750903 | P2: 0.43257737 | Q2: 0.48296633 | R2: 0.48059136 | S2: 0.41038267 | T2: 0.52664257 | U2: 0.49252943 | V2: 0.44680317 | W2: 0.32883129 | X2: 0.24388648 | Y2: 0.23839942
A3: Spring | B3: 0.25985139 | C3: 0.24805398 | D3: 0.24805398 | E3: 0.24805398 | F3: 0.26496839 | G3: 0.28737163 | H3: 0.29905072 | I3: 0.34021065 | J3: 0.39162148 | K3: 0.47014269 | L3: 0.55435132 | M3: 0.5649318 | N3: 0.58834069 | O3: 0.63417395 | P3: 0.63844587 | Q3: 0.77513859 | R3: 0.76672576 | S3: 0.68499322 | T3: 0.87178267 | U3: 0.85945286 | V3: 0.57502213 | W3: 0.43882378 | X3: 0.33720637 | Y3: 0.27521083
A4: Summer | B4: 0.24986188 | C4: 0.24107614 | D4: 0.24619215 | E4: 0.25073381 | F4: 0.26507153 | G4: 0.31999804 | H4: 0.3502752 | I4: 0.40374974 | J4: 0.38462014 | K4: 0.45238312 | L4: 0.51184371 | M4: 0.509226 | N4: 0.5205233 | O4: 0.50213485 | P4: 0.51582051 | Q4: 0.64932774 | R4: 0.7645792 | S4: 0.67374773 | T4: 0.74657175 | U4: 0.74903213 | V4: 0.65420112 | W4: 0.49742448 | X4: 0.31492942 | Y4: 0.27209065
A5: Fall | B5: 0.24093041 | C5: 0.24093041 | D5: 0.23439889 | E5: 0.23087531 | F5: 0.30348857 | G5: 0.34546902 | H5: 0.37611902 | I5: 0.39148527 | J5: 0.33890313 | K5: 0.42281591 | L5: 0.48215645 | M5: 0.54777755 | N5: 0.58504156 | O5: 0.57052785 | P5: 0.61918764 | Q5: 0.75197678 | R5: 0.82934086 | S5: 0.69890306 | T5: 0.86534669 | U5: 0.76238595 | V5: 0.73600894 | W5: 0.51691786 | X5: 0.31345085 | Y5: 0.26839715
A6: Summer Peak | B6: 0.24452191 | C6: 0.24452191 | D6: 0.24452191 | E6: 0.24452191 | F6: 0.24452191 | G6: 0.24452191 | H6: 0.24452191 | I6: 0.26843631 | J6: 0.29235072 | K6: 0.3975102 | L6: 0.6035146 | M6: 0.72363365 | N6: 0.74741284 | O6: 0.78988842 | P6: 0.81992433 | Q6: 0.83672157 | R6: 0.85346965 | S6: 0.78127161 | T6: 0.94553182 | U6: 0.8511157 | V6: 0.68764219 | W6: 0.36478231 | X6: 0.26843631 | Y6: 0.24521027
A7: Winter Peak | B7: 0.21682348 | C7: 0.21682348 | D7: 0.21682348 | E7: 0.21682348 | F7: 0.21682348 | G7: 0.41313772 | H7: 0.5296704 | I7: 0.61550414 | J7: 0.56436086 | K7: 0.54571758 | L7: 0.69076686 | M7: 0.63224902 | N7: 0.45664683 | O7: 0.41313772 | P7: 0.44589733 | Q7: 0.79929217 | R7: 0.89275197 | S7: 0.7642772 | T7: 0.84070817 | U7: 0.86637716 | V7: 0.77139215 | W7: 0.60945197 | X7: 0.45147895 | Y7: 0.33437026

Sheet SYSHECF-pumped-hydro
A1: pumped hydro | B1: Hour0 | C1: Hour1 | D1: Hour2 | E1: Hour3 | F1: Hour4 | G1: Hour5 | H1: Hour6 | I1: Hour7 | J1: Hour8 | K1: Hour9 | L1: Hour10 | M1: Hour11 | N1: Hour12 | O1: Hour13 | P1: Hour14 | Q1: Hour15 | R1: Hour16 | S1: Hour17 | T1: Hour18 | U1: Hour19 | V1: Hour20 | W1: Hour21 | X1: Hour22 | Y1: Hour23
A2: Winter | B2: 0.050786458 | C2: 0.031782424 | D2: 0.011014966 | E2: 0.003603455 | F2: 0.001585094 | G2: 0.005556013 | H2: 0.040083994 | I2: 0.033930512 | J2: 0.01515099 | K2: 0.008908506 | L2: 0.001765122 | M2: 0.002506374 | N2: 0.001728191 | O2: 0.001112944 | P2: 0.000620595 | Q2: 0.000679352 | R2: 0.005715336 | S2: 0.12696127 | T2: 0.27549257 | U2: 0.26940648 | V2: 0.1932247 | W2: 0.12360632 | X2: 0.087957514 | Y2: 0.059442809
A3: Spring | B3: 0.13406067 | C3: 0.089046283 | D3: 0.043600997 | E3: 0.027674377 | F3: 0.022308315 | G3: 0.021573644 | H3: 0.030020309 | I3: 0.021768825 | J3: 0.016239916 | K3: 0.001941714 | L3: 0.00193389 | M3: 0.001626768 | N3: 0.001735835 | O3: 0.00338518 | P3: 0.006727515 | Q3: 0.010700968 | R3: 0.041978612 | S3: 0.14698738 | T3: 0.34077981 | U3: 0.37693714 | V3: 0.35940016 | W3: 0.20445418 | X3: 0.15712647 | Y3: 0.14249998
A4: Summer | B4: 0.088022871 | C4: 0.039338897 | D4: 0.016513904 | E4: 0.009312367 | F4: 0.005429409 | G4: 0.003830827 | H4: 0.003117602 | I4: 0.001265442 | J4: 0.000152477 | K4: 2.34725e-05 | L4: 0.00083549 | M4: 0.022594699 | N4: 0.1031461 | O4: 0.18901916 | P4: 0.26780428 | Q4: 0.35551079 | R4: 0.45477054 | S4: 0.53128118 | T4: 0.58424512 | U4: 0.58311646 | V4: 0.54844256 | W4: 0.32976281 | X4: 0.16117157 | Y4: 0.12689364
A5: Fall | B5: 0.087977237 | C5: 0.062358662 | D5: 0.024154758 | E5: 0.00620082 | F5: 0.002589261 | G5: 0.001716388 | H5: 0.002370386 | I5: 0.006349605 | J5: 0.007834535 | K5: 0.000337946 | L5: 0.000716554 | M5: 0.000897185 | N5: 0.004613099 | O5: 0.012083173 | P5: 0.021130801 | Q5: 0.035839561 | R5: 0.098139007 | S5: 0.31040897 | T5: 0.39753658 | U5: 0.41951473 | V5: 0.24537432 | W5: 0.15513013 | X5: 0.13819643 | Y5: 0.11573204
A6: Summer Peak | B6: 0.13153522 | C6: 0.040447158 | D6: 0 | E6: 0 | F6: 0 | G6: 0 | H6: 0 | I6: 0 | J6: 0 | K6: 0.000431894 | L6: 0.001847259 | M6: 0.083516036 | N6: 0.34411566 | O6: 0.45310738 | P6: 0.54916917 | Q6: 0.60615493 | R6: 0.63471806 | S6: 0.64233951 | T6: 0.63900057 | U6: 0.63262103 | V6: 0.72696998 | W6: 0.67088183 | X6: 0.19429258 | Y6: 0.14992802
A7: Winter Peak | B7: 0.004763846 | C7: 0.002657277 | D7: 0.001847259 | E7: 0.001847259 | F7: 0 | G7: 0.094888384 | H7: 0.19155291 | I7: 0.14615111 | J7: 0.004314606 | K7: 0.012963766 | L7: 0.003345012 | M7: 0.005248643 | N7: 0.003694517 | O7: 0 | P7: 0 | Q7: 0 | R7: 0.004889598 | S7: 0.20752172 | T7: 0.37460496 | U7: 0.38503981 | V7: 0.33367388 | W7: 0.19894108 | X7: 0.069298215 | Y7: 0.020110836

Sheet SYSHECF-onshore-wind
A1: onshore wind | B1: Hour0 | C1: Hour1 | D1: Hour2 | E1: Hour3 | F1: Hour4 | G1: Hour5 | H1: Hour6 | I1: Hour7 | J1: Hour8 | K1: Hour9 | L1: Hour10 | M1: Hour11 | N1: Hour12 | O1: Hour13 | P1: Hour14 | Q1: Hour15 | R1: Hour16 | S1: Hour17 | T1: Hour18 | U1: Hour19 | V1: Hour20 | W1: Hour21 | X1: Hour22 | Y1: Hour23
A2: Winter | B2: 0.56043109 | C2: 0.56510111 | D2: 0.57425438 | E2: 0.5909019 | F2: 0.61446771 | G2: 0.64187499 | H2: 0.64602974 | I2: 0.62406335 | J2: 0.60893955 | K2: 0.59907824 | L2: 0.59316154 | M2: 0.59285748 | N2: 0.59769732 | O2: 0.59693825 | P2: 0.60109793 | Q2: 0.61635596 | R2: 0.62806414 | S2: 0.62445811 | T2: 0.63102324 | U2: 0.63653425 | V2: 0.62899926 | W2: 0.60011135 | X2: 0.57110079 | Y2: 0.54300991
A3: Spring | B3: 0.57109742 | C3: 0.56976173 | D3: 0.54770073 | E3: 0.54595417 | F3: 0.57123825 | G3: 0.56244227 | H3: 0.47930918 | I3: 0.38703861 | J3: 0.31078253 | K3: 0.28378178 | L3: 0.26925711 | M3: 0.26507806 | N3: 0.2650656 | O3: 0.2693697 | P3: 0.27546357 | Q3: 0.2783946 | R3: 0.29208005 | S3: 0.31013857 | T3: 0.36236939 | U3: 0.42770902 | V3: 0.46720287 | W3: 0.47682186 | X3: 0.47198058 | Y3: 0.45127438
A4: Summer | B4: 0.39262439 | C4: 0.3881429 | D4: 0.39307467 | E4: 0.39675625 | F4: 0.40524492 | G4: 0.4002606 | H4: 0.37574937 | I4: 0.34597761 | J4: 0.31360466 | K4: 0.28119779 | L4: 0.26289441 | M4: 0.25818331 | N4: 0.26198026 | O4: 0.26736715 | P4: 0.2802719 | Q4: 0.30517451 | R4: 0.3342293 | S4: 0.36531181 | T4: 0.39807465 | U4: 0.43115376 | V4: 0.45261912 | W4: 0.46617393 | X4: 0.46974667 | Y4: 0.46814928
A5: Fall | B5: 0.27347367 | C5: 0.25785825 | D5: 0.24477172 | E5: 0.23732296 | F5: 0.23345087 | G5: 0.22852492 | H5: 0.20595827 | I5: 0.16943407 | J5: 0.14243021 | K5: 0.12141294 | L5: 0.11034018 | M5: 0.1053348 | N5: 0.10504885 | O5: 0.10713733 | P5: 0.11282209 | Q5: 0.12428793 | R5: 0.1440215 | S5: 0.15927898 | T5: 0.18167562 | U5: 0.21511695 | V5: 0.22628367 | W5: 0.23163212 | X5: 0.23359756 | Y5: 0.24386386
A6: Summer Peak | B6: 0.22370437 | C6: 0.21157252 | D6: 0.20753522 | E6: 0.21308991 | F6: 0.21678518 | G6: 0.18662718 | H6: 0.1306047 | I6: 0.078035775 | J6: 0.065697861 | K6: 0.065123176 | L6: 0.067371157 | M6: 0.071399395 | N6: 0.078708356 | O6: 0.085889811 | P6: 0.10079961 | Q6: 0.1112352 | R6: 0.12696805 | S6: 0.14998508 | T6: 0.19552121 | U6: 0.28306498 | V6: 0.34221952 | W6: 0.35606092 | X6: 0.36469692 | Y6: 0.36266588
A7: Winter Peak | B7: 0.28190405 | C7: 0.26808919 | D7: 0.25637779 | E7: 0.24849042 | F7: 0.23941532 | G7: 0.23204643 | H7: 0.22386393 | I7: 0.21263432 | J7: 0.18525666 | K7: 0.1409269 | L7: 0.107672 | M7: 0.087309858 | N7: 0.07886731 | O7: 0.078699799 | P7: 0.090226143 | Q7: 0.11760221 | R7: 0.16138396 | S7: 0.20003032 | T7: 0.2244199 | U7: 0.23571173 | V7: 0.23930763 | W7: 0.2383935 | X7: 0.23610658 | Y7: 0.21834564

Sheet SYSHECF-solar-pv
A1: solar pv | B1: Hour0 | C1: Hour1 | D1: Hour2 | E1: Hour3 | F1: Hour4 | G1: Hour5 | H1: Hour6 | I1: Hour7 | J1: Hour8 | K1: Hour9 | L1: Hour10 | M1: Hour11 | N1: Hour12 | O1: Hour13 | P1: Hour14 | Q1: Hour15 | R1: Hour16 | S1: Hour17 | T1: Hour18 | U1: Hour19 | V1: Hour20 | W1: Hour21 | X1: Hour22 | Y1: Hour23
A2: Winter | B2: 0 | C2: 0 | D2: 0 | E2: 0 | F2: 0 | G2: 0 | H2: 0 | I2: 0.0014423598 | J2: 0.069832569 | K2: 0.2594552 | L2: 0.34987392 | M2: 0.34061332 | N2: 0.33440749 | O2: 0.34889744 | P2: 0.36503689 | Q2: 0.34905464 | R2: 0.19409335 | S2: 0.032034181 | T2: 0 | U2: 0 | V2: 0 | W2: 0 | X2: 0 | Y2: 0
A3: Spring | B3: 0 | C3: 0 | D3: 0 | E3: 0 | F3: 0 | G3: 0.0039502688 | H3: 0.086575569 | I3: 0.26921236 | J3: 0.44420205 | K3: 0.54329088 | L3: 0.5735192 | M3: 0.58775844 | N3: 0.59217991 | O3: 0.59341995 | P3: 0.58886292 | Q3: 0.57862405 | R3: 0.53064766 | S3: 0.40361256 | T3: 0.17420582 | U3: 0.023232177 | V3: 0 | W3: 0 | X3: 0 | Y3: 0
A4: Summer | B4: 0 | C4: 0 | D4: 0 | E4: 0 | F4: 0 | G4: 0.013585482 | H4: 0.18161124 | I4: 0.4205672 | J4: 0.54922074 | K4: 0.61904624 | L4: 0.65300652 | M4: 0.66329815 | N4: 0.66880015 | O4: 0.67095502 | P4: 0.66822521 | Q4: 0.66581201 | R4: 0.63780216 | S4: 0.55201599 | T4: 0.35861328 | U4: 0.10805188 | V4: 7.7905552e-06 | W4: 0 | X4: 0 | Y4: 0
A5: Fall | B5: 0 | C5: 0 | D5: 0 | E5: 0 | F5: 0 | G5: 0 | H5: 0.0068217831 | I5: 0.15254501 | J5: 0.41013054 | K5: 0.51925285 | L5: 0.53578086 | M5: 0.5236124 | N5: 0.5165044 | O5: 0.5200324 | P5: 0.53209641 | Q5: 0.52744707 | R5: 0.434167 | S5: 0.21703261 | T5: 0.032732914 | U5: 0 | V5: 0 | W5: 0 | X5: 0 | Y5: 0
A6: Summer Peak | B6: 0 | C6: 0 | D6: 0 | E6: 0 | F6: 0 | G6: 0.012959121 | H6: 0.21296879 | I6: 0.46638738 | J6: 0.5926873 | K6: 0.71829318 | L6: 0.7319355 | M6: 0.73195719 | N6: 0.72286411 | O6: 0.7133698 | P6: 0.72836225 | Q6: 0.72629096 | R6: 0.68982649 | S6: 0.60290278 | T6: 0.39498208 | U6: 0.13197157 | V6: 0 | W6: 0 | X6: 0 | Y6: 0
A7: Winter Peak | B7: 0 | C7: 0 | D7: 0 | E7: 0 | F7: 0 | G7: 0 | H7: 0 | I7: 0.00065970421 | J7: 0.11044172 | K7: 0.39166097 | L7: 0.47192348 | M7: 0.42869026 | N7: 0.39782423 | O7: 0.40530691 | P7: 0.42302855 | Q7: 0.41471447 | R7: 0.27680014 | S7: 0.050367965 | T7: 0 | U7: 0 | V7: 0 | W7: 0 | X7: 0 | Y7: 0

Sheet SYSHECF-solar-thermal
A1: solar thermal | B1: Hour0 | C1: Hour1 | D1: Hour2 | E1: Hour3 | F1: Hour4 | G1: Hour5 | H1: Hour6 | I1: Hour7 | J1: Hour8 | K1: Hour9 | L1: Hour10 | M1: Hour11 | N1: Hour12 | O1: Hour13 | P1: Hour14 | Q1: Hour15 | R1: Hour16 | S1: Hour17 | T1: Hour18 | U1: Hour19 | V1: Hour20 | W1: Hour21 | X1: Hour22 | Y1: Hour23
A2: Winter | B2: 0 | C2: 0 | D2: 0 | E2: 0 | F2: 0 | G2: 0 | H2: 0 | I2: 0 | J2: 0 | K2: 0.085970261 | L2: 0.37963217 | M2: 0.49887313 | N2: 0.49723308 | O2: 0.48343923 | P2: 0.47115795 | Q2: 0.48278742 | R2: 0.49201858 | S2: 0.44649224 | T2: 0.2128181 | U2: 0.015243346 | V2: 0 | W2: 0 | X2: 0 | Y2: 0
A3: Spring | B3: 0 | C3: 0 | D3: 0 | E3: 0 | F3: 0 | G3: 0 | H3: 0 | I3: 0.0076376067 | J3: 0.18687045 | K3: 0.48014337 | L3: 0.63047092 | M3: 0.67382434 | N3: 0.67705712 | O3: 0.67418244 | P3: 0.66674031 | Q3: 0.66650048 | R3: 0.66682984 | S3: 0.64842041 | T3: 0.56803293 | U3: 0.30656379 | V3: 0.039289445 | W3: 0 | X3: 0 | Y3: 0
A4: Summer | B4: 0 | C4: 0 | D4: 0 | E4: 0 | F4: 0 | G4: 0 | H4: 0 | I4: 0.024164508 | J4: 0.27575698 | K4: 0.51488677 | L4: 0.59949295 | M4: 0.63012113 | N4: 0.63916783 | O4: 0.63841568 | P4: 0.63266768 | Q4: 0.62353065 | R4: 0.61337916 | S4: 0.59439288 | T4: 0.54206511 | U4: 0.40006062 | V4: 0.11961875 | W4: 2.6056188e-06 | X4: 0 | Y4: 0
A5: Fall | B5: 0 | C5: 0 | D5: 0 | E5: 0 | F5: 0 | G5: 0 | H5: 0 | I5: 0 | J5: 0.05499372 | K5: 0.36422206 | L5: 0.55216568 | M5: 0.58568962 | N5: 0.57825967 | O5: 0.56812185 | P5: 0.56341217 | Q5: 0.56827174 | R5: 0.56954888 | S5: 0.52877833 | T5: 0.35578626 | U5: 0.077412378 | V5: 3.2207156e-05 | W5: 0 | X5: 0 | Y5: 0
A6: Summer Peak | B6: 0 | C6: 0 | D6: 0 | E6: 0 | F6: 0 | G6: 0 | H6: 0 | I6: 0.0277316 | J6: 0.38083724 | K6: 0.62248753 | L6: 0.69230769 | M6: 0.71807466 | N6: 0.72479976 | O6: 0.72464863 | P6: 0.7232885 | Q6: 0.72570651 | R6: 0.723893 | S6: 0.71218075 | T6: 0.6731147 | U6: 0.55977029 | V6: 0.22117274 | W6: 0 | X6: 0 | Y6: 0
A7: Winter Peak | B7: 0 | C7: 0 | D7: 0 | E7: 0 | F7: 0 | G7: 0 | H7: 0 | I7: 0 | J7: 0 | K7: 0.002644703 | L7: 0.27588031 | M7: 0.35612815 | N7: 0.39020704 | O7: 0.41121354 | P7: 0.42511712 | Q7: 0.48556748 | R7: 0.52765604 | S7: 0.49304821 | T7: 0.19344114 | U7: 0 | V7: 0 | W7: 0 | X7: 0 | Y7: 0

Sheet SYSHECF-biomass
A1: biomass | B1: Hour0 | C1: Hour1 | D1: Hour2 | E1: Hour3 | F1: Hour4 | G1: Hour5 | H1: Hour6 | I1: Hour7 | J1: Hour8 | K1: Hour9 | L1: Hour10 | M1: Hour11 | N1: Hour12 | O1: Hour13 | P1: Hour14 | Q1: Hour15 | R1: Hour16 | S1: Hour17 | T1: Hour18 | U1: Hour19 | V1: Hour20 | W1: Hour21 | X1: Hour22 | Y1: Hour23
A2: Winter | B2: 0.50753643 | C2: 0.50716569 | D2: 0.50695974 | E2: 0.50693741 | F2: 0.50701954 | G2: 0.50711904 | H2: 0.50830296 | I2: 0.50991258 | J2: 0.50971021 | K2: 0.50884038 | L2: 0.50789969 | M2: 0.50771532 | N2: 0.50795528 | O2: 0.50793949 | P2: 0.50804257 | Q2: 0.50856188 | R2: 0.51244626 | S2: 0.51379107 | T2: 0.51450959 | U2: 0.51474755 | V2: 0.51462099 | W2: 0.51421245 | X2: 0.51354005 | Y2: 0.50885712
A3: Spring | B3: 0.50453843 | C3: 0.50391062 | D3: 0.50307986 | E3: 0.50244402 | F3: 0.50216683 | G3: 0.50225514 | H3: 0.50296008 | I3: 0.50413595 | J3: 0.50394405 | K3: 0.49776017 | L3: 0.49537882 | M3: 0.49514784 | N3: 0.49535329 | O3: 0.49593609 | P3: 0.49651441 | Q3: 0.49742336 | R3: 0.50244375 | S3: 0.5051927 | T3: 0.50971111 | U3: 0.51436639 | V3: 0.5144938 | W3: 0.51419674 | X3: 0.51268973 | Y3: 0.50625024
A4: Summer | B4: 0.51063809 | C4: 0.50969904 | D4: 0.5092943 | E4: 0.50892867 | F4: 0.5089295 | G4: 0.5089302 | H4: 0.50919826 | I4: 0.50988401 | J4: 0.50972645 | K4: 0.50940383 | L4: 0.51088903 | M4: 0.51165703 | N4: 0.51223143 | O4: 0.51256951 | P4: 0.51293569 | Q4: 0.51376479 | R4: 0.51420892 | S4: 0.51475172 | T4: 0.51530302 | U4: 0.51543037 | V4: 0.51546099 | W4: 0.51526558 | X4: 0.51451205 | Y4: 0.51184256
A5: Fall | B5: 0.50575733 | C5: 0.50527656 | D5: 0.50462526 | E5: 0.50455797 | F5: 0.50461454 | G5: 0.50493076 | H5: 0.50595524 | I5: 0.50678916 | J5: 0.50671889 | K5: 0.50743469 | L5: 0.50755479 | M5: 0.508455 | N5: 0.50883256 | O5: 0.50890839 | P5: 0.50928257 | Q5: 0.51180257 | R5: 0.5139885 | S5: 0.51466381 | T5: 0.51504891 | U5: 0.51499789 | V5: 0.51491353 | W5: 0.51361253 | X5: 0.51135634 | Y5: 0.50686221
A6: Summer Peak | B6: 0.51335031 | C6: 0.51335031 | D6: 0.51335031 | E6: 0.51335031 | F6: 0.51335031 | G6: 0.51335031 | H6: 0.51335031 | I6: 0.51427058 | J6: 0.51427058 | K6: 0.51462173 | L6: 0.51552988 | M6: 0.51552988 | N6: 0.51552988 | O6: 0.51552988 | P6: 0.51552988 | Q6: 0.51552988 | R6: 0.51552988 | S6: 0.51552988 | T6: 0.51552988 | U6: 0.51552988 | V6: 0.51552988 | W6: 0.51552988 | X6: 0.51552988 | Y6: 0.51519084
A7: Winter Peak | B7: 0.51427058 | C7: 0.51427058 | D7: 0.51427058 | E7: 0.51427058 | F7: 0.51427058 | G7: 0.51427058 | H7: 0.51427058 | I7: 0.51427058 | J7: 0.51427058 | K7: 0.51427058 | L7: 0.51427058 | M7: 0.51427058 | N7: 0.51427058 | O7: 0.51427058 | P7: 0.51427058 | Q7: 0.51427058 | R7: 0.51462173 | S7: 0.51552988 | T7: 0.51552988 | U7: 0.51552988 | V7: 0.51552988 | W7: 0.51552988 | X7: 0.51552988 | Y7: 0.50758655

Sheet SYSHECF-geothermal
A1: geothermal | B1: Hour0 | C1: Hour1 | D1: Hour2 | E1: Hour3 | F1: Hour4 | G1: Hour5 | H1: Hour6 | I1: Hour7 | J1: Hour8 | K1: Hour9 | L1: Hour10 | M1: Hour11 | N1: Hour12 | O1: Hour13 | P1: Hour14 | Q1: Hour15 | R1: Hour16 | S1: Hour17 | T1: Hour18 | U1: Hour19 | V1: Hour20 | W1: Hour21 | X1: Hour22 | Y1: Hour23
A2: Winter | B2: 0.6595 | C2: 0.6595 | D2: 0.6595 | E2: 0.6595 | F2: 0.6595 | G2: 0.6595 | H2: 0.6595 | I2: 0.6595 | J2: 0.6595 | K2: 0.6595 | L2: 0.6595 | M2: 0.6595 | N2: 0.6595 | O2: 0.6595 | P2: 0.6595 | Q2: 0.6595 | R2: 0.6595 | S2: 0.6595 | T2: 0.6595 | U2: 0.6595 | V2: 0.6595 | W2: 0.6595 | X2: 0.6595 | Y2: 0.6595
A3: Spring | B3: 0.6595 | C3: 0.6595 | D3: 0.6595 | E3: 0.6595 | F3: 0.6595 | G3: 0.6595 | H3: 0.6595 | I3: 0.6595 | J3: 0.6595 | K3: 0.6595 | L3: 0.6595 | M3: 0.6595 | N3: 0.6595 | O3: 0.6595 | P3: 0.6595 | Q3: 0.6595 | R3: 0.6595 | S3: 0.6595 | T3: 0.6595 | U3: 0.6595 | V3: 0.6595 | W3: 0.6595 | X3: 0.6595 | Y3: 0.6595
A4: Summer | B4: 0.6595 | C4: 0.6595 | D4: 0.6595 | E4: 0.6595 | F4: 0.6595 | G4: 0.6595 | H4: 0.6595 | I4: 0.6595 | J4: 0.6595 | K4: 0.6595 | L4: 0.6595 | M4: 0.6595 | N4: 0.6595 | O4: 0.6595 | P4: 0.6595 | Q4: 0.6595 | R4: 0.6595 | S4: 0.6595 | T4: 0.6595 | U4: 0.6595 | V4: 0.6595 | W4: 0.6595 | X4: 0.6595 | Y4: 0.6595
A5: Fall | B5: 0.6595 | C5: 0.6595 | D5: 0.6595 | E5: 0.6595 | F5: 0.6595 | G5: 0.6595 | H5: 0.6595 | I5: 0.6595 | J5: 0.6595 | K5: 0.6595 | L5: 0.6595 | M5: 0.6595 | N5: 0.6595 | O5: 0.6595 | P5: 0.6595 | Q5: 0.6595 | R5: 0.6595 | S5: 0.6595 | T5: 0.6595 | U5: 0.6595 | V5: 0.6595 | W5: 0.6595 | X5: 0.6595 | Y5: 0.6595
A6: Summer Peak | B6: 0.6595 | C6: 0.6595 | D6: 0.6595 | E6: 0.6595 | F6: 0.6595 | G6: 0.6595 | H6: 0.6595 | I6: 0.6595 | J6: 0.6595 | K6: 0.6595 | L6: 0.6595 | M6: 0.6595 | N6: 0.6595 | O6: 0.6595 | P6: 0.6595 | Q6: 0.6595 | R6: 0.6595 | S6: 0.6595 | T6: 0.6595 | U6: 0.6595 | V6: 0.6595 | W6: 0.6595 | X6: 0.6595 | Y6: 0.6595
A7: Winter Peak | B7: 0.6595 | C7: 0.6595 | D7: 0.6595 | E7: 0.6595 | F7: 0.6595 | G7: 0.6595 | H7: 0.6595 | I7: 0.6595 | J7: 0.6595 | K7: 0.6595 | L7: 0.6595 | M7: 0.6595 | N7: 0.6595 | O7: 0.6595 | P7: 0.6595 | Q7: 0.6595 | R7: 0.6595 | S7: 0.6595 | T7: 0.6595 | U7: 0.6595 | V7: 0.6595 | W7: 0.6595 | X7: 0.6595 | Y7: 0.6595

Sheet SYSHECF-petroleum
A1: petroleum | B1: Hour0 | C1: Hour1 | D1: Hour2 | E1: Hour3 | F1: Hour4 | G1: Hour5 | H1: Hour6 | I1: Hour7 | J1: Hour8 | K1: Hour9 | L1: Hour10 | M1: Hour11 | N1: Hour12 | O1: Hour13 | P1: Hour14 | Q1: Hour15 | R1: Hour16 | S1: Hour17 | T1: Hour18 | U1: Hour19 | V1: Hour20 | W1: Hour21 | X1: Hour22 | Y1: Hour23
A2: Winter | B2: ='SYSHECF-natural-gas-peaker'!B2 -> 0.0022534594 | C2: ='SYSHECF-natural-gas-peaker'!C2 -> 0.0022534594 | D2: ='SYSHECF-natural-gas-peaker'!D2 -> 0.0022534594 | E2: ='SYSHECF-natural-gas-peaker'!E2 -> 0.0022534594 | F2: ='SYSHECF-natural-gas-peaker'!F2 -> 0.0022534594 | G2: ='SYSHECF-natural-gas-peaker'!G2 -> 0.0022534594 | H2: ='SYSHECF-natural-gas-peaker'!H2 -> 0.0022534594 | I2: ='SYSHECF-natural-gas-peaker'!I2 -> 0.0022534594 | ... Y2: ='SYSHECF-natural-gas-peaker'!Y2 -> 0.0022534594
A3: Spring | B3: ='SYSHECF-natural-gas-peaker'!B3 -> 0.64583263 | C3: ='SYSHECF-natural-gas-peaker'!C3 -> 0.64583263 | D3: ='SYSHECF-natural-gas-peaker'!D3 -> 0.64583263 | E3: ='SYSHECF-natural-gas-peaker'!E3 -> 0.64583263 | F3: ='SYSHECF-natural-gas-peaker'!F3 -> 0.64583263 | G3: ='SYSHECF-natural-gas-peaker'!G3 -> 0.64583263 | H3: ='SYSHECF-natural-gas-peaker'!H3 -> 0.64583263 | I3: ='SYSHECF-natural-gas-peaker'!I3 -> 0.64583263 | ... Y3: ='SYSHECF-natural-gas-peaker'!Y3 -> 0.49593065
A4: Summer | B4: ='SYSHECF-natural-gas-peaker'!B4 -> 0.23276761 | C4: ='SYSHECF-natural-gas-peaker'!C4 -> 0.23276761 | D4: ='SYSHECF-natural-gas-peaker'!D4 -> 0.23276761 | E4: ='SYSHECF-natural-gas-peaker'!E4 -> 0.23276761 | F4: ='SYSHECF-natural-gas-peaker'!F4 -> 0.23276761 | G4: ='SYSHECF-natural-gas-peaker'!G4 -> 0.23276761 | H4: ='SYSHECF-natural-gas-peaker'!H4 -> 0.23276761 | I4: ='SYSHECF-natural-gas-peaker'!I4 -> 0.23276761 | ... Y4: ='SYSHECF-natural-gas-peaker'!Y4 -> 0.17880023
A5: Fall | B5: ='SYSHECF-natural-gas-peaker'!B5 -> 0.62619414 | C5: ='SYSHECF-natural-gas-peaker'!C5 -> 0.62619414 | D5: ='SYSHECF-natural-gas-peaker'!D5 -> 0.62619414 | E5: ='SYSHECF-natural-gas-peaker'!E5 -> 0.62619414 | F5: ='SYSHECF-natural-gas-peaker'!F5 -> 0.62619414 | G5: ='SYSHECF-natural-gas-peaker'!G5 -> 0.62619414 | H5: ='SYSHECF-natural-gas-peaker'!H5 -> 0.62619414 | I5: ='SYSHECF-natural-gas-peaker'!I5 -> 0.62619414 | ... Y5: ='SYSHECF-natural-gas-peaker'!Y5 -> 0.82960592
A6: Summer Peak | B6: ='SYSHECF-natural-gas-peaker'!B6 -> 1 | C6: ='SYSHECF-natural-gas-peaker'!C6 -> 1 | D6: ='SYSHECF-natural-gas-peaker'!D6 -> 1 | E6: ='SYSHECF-natural-gas-peaker'!E6 -> 1 | F6: ='SYSHECF-natural-gas-peaker'!F6 -> 1 | G6: ='SYSHECF-natural-gas-peaker'!G6 -> 1 | H6: ='SYSHECF-natural-gas-peaker'!H6 -> 1 | I6: ='SYSHECF-natural-gas-peaker'!I6 -> 1 | ... Y6: ='SYSHECF-natural-gas-peaker'!Y6 -> 1
A7: Winter Peak | B7: ='SYSHECF-natural-gas-peaker'!B7 -> 0.0022534594 | C7: ='SYSHECF-natural-gas-peaker'!C7 -> 0.0022534594 | D7: ='SYSHECF-natural-gas-peaker'!D7 -> 0.0022534594 | E7: ='SYSHECF-natural-gas-peaker'!E7 -> 0.0022534594 | F7: ='SYSHECF-natural-gas-peaker'!F7 -> 0.0022534594 | G7: ='SYSHECF-natural-gas-peaker'!G7 -> 0.0022534594 | H7: ='SYSHECF-natural-gas-peaker'!H7 -> 0.0022534594 | I7: ='SYSHECF-natural-gas-peaker'!I7 -> 0.0022534594 | ... Y7: ='SYSHECF-natural-gas-peaker'!Y7 -> 0.0022534594
A9: Mirrors natural gas peaker cell-by-cell (decision 2026-08-26, matching the eps-us hydrogen-CT convention). Derivation: SYSHECF-natural-gas-peaker tab; level basis: Peaker Targets tab.

Sheet SYSHECF-natural-gas-peaker
A1: natural gas peaker | B1: Hour0 | C1: Hour1 | D1: Hour2 | E1: Hour3 | F1: Hour4 | G1: Hour5 | H1: Hour6 | I1: Hour7 | J1: Hour8 | K1: Hour9 | L1: Hour10 | M1: Hour11 | N1: Hour12 | O1: Hour13 | P1: Hour14 | Q1: Hour15 | R1: Hour16 | S1: Hour17 | T1: Hour18 | U1: Hour19 | V1: Hour20 | W1: Hour21 | X1: Hour22 | Y1: Hour23 | Z1: Row sum x days (for annual CF) | AA1: Unsaturated hours x days (water-fill denominator) | AC1: Calibration to observed fleet CF (see Peaker Targets)
A2: Winter | B2: =MIN('Peaker Keys'!$B$10,B60+$AD$22) -> 0.0022534594 | C2: =MIN('Peaker Keys'!$B$10,C60+$AD$22) -> 0.0022534594 | D2: =MIN('Peaker Keys'!$B$10,D60+$AD$22) -> 0.0022534594 | E2: =MIN('Peaker Keys'!$B$10,E60+$AD$22) -> 0.0022534594 | F2: =MIN('Peaker Keys'!$B$10,F60+$AD$22) -> 0.0022534594 | G2: =MIN('Peaker Keys'!$B$10,G60+$AD$22) -> 0.0022534594 | H2: =MIN('Peaker Keys'!$B$10,H60+$AD$22) -> 0.0022534594 | I2: =MIN('Peaker Keys'!$B$10,I60+$AD$22) -> 0.0022534594 | ... Y2: =MIN('Peaker Keys'!$B$10,Y60+$AD$22) -> 0.0022534594 | Z2: =SUM($B2:$Y2)*INDEX(Clustering!$E$6:$E$11,MATCH($A2,Clustering!$D$6:$D$11,0)) -> 5.0297215 | AC2: Target bid CF (from Peaker Targets) | AD2: ='Peaker Targets'!$B$14 -> 0.42885422
A3: Spring | B3: =MIN('Peaker Keys'!$B$10,B61+$AD$22) -> 0.64583263 | C3: =MIN('Peaker Keys'!$B$10,C61+$AD$22) -> 0.64583263 | D3: =MIN('Peaker Keys'!$B$10,D61+$AD$22) -> 0.64583263 | E3: =MIN('Peaker Keys'!$B$10,E61+$AD$22) -> 0.64583263 | F3: =MIN('Peaker Keys'!$B$10,F61+$AD$22) -> 0.64583263 | G3: =MIN('Peaker Keys'!$B$10,G61+$AD$22) -> 0.64583263 | H3: =MIN('Peaker Keys'!$B$10,H61+$AD$22) -> 0.64583263 | I3: =MIN('Peaker Keys'!$B$10,I61+$AD$22) -> 0.64583263 | ... Y3: =MIN('Peaker Keys'!$B$10,Y61+$AD$22) -> 0.49593065 | Z3: =SUM($B3:$Y3)*INDEX(Clustering!$E$6:$E$11,MATCH($A3,Clustering!$D$6:$D$11,0)) -> 822.70318 | AC3: Annual CF, block 0 | AD3: =SUM($Z$11:$Z$16)/'Peaker Keys'!$B$5 -> 0.038266172
A4: Summer | B4: =MIN('Peaker Keys'!$B$10,B62+$AD$22) -> 0.23276761 | C4: =MIN('Peaker Keys'!$B$10,C62+$AD$22) -> 0.23276761 | D4: =MIN('Peaker Keys'!$B$10,D62+$AD$22) -> 0.23276761 | E4: =MIN('Peaker Keys'!$B$10,E62+$AD$22) -> 0.23276761 | F4: =MIN('Peaker Keys'!$B$10,F62+$AD$22) -> 0.23276761 | G4: =MIN('Peaker Keys'!$B$10,G62+$AD$22) -> 0.23276761 | H4: =MIN('Peaker Keys'!$B$10,H62+$AD$22) -> 0.23276761 | I4: =MIN('Peaker Keys'!$B$10,I62+$AD$22) -> 0.23276761 | ... Y4: =MIN('Peaker Keys'!$B$10,Y62+$AD$22) -> 0.17880023 | Z4: =SUM($B4:$Y4)*INDEX(Clustering!$E$6:$E$11,MATCH($A4,Clustering!$D$6:$D$11,0)) -> 976.07356 | AC4: Scale, multiplicative pass 1 | AD4: =IF($AD$3>0,$AD$2/$AD$3,0) -> 11.207137
A5: Fall | B5: =MIN('Peaker Keys'!$B$10,B63+$AD$22) -> 0.62619414 | C5: =MIN('Peaker Keys'!$B$10,C63+$AD$22) -> 0.62619414 | D5: =MIN('Peaker Keys'!$B$10,D63+$AD$22) -> 0.62619414 | E5: =MIN('Peaker Keys'!$B$10,E63+$AD$22) -> 0.62619414 | F5: =MIN('Peaker Keys'!$B$10,F63+$AD$22) -> 0.62619414 | G5: =MIN('Peaker Keys'!$B$10,G63+$AD$22) -> 0.62619414 | H5: =MIN('Peaker Keys'!$B$10,H63+$AD$22) -> 0.62619414 | I5: =MIN('Peaker Keys'!$B$10,I63+$AD$22) -> 0.62619414 | ... Y5: =MIN('Peaker Keys'!$B$10,Y63+$AD$22) -> 0.82960592 | Z5: =SUM($B5:$Y5)*INDEX(Clustering!$E$6:$E$11,MATCH($A5,Clustering!$D$6:$D$11,0)) -> 1159.6044 | AC5: Achieved CF, multiplicative pass 1 | AD5: =SUM($Z$20:$Z$25)/'Peaker Keys'!$B$5 -> 0.30871564
A6: Summer Peak | B6: =MIN('Peaker Keys'!$B$10,B64+$AD$22) -> 1 | C6: =MIN('Peaker Keys'!$B$10,C64+$AD$22) -> 1 | D6: =MIN('Peaker Keys'!$B$10,D64+$AD$22) -> 1 | E6: =MIN('Peaker Keys'!$B$10,E64+$AD$22) -> 1 | F6: =MIN('Peaker Keys'!$B$10,F64+$AD$22) -> 1 | G6: =MIN('Peaker Keys'!$B$10,G64+$AD$22) -> 1 | H6: =MIN('Peaker Keys'!$B$10,H64+$AD$22) -> 1 | I6: =MIN('Peaker Keys'!$B$10,I64+$AD$22) -> 1 | ... Y6: =MIN('Peaker Keys'!$B$10,Y64+$AD$22) -> 1 | Z6: =SUM($B6:$Y6)*INDEX(Clustering!$E$6:$E$11,MATCH($A6,Clustering!$D$6:$D$11,0)) -> 792 | AC6: Scale, multiplicative pass 2 | AD6: =IF($AD$5>0,$AD$4*$AD$2/$AD$5,0) -> 15.568462
A7: Winter Peak | B7: =MIN('Peaker Keys'!$B$10,B65+$AD$22) -> 0.0022534594 | C7: =MIN('Peaker Keys'!$B$10,C65+$AD$22) -> 0.0022534594 | D7: =MIN('Peaker Keys'!$B$10,D65+$AD$22) -> 0.0022534594 | E7: =MIN('Peaker Keys'!$B$10,E65+$AD$22) -> 0.0022534594 | F7: =MIN('Peaker Keys'!$B$10,F65+$AD$22) -> 0.0022534594 | G7: =MIN('Peaker Keys'!$B$10,G65+$AD$22) -> 0.0022534594 | H7: =MIN('Peaker Keys'!$B$10,H65+$AD$22) -> 0.0022534594 | I7: =MIN('Peaker Keys'!$B$10,I65+$AD$22) -> 0.0022534594 | ... Y7: =MIN('Peaker Keys'!$B$10,Y65+$AD$22) -> 0.0022534594 | Z7: =SUM($B7:$Y7)*INDEX(Clustering!$E$6:$E$11,MATCH($A7,Clustering!$D$6:$D$11,0)) -> 1.3520757 | AC7: Achieved CF, multiplicative pass 2 | AD7: =SUM($Z$28:$Z$33)/'Peaker Keys'!$B$5 -> 0.37622219
AC8: Scale, multiplicative pass 3 | AD8: =IF($AD$7>0,$AD$6*$AD$2/$AD$7,0) -> 17.74643
A9: Block 0: raw Cambium slice x hour shape (AVERAGEIFS of "CF USED" on Cambium Peaker Source; uncalibrated) | AC9: Achieved CF, multiplicative pass 3 | AD9: =SUM($Z$36:$Z$41)/'Peaker Keys'!$B$5 -> 0.40544681
A10: hour -> | B10: 0 | C10: 1 | D10: 2 | E10: 3 | F10: 4 | G10: 5 | H10: 6 | I10: 7 | J10: 8 | K10: 9 | L10: 10 | M10: 11 | N10: 12 | O10: 13 | P10: 14 | Q10: 15 | R10: 16 | S10: 17 | T10: 18 | U10: 19 | V10: 20 | W10: 21 | X10: 22 | Y10: 23 | AC10: Scale, multiplicative pass 4 | AD10: =IF($AD$9>0,$AD$8*$AD$2/$AD$9,0) -> 18.770973
A11: Winter | B11: =IFERROR(AVERAGEIFS('Cambium Peaker Source'!$J$7:$J$8766,'Cambium Peaker Source'!$G$7:$G$8766,$A11,'Cambium Peaker Source'!$F$7:$F$8766,B$10),0) -> 0 | C11: =IFERROR(AVERAGEIFS('Cambium Peaker Source'!$J$7:$J$8766,'Cambium Peaker Source'!$G$7:$G$8766,$A11,'Cambium Peaker Source'!$F$7:$F$8766,C$10),0) -> 0 | D11: =IFERROR(AVERAGEIFS('Cambium Peaker Source'!$J$7:$J$8766,'Cambium Peaker Source'!$G$7:$G$8766,$A11,'Cambium Peaker Source'!$F$7:$F$8766,D$10),0) -> 0 | E11: =IFERROR(AVERAGEIFS('Cambium Peaker Source'!$J$7:$J$8766,'Cambium Peaker Source'!$G$7:$G$8766,$A11,'Cambium Peaker Source'!$F$7:$F$8766,E$10),0) -> 0 | F11: =IFERROR(AVERAGEIFS('Cambium Peaker Source'!$J$7:$J$8766,'Cambium Peaker Source'!$G$7:$G$8766,$A11,'Cambium Peaker Source'!$F$7:$F$8766,F$10),0) -> 0 | G11: =IFERROR(AVERAGEIFS('Cambium Peaker Source'!$J$7:$J$8766,'Cambium Peaker Source'!$G$7:$G$8766,$A11,'Cambium Peaker Source'!$F$7:$F$8766,G$10),0) -> 0 | H11: =IFERROR(AVERAGEIFS('Cambium Peaker Source'!$J$7:$J$8766,'Cambium Peaker Source'!$G$7:$G$8766,$A11,'Cambium Peaker Source'!$F$7:$F$8766,H$10),0) -> 0 | I11: =IFERROR(AVERAGEIFS('Cambium Peaker Source'!$J$7:$J$8766,'Cambium Peaker Source'!$G$7:$G$8766,$A11,'Cambium Peaker Source'!$F$7:$F$8766,I$10),0) -> 0 | ... Y11: =IFERROR(AVERAGEIFS('Cambium Peaker Source'!$J$7:$J$8766,'Cambium Peaker Source'!$G$7:$G$8766,$A11,'Cambium Peaker Source'!$F$7:$F$8766,Y$10),0) -> 0 | Z11: =SUM($B11:$Y11)*INDEX(Clustering!$E$6:$E$11,MATCH($A11,Clustering!$D$6:$D$11,0)) -> 0 | AC11: Achieved CF, multiplicative pass 4 | AD11: =SUM($Z$44:$Z$49)/'Peaker Keys'!$B$5 -> 0.41867823
A12: Spring | B12: =IFERROR(AVERAGEIFS('Cambium Peaker Source'!$J$7:$J$8766,'Cambium Peaker Source'!$G$7:$G$8766,$A12,'Cambium Peaker Source'!$F$7:$F$8766,B$10),0) -> 0.033131468 | C12: =IFERROR(AVERAGEIFS('Cambium Peaker Source'!$J$7:$J$8766,'Cambium Peaker Source'!$G$7:$G$8766,$A12,'Cambium Peaker Source'!$F$7:$F$8766,C$10),0) -> 0.033131468 | D12: =IFERROR(AVERAGEIFS('Cambium Peaker Source'!$J$7:$J$8766,'Cambium Peaker Source'!$G$7:$G$8766,$A12,'Cambium Peaker Source'!$F$7:$F$8766,D$10),0) -> 0.033131468 | E12: =IFERROR(AVERAGEIFS('Cambium Peaker Source'!$J$7:$J$8766,'Cambium Peaker Source'!$G$7:$G$8766,$A12,'Cambium Peaker Source'!$F$7:$F$8766,E$10),0) -> 0.033131468 | F12: =IFERROR(AVERAGEIFS('Cambium Peaker Source'!$J$7:$J$8766,'Cambium Peaker Source'!$G$7:$G$8766,$A12,'Cambium Peaker Source'!$F$7:$F$8766,F$10),0) -> 0.033131468 | G12: =IFERROR(AVERAGEIFS('Cambium Peaker Source'!$J$7:$J$8766,'Cambium Peaker Source'!$G$7:$G$8766,$A12,'Cambium Peaker Source'!$F$7:$F$8766,G$10),0) -> 0.033131468 | H12: =IFERROR(AVERAGEIFS('Cambium Peaker Source'!$J$7:$J$8766,'Cambium Peaker Source'!$G$7:$G$8766,$A12,'Cambium Peaker Source'!$F$7:$F$8766,H$10),0) -> 0.033131468 | I12: =IFERROR(AVERAGEIFS('Cambium Peaker Source'!$J$7:$J$8766,'Cambium Peaker Source'!$G$7:$G$8766,$A12,'Cambium Peaker Source'!$F$7:$F$8766,I$10),0) -> 0.033131468 | ... Y12: =IFERROR(AVERAGEIFS('Cambium Peaker Source'!$J$7:$J$8766,'Cambium Peaker Source'!$G$7:$G$8766,$A12,'Cambium Peaker Source'!$F$7:$F$8766,Y$10),0) -> 0.025414511 | Z12: =SUM($B12:$Y12)*INDEX(Clustering!$E$6:$E$11,MATCH($A12,Clustering!$D$6:$D$11,0)) -> 44.167686 | AC12: Scale, multiplicative pass 5 | AD12: =IF($AD$11>0,$AD$10*$AD$2/$AD$11,0) -> 19.227202
A13: Summer | B13: =IFERROR(AVERAGEIFS('Cambium Peaker Source'!$J$7:$J$8766,'Cambium Peaker Source'!$G$7:$G$8766,$A13,'Cambium Peaker Source'!$F$7:$F$8766,B$10),0) -> 0.011866873 | C13: =IFERROR(AVERAGEIFS('Cambium Peaker Source'!$J$7:$J$8766,'Cambium Peaker Source'!$G$7:$G$8766,$A13,'Cambium Peaker Source'!$F$7:$F$8766,C$10),0) -> 0.011866873 | D13: =IFERROR(AVERAGEIFS('Cambium Peaker Source'!$J$7:$J$8766,'Cambium Peaker Source'!$G$7:$G$8766,$A13,'Cambium Peaker Source'!$F$7:$F$8766,D$10),0) -> 0.011866873 | E13: =IFERROR(AVERAGEIFS('Cambium Peaker Source'!$J$7:$J$8766,'Cambium Peaker Source'!$G$7:$G$8766,$A13,'Cambium Peaker Source'!$F$7:$F$8766,E$10),0) -> 0.011866873 | F13: =IFERROR(AVERAGEIFS('Cambium Peaker Source'!$J$7:$J$8766,'Cambium Peaker Source'!$G$7:$G$8766,$A13,'Cambium Peaker Source'!$F$7:$F$8766,F$10),0) -> 0.011866873 | G13: =IFERROR(AVERAGEIFS('Cambium Peaker Source'!$J$7:$J$8766,'Cambium Peaker Source'!$G$7:$G$8766,$A13,'Cambium Peaker Source'!$F$7:$F$8766,G$10),0) -> 0.011866873 | H13: =IFERROR(AVERAGEIFS('Cambium Peaker Source'!$J$7:$J$8766,'Cambium Peaker Source'!$G$7:$G$8766,$A13,'Cambium Peaker Source'!$F$7:$F$8766,H$10),0) -> 0.011866873 | I13: =IFERROR(AVERAGEIFS('Cambium Peaker Source'!$J$7:$J$8766,'Cambium Peaker Source'!$G$7:$G$8766,$A13,'Cambium Peaker Source'!$F$7:$F$8766,I$10),0) -> 0.011866873 | ... Y13: =IFERROR(AVERAGEIFS('Cambium Peaker Source'!$J$7:$J$8766,'Cambium Peaker Source'!$G$7:$G$8766,$A13,'Cambium Peaker Source'!$F$7:$F$8766,Y$10),0) -> 0.0090886312 | Z13: =SUM($B13:$Y13)*INDEX(Clustering!$E$6:$E$11,MATCH($A13,Clustering!$D$6:$D$11,0)) -> 49.950376 | AC13: Achieved CF, multiplicative pass 5 | AD13: =SUM($Z$52:$Z$57)/'Peaker Keys'!$B$5 -> 0.42448708
A14: Fall | B14: =IFERROR(AVERAGEIFS('Cambium Peaker Source'!$J$7:$J$8766,'Cambium Peaker Source'!$G$7:$G$8766,$A14,'Cambium Peaker Source'!$F$7:$F$8766,B$10),0) -> 0.032120478 | C14: =IFERROR(AVERAGEIFS('Cambium Peaker Source'!$J$7:$J$8766,'Cambium Peaker Source'!$G$7:$G$8766,$A14,'Cambium Peaker Source'!$F$7:$F$8766,C$10),0) -> 0.032120478 | D14: =IFERROR(AVERAGEIFS('Cambium Peaker Source'!$J$7:$J$8766,'Cambium Peaker Source'!$G$7:$G$8766,$A14,'Cambium Peaker Source'!$F$7:$F$8766,D$10),0) -> 0.032120478 | E14: =IFERROR(AVERAGEIFS('Cambium Peaker Source'!$J$7:$J$8766,'Cambium Peaker Source'!$G$7:$G$8766,$A14,'Cambium Peaker Source'!$F$7:$F$8766,E$10),0) -> 0.032120478 | F14: =IFERROR(AVERAGEIFS('Cambium Peaker Source'!$J$7:$J$8766,'Cambium Peaker Source'!$G$7:$G$8766,$A14,'Cambium Peaker Source'!$F$7:$F$8766,F$10),0) -> 0.032120478 | G14: =IFERROR(AVERAGEIFS('Cambium Peaker Source'!$J$7:$J$8766,'Cambium Peaker Source'!$G$7:$G$8766,$A14,'Cambium Peaker Source'!$F$7:$F$8766,G$10),0) -> 0.032120478 | H14: =IFERROR(AVERAGEIFS('Cambium Peaker Source'!$J$7:$J$8766,'Cambium Peaker Source'!$G$7:$G$8766,$A14,'Cambium Peaker Source'!$F$7:$F$8766,H$10),0) -> 0.032120478 | I14: =IFERROR(AVERAGEIFS('Cambium Peaker Source'!$J$7:$J$8766,'Cambium Peaker Source'!$G$7:$G$8766,$A14,'Cambium Peaker Source'!$F$7:$F$8766,I$10),0) -> 0.032120478 | ... Y14: =IFERROR(AVERAGEIFS('Cambium Peaker Source'!$J$7:$J$8766,'Cambium Peaker Source'!$G$7:$G$8766,$A14,'Cambium Peaker Source'!$F$7:$F$8766,Y$10),0) -> 0.04259212 | Z14: =SUM($B14:$Y14)*INDEX(Clustering!$E$6:$E$11,MATCH($A14,Clustering!$D$6:$D$11,0)) -> 83.178504 | AC14: Scale, multiplicative pass 6 | AD14: =IF($AD$13>0,$AD$12*$AD$2/$AD$13,0) -> 19.425012
A15: Summer Peak | B15: =IFERROR(AVERAGEIFS('Cambium Peaker Source'!$J$7:$J$8766,'Cambium Peaker Source'!$G$7:$G$8766,$A15,'Cambium Peaker Source'!$F$7:$F$8766,B$10),0) -> 0.11250321 | C15: =IFERROR(AVERAGEIFS('Cambium Peaker Source'!$J$7:$J$8766,'Cambium Peaker Source'!$G$7:$G$8766,$A15,'Cambium Peaker Source'!$F$7:$F$8766,C$10),0) -> 0.11250321 | D15: =IFERROR(AVERAGEIFS('Cambium Peaker Source'!$J$7:$J$8766,'Cambium Peaker Source'!$G$7:$G$8766,$A15,'Cambium Peaker Source'!$F$7:$F$8766,D$10),0) -> 0.11250321 | E15: =IFERROR(AVERAGEIFS('Cambium Peaker Source'!$J$7:$J$8766,'Cambium Peaker Source'!$G$7:$G$8766,$A15,'Cambium Peaker Source'!$F$7:$F$8766,E$10),0) -> 0.11250321 | F15: =IFERROR(AVERAGEIFS('Cambium Peaker Source'!$J$7:$J$8766,'Cambium Peaker Source'!$G$7:$G$8766,$A15,'Cambium Peaker Source'!$F$7:$F$8766,F$10),0) -> 0.11250321 | G15: =IFERROR(AVERAGEIFS('Cambium Peaker Source'!$J$7:$J$8766,'Cambium Peaker Source'!$G$7:$G$8766,$A15,'Cambium Peaker Source'!$F$7:$F$8766,G$10),0) -> 0.11250321 | H15: =IFERROR(AVERAGEIFS('Cambium Peaker Source'!$J$7:$J$8766,'Cambium Peaker Source'!$G$7:$G$8766,$A15,'Cambium Peaker Source'!$F$7:$F$8766,H$10),0) -> 0.11250321 | I15: =IFERROR(AVERAGEIFS('Cambium Peaker Source'!$J$7:$J$8766,'Cambium Peaker Source'!$G$7:$G$8766,$A15,'Cambium Peaker Source'!$F$7:$F$8766,I$10),0) -> 0.11250321 | ... Y15: =IFERROR(AVERAGEIFS('Cambium Peaker Source'!$J$7:$J$8766,'Cambium Peaker Source'!$G$7:$G$8766,$A15,'Cambium Peaker Source'!$F$7:$F$8766,Y$10),0) -> 0.11401408 | Z15: =SUM($B15:$Y15)*INDEX(Clustering!$E$6:$E$11,MATCH($A15,Clustering!$D$6:$D$11,0)) -> 157.9151 | AC15: Achieved CF, multiplicative pass 6 | AD15: =SUM($Z$60:$Z$65)/'Peaker Keys'!$B$5 -> 0.42700566
A16: Winter Peak | B16: =IFERROR(AVERAGEIFS('Cambium Peaker Source'!$J$7:$J$8766,'Cambium Peaker Source'!$G$7:$G$8766,$A16,'Cambium Peaker Source'!$F$7:$F$8766,B$10),0) -> 0 | C16: =IFERROR(AVERAGEIFS('Cambium Peaker Source'!$J$7:$J$8766,'Cambium Peaker Source'!$G$7:$G$8766,$A16,'Cambium Peaker Source'!$F$7:$F$8766,C$10),0) -> 0 | D16: =IFERROR(AVERAGEIFS('Cambium Peaker Source'!$J$7:$J$8766,'Cambium Peaker Source'!$G$7:$G$8766,$A16,'Cambium Peaker Source'!$F$7:$F$8766,D$10),0) -> 0 | E16: =IFERROR(AVERAGEIFS('Cambium Peaker Source'!$J$7:$J$8766,'Cambium Peaker Source'!$G$7:$G$8766,$A16,'Cambium Peaker Source'!$F$7:$F$8766,E$10),0) -> 0 | F16: =IFERROR(AVERAGEIFS('Cambium Peaker Source'!$J$7:$J$8766,'Cambium Peaker Source'!$G$7:$G$8766,$A16,'Cambium Peaker Source'!$F$7:$F$8766,F$10),0) -> 0 | G16: =IFERROR(AVERAGEIFS('Cambium Peaker Source'!$J$7:$J$8766,'Cambium Peaker Source'!$G$7:$G$8766,$A16,'Cambium Peaker Source'!$F$7:$F$8766,G$10),0) -> 0 | H16: =IFERROR(AVERAGEIFS('Cambium Peaker Source'!$J$7:$J$8766,'Cambium Peaker Source'!$G$7:$G$8766,$A16,'Cambium Peaker Source'!$F$7:$F$8766,H$10),0) -> 0 | I16: =IFERROR(AVERAGEIFS('Cambium Peaker Source'!$J$7:$J$8766,'Cambium Peaker Source'!$G$7:$G$8766,$A16,'Cambium Peaker Source'!$F$7:$F$8766,I$10),0) -> 0 | ... Y16: =IFERROR(AVERAGEIFS('Cambium Peaker Source'!$J$7:$J$8766,'Cambium Peaker Source'!$G$7:$G$8766,$A16,'Cambium Peaker Source'!$F$7:$F$8766,Y$10),0) -> 0 | Z16: =SUM($B16:$Y16)*INDEX(Clustering!$E$6:$E$11,MATCH($A16,Clustering!$D$6:$D$11,0)) -> 0 | AC16: Uniform lift, additive pass 1 | AD16: =0+IF(SUM($AA$60:$AA$65)>0,MAX(0,$AD$2-$AD$15)*'Peaker Keys'!$B$5/SUM($AA$60:$AA$65),0) -> 0.0022534594
AC17: Achieved CF, additive pass 1 | AD17: =SUM($Z$68:$Z$73)/'Peaker Keys'!$B$5 -> 0.42885422
AC18: Uniform lift, additive pass 2 | AD18: =$AD$16+IF(SUM($AA$68:$AA$73)>0,MAX(0,$AD$2-$AD$17)*'Peaker Keys'!$B$5/SUM($AA$68:$AA$73),0) -> 0.0022534594
A19: Multiplicative pass 1: MIN(clip, block 0 x scale 1) | AC19: Achieved CF, additive pass 2 | AD19: =SUM($Z$76:$Z$81)/'Peaker Keys'!$B$5 -> 0.42885422
A20: =A11 -> Winter | B20: =MIN('Peaker Keys'!$B$10,B11*$AD$4) -> 0 | C20: =MIN('Peaker Keys'!$B$10,C11*$AD$4) -> 0 | D20: =MIN('Peaker Keys'!$B$10,D11*$AD$4) -> 0 | E20: =MIN('Peaker Keys'!$B$10,E11*$AD$4) -> 0 | F20: =MIN('Peaker Keys'!$B$10,F11*$AD$4) -> 0 | G20: =MIN('Peaker Keys'!$B$10,G11*$AD$4) -> 0 | H20: =MIN('Peaker Keys'!$B$10,H11*$AD$4) -> 0 | I20: =MIN('Peaker Keys'!$B$10,I11*$AD$4) -> 0 | ... Y20: =MIN('Peaker Keys'!$B$10,Y11*$AD$4) -> 0 | Z20: =SUM($B20:$Y20)*INDEX(Clustering!$E$6:$E$11,MATCH($A20,Clustering!$D$6:$D$11,0)) -> 0 | AA20: =COUNTIF($B20:$Y20,"<"&'Peaker Keys'!$B$10)*INDEX(Clustering!$E$6:$E$11,MATCH($A20,Clustering!$D$6:$D$11,0)) -> 2232 | AC20: Uniform lift, additive pass 3 | AD20: =$AD$18+IF(SUM($AA$76:$AA$81)>0,MAX(0,$AD$2-$AD$19)*'Peaker Keys'!$B$5/SUM($AA$76:$AA$81),0) -> 0.0022534594
A21: =A12 -> Spring | B21: =MIN('Peaker Keys'!$B$10,B12*$AD$4) -> 0.37130888 | C21: =MIN('Peaker Keys'!$B$10,C12*$AD$4) -> 0.37130888 | D21: =MIN('Peaker Keys'!$B$10,D12*$AD$4) -> 0.37130888 | E21: =MIN('Peaker Keys'!$B$10,E12*$AD$4) -> 0.37130888 | F21: =MIN('Peaker Keys'!$B$10,F12*$AD$4) -> 0.37130888 | G21: =MIN('Peaker Keys'!$B$10,G12*$AD$4) -> 0.37130888 | H21: =MIN('Peaker Keys'!$B$10,H12*$AD$4) -> 0.37130888 | I21: =MIN('Peaker Keys'!$B$10,I12*$AD$4) -> 0.37130888 | ... Y21: =MIN('Peaker Keys'!$B$10,Y12*$AD$4) -> 0.2848239 | Z21: =SUM($B21:$Y21)*INDEX(Clustering!$E$6:$E$11,MATCH($A21,Clustering!$D$6:$D$11,0)) -> 494.99329 | AA21: =COUNTIF($B21:$Y21,"<"&'Peaker Keys'!$B$10)*INDEX(Clustering!$E$6:$E$11,MATCH($A21,Clustering!$D$6:$D$11,0)) -> 1152 | AC21: Achieved CF, additive pass 3 | AD21: =SUM($Z$84:$Z$89)/'Peaker Keys'!$B$5 -> 0.42885422
A22: =A13 -> Summer | B22: =MIN('Peaker Keys'!$B$10,B13*$AD$4) -> 0.13299367 | C22: =MIN('Peaker Keys'!$B$10,C13*$AD$4) -> 0.13299367 | D22: =MIN('Peaker Keys'!$B$10,D13*$AD$4) -> 0.13299367 | E22: =MIN('Peaker Keys'!$B$10,E13*$AD$4) -> 0.13299367 | F22: =MIN('Peaker Keys'!$B$10,F13*$AD$4) -> 0.13299367 | G22: =MIN('Peaker Keys'!$B$10,G13*$AD$4) -> 0.13299367 | H22: =MIN('Peaker Keys'!$B$10,H13*$AD$4) -> 0.13299367 | I22: =MIN('Peaker Keys'!$B$10,I13*$AD$4) -> 0.13299367 | ... Y22: =MIN('Peaker Keys'!$B$10,Y13*$AD$4) -> 0.10185753 | Z22: =SUM($B22:$Y22)*INDEX(Clustering!$E$6:$E$11,MATCH($A22,Clustering!$D$6:$D$11,0)) -> 559.80069 | AA22: =COUNTIF($B22:$Y22,"<"&'Peaker Keys'!$B$10)*INDEX(Clustering!$E$6:$E$11,MATCH($A22,Clustering!$D$6:$D$11,0)) -> 2568 | AC22: Uniform lift, additive pass 4 (applied to the output table) | AD22: =$AD$20+IF(SUM($AA$84:$AA$89)>0,MAX(0,$AD$2-$AD$21)*'Peaker Keys'!$B$5/SUM($AA$84:$AA$89),0) -> 0.0022534594
A23: =A14 -> Fall | B23: =MIN('Peaker Keys'!$B$10,B14*$AD$4) -> 0.35997858 | C23: =MIN('Peaker Keys'!$B$10,C14*$AD$4) -> 0.35997858 | D23: =MIN('Peaker Keys'!$B$10,D14*$AD$4) -> 0.35997858 | E23: =MIN('Peaker Keys'!$B$10,E14*$AD$4) -> 0.35997858 | F23: =MIN('Peaker Keys'!$B$10,F14*$AD$4) -> 0.35997858 | G23: =MIN('Peaker Keys'!$B$10,G14*$AD$4) -> 0.35997858 | H23: =MIN('Peaker Keys'!$B$10,H14*$AD$4) -> 0.35997858 | I23: =MIN('Peaker Keys'!$B$10,I14*$AD$4) -> 0.35997858 | ... Y23: =MIN('Peaker Keys'!$B$10,Y14*$AD$4) -> 0.47733571 | Z23: =SUM($B23:$Y23)*INDEX(Clustering!$E$6:$E$11,MATCH($A23,Clustering!$D$6:$D$11,0)) -> 857.55503 | AA23: =COUNTIF($B23:$Y23,"<"&'Peaker Keys'!$B$10)*INDEX(Clustering!$E$6:$E$11,MATCH($A23,Clustering!$D$6:$D$11,0)) -> 1121 | AC23: Achieved final (output table A1:Y7) | AD23: =SUM($Z$2:$Z$7)/'Peaker Keys'!$B$5 -> 0.42885422
A24: =A15 -> Summer Peak | B24: =MIN('Peaker Keys'!$B$10,B15*$AD$4) -> 1 | C24: =MIN('Peaker Keys'!$B$10,C15*$AD$4) -> 1 | D24: =MIN('Peaker Keys'!$B$10,D15*$AD$4) -> 1 | E24: =MIN('Peaker Keys'!$B$10,E15*$AD$4) -> 1 | F24: =MIN('Peaker Keys'!$B$10,F15*$AD$4) -> 1 | G24: =MIN('Peaker Keys'!$B$10,G15*$AD$4) -> 1 | H24: =MIN('Peaker Keys'!$B$10,H15*$AD$4) -> 1 | I24: =MIN('Peaker Keys'!$B$10,I15*$AD$4) -> 1 | ... Y24: =MIN('Peaker Keys'!$B$10,Y15*$AD$4) -> 1 | Z24: =SUM($B24:$Y24)*INDEX(Clustering!$E$6:$E$11,MATCH($A24,Clustering!$D$6:$D$11,0)) -> 792 | AA24: =COUNTIF($B24:$Y24,"<"&'Peaker Keys'!$B$10)*INDEX(Clustering!$E$6:$E$11,MATCH($A24,Clustering!$D$6:$D$11,0)) -> 0 | AC24: Check | AD24: =IF(ABS($AD$23-$AD$2)>'Peaker Keys'!$B$11,"WARN: >0.005 off target","OK") -> OK
A25: =A16 -> Winter Peak | B25: =MIN('Peaker Keys'!$B$10,B16*$AD$4) -> 0 | C25: =MIN('Peaker Keys'!$B$10,C16*$AD$4) -> 0 | D25: =MIN('Peaker Keys'!$B$10,D16*$AD$4) -> 0 | E25: =MIN('Peaker Keys'!$B$10,E16*$AD$4) -> 0 | F25: =MIN('Peaker Keys'!$B$10,F16*$AD$4) -> 0 | G25: =MIN('Peaker Keys'!$B$10,G16*$AD$4) -> 0 | H25: =MIN('Peaker Keys'!$B$10,H16*$AD$4) -> 0 | I25: =MIN('Peaker Keys'!$B$10,I16*$AD$4) -> 0 | ... Y25: =MIN('Peaker Keys'!$B$10,Y16*$AD$4) -> 0 | Z25: =SUM($B25:$Y25)*INDEX(Clustering!$E$6:$E$11,MATCH($A25,Clustering!$D$6:$D$11,0)) -> 0 | AA25: =COUNTIF($B25:$Y25,"<"&'Peaker Keys'!$B$10)*INDEX(Clustering!$E$6:$E$11,MATCH($A25,Clustering!$D$6:$D$11,0)) -> 600
A27: Multiplicative pass 2: MIN(clip, block 0 x scale 2)
A28: =A11 -> Winter | B28: =MIN('Peaker Keys'!$B$10,B11*$AD$6) -> 0 | C28: =MIN('Peaker Keys'!$B$10,C11*$AD$6) -> 0 | D28: =MIN('Peaker Keys'!$B$10,D11*$AD$6) -> 0 | E28: =MIN('Peaker Keys'!$B$10,E11*$AD$6) -> 0 | F28: =MIN('Peaker Keys'!$B$10,F11*$AD$6) -> 0 | G28: =MIN('Peaker Keys'!$B$10,G11*$AD$6) -> 0 | H28: =MIN('Peaker Keys'!$B$10,H11*$AD$6) -> 0 | I28: =MIN('Peaker Keys'!$B$10,I11*$AD$6) -> 0 | ... Y28: =MIN('Peaker Keys'!$B$10,Y11*$AD$6) -> 0 | Z28: =SUM($B28:$Y28)*INDEX(Clustering!$E$6:$E$11,MATCH($A28,Clustering!$D$6:$D$11,0)) -> 0 | AA28: =COUNTIF($B28:$Y28,"<"&'Peaker Keys'!$B$10)*INDEX(Clustering!$E$6:$E$11,MATCH($A28,Clustering!$D$6:$D$11,0)) -> 2232
A29: =A12 -> Spring | B29: =MIN('Peaker Keys'!$B$10,B12*$AD$6) -> 0.515806 | C29: =MIN('Peaker Keys'!$B$10,C12*$AD$6) -> 0.515806 | D29: =MIN('Peaker Keys'!$B$10,D12*$AD$6) -> 0.515806 | E29: =MIN('Peaker Keys'!$B$10,E12*$AD$6) -> 0.515806 | F29: =MIN('Peaker Keys'!$B$10,F12*$AD$6) -> 0.515806 | G29: =MIN('Peaker Keys'!$B$10,G12*$AD$6) -> 0.515806 | H29: =MIN('Peaker Keys'!$B$10,H12*$AD$6) -> 0.515806 | I29: =MIN('Peaker Keys'!$B$10,I12*$AD$6) -> 0.515806 | ... Y29: =MIN('Peaker Keys'!$B$10,Y12*$AD$6) -> 0.39566485 | Z29: =SUM($B29:$Y29)*INDEX(Clustering!$E$6:$E$11,MATCH($A29,Clustering!$D$6:$D$11,0)) -> 685.661 | AA29: =COUNTIF($B29:$Y29,"<"&'Peaker Keys'!$B$10)*INDEX(Clustering!$E$6:$E$11,MATCH($A29,Clustering!$D$6:$D$11,0)) -> 1056
A30: =A13 -> Summer | B30: =MIN('Peaker Keys'!$B$10,B13*$AD$6) -> 0.18474896 | C30: =MIN('Peaker Keys'!$B$10,C13*$AD$6) -> 0.18474896 | D30: =MIN('Peaker Keys'!$B$10,D13*$AD$6) -> 0.18474896 | E30: =MIN('Peaker Keys'!$B$10,E13*$AD$6) -> 0.18474896 | F30: =MIN('Peaker Keys'!$B$10,F13*$AD$6) -> 0.18474896 | G30: =MIN('Peaker Keys'!$B$10,G13*$AD$6) -> 0.18474896 | H30: =MIN('Peaker Keys'!$B$10,H13*$AD$6) -> 0.18474896 | I30: =MIN('Peaker Keys'!$B$10,I13*$AD$6) -> 0.18474896 | ... Y30: =MIN('Peaker Keys'!$B$10,Y13*$AD$6) -> 0.14149601 | Z30: =SUM($B30:$Y30)*INDEX(Clustering!$E$6:$E$11,MATCH($A30,Clustering!$D$6:$D$11,0)) -> 777.65055 | AA30: =COUNTIF($B30:$Y30,"<"&'Peaker Keys'!$B$10)*INDEX(Clustering!$E$6:$E$11,MATCH($A30,Clustering!$D$6:$D$11,0)) -> 2568
